Workbook

Sheet Data-PP1
A1: AyurVAID Centre | B1: Date Created | C1: Registration Date | D1: Patient ID | E1: Physician to be Met | F1: First Name | G1: Last Name | H1: Name | I1: NFT | J1: Presenting Complaint | K1: Severity | L1: Chronicity | M1: Episode | N1: Are You Diabetic? | O1: Diabetes Type | P1: Covered by Insurance? | Q1: Corporate/Retail | R1: Insurance Company | S1: TPA | T1: Employer Name | U1: Employer-Others | V1: Salutation | W1: Gender | X1: Phone | Y1: Home Phone | Z1: Email | AA1: Date of Birth | AB1: City | AC1: Locality | AD1: Contacted By Ayurvaid | AE1: Preferred time of contact | AF1: Ayurveda Experience | AG1: Hear about Ayurvaid | AH1: Consent of the Patient | AI1: Status | AJ1: Lead Category | AK1: Sub Category | AL1: Lead Source | AM1: DSQ Screening done ? | AN1: Stage | AO1: ID | AP1: Disease (Allopathy) | AQ1: Age (Yrs) | AR1: Date Created | AS1: Month
A2: Kalmatia | B2: 46120.525 | C2: 46120 | D2: 5961068363 | E2: Dr. Adarsh T (AVK) | F2: RENUKA | G2: SINGH | H2: RENUKA SINGH | P2: Yes | R2: Other | S2: NA | T2: Not Employed | W2: Female | X2: 919936164333 | AB2: Kanpur | AD2: Phone | AE2: 0.625 | AF2: No | AG2: Website | AH2: Yes | AI2: CONSULTATION PATIENT-W2 / Estimate | AL2: Other | AN2: Consultation Patient | AO2: 000266388 | AQ2: 43 | AS2: =VLOOKUP(MONTH(AR2),Month!$A:$B,2,FALSE) & "-" & MID(YEAR(AR2),3,2) -> Jan-00

Sheet C+8 Data
A1: Registration Date | B1: Internal ID | C1: ID | D1: Patient Name | E1: Date of Feedback Call | F1: Patient ID | G1: AVH Centre | H1: Name of Physician | I1: The Process of fixing apptnt with Doctor | J1: Overall Services (Reception team) | K1: Overall Services (Pharmacy and Billing) | L1: Interval Time b4 the Doctor Could Be Met | M1: Time spent by the PP for screening & Con | N1: State why if any of the rating <= Good | O1: Do you think your health needs have been understood clearly by the doctor? | P1: Your diagnosis? | Q1: Your Risk factors? | R1: Dos and Don'ts? | S1: Diet-lifestyle-medicine-treatment process | T1: Health outcomes that you may expect | U1: The review date | V1: Please rate your overall satisfaction with your consultation | W1: Please rate your overall satisfaction with AyurVAID | X1: Probability that you will recommend your friends and relatives to visit AyurVAID | Y1: Comments | Z1: Date Created | AA1: Submitted by | AB1: Month
A2: 45778 | B2: 21472 | C2: CIF000021472 | E2: 45787.401 | F2: 802074483 | G2: HRBR | H2: Dr. Vrashank Gaitonde (HRBR) | I2: Very satisfactory (100%) | J2: Very satisfactory (100%) | K2: Very satisfactory (100%) | L2: Very satisfactory (100%) | M2: Very satisfactory (100%) | O2: Yes | P2: Yes | Q2: Yes | R2: Yes | S2: Yes | T2: Yes | U2: Yes | V2: Very satisfactory (100%) | W2: Very satisfactory (100%) | X2: 1 | Y2: Treatment taken at HRBR | Z2: 45787.535 | AB2: =VLOOKUP(MONTH(A2),Month!$A:$B,2,FALSE) & "-" & MID(YEAR(A2),3,2) -> May-25

Sheet C+8 Dashboard
A1: CSAT | F1: 45748 | I1: =EDATE(F1,1) -> 45778 | L1: =EDATE(I1,1) -> 45809 | O1: =EDATE(L1,1) -> 45839 | R1: =EDATE(O1,1) -> 45870 | U1: =EDATE(R1,1) -> 45901 | X1: =EDATE(U1,1) -> 45931 | AA1: =EDATE(X1,1) -> 45962 | AD1: =EDATE(AA1,1) -> 45992 | AG1: =EDATE(AD1,1) -> 46023 | AJ1: =EDATE(AG1,1) -> 46054 | AM1: =EDATE(AJ1,1) -> 46082
A2: Slno | B2: Customer Satisfaction-2018 | C2: Total # filled the form | D2: Actuals | E2: % satisfaction | F2: Total # filled the form | G2: Actuals | H2: % satisfaction | I2: Total # filled the form | J2: Actuals | K2: % satisfaction | L2: Total # filled the form | M2: Actuals | N2: % satisfaction | O2: Total # filled the form | P2: Actuals | Q2: % satisfaction | R2: Total # filled the form | S2: Actuals | T2: % satisfaction | U2: Total # filled the form | V2: Actuals | W2: % satisfaction | X2: Total # filled the form | Y2: Actuals | Z2: % satisfaction | AA2: Total # filled the form | AB2: Actuals | AC2: % satisfaction | AD2: Total # filled the form | AE2: Actuals | AF2: % satisfaction | AG2: Total # filled the form | AH2: Actuals | AI2: % satisfaction | AJ2: Total # filled the form | AK2: Actuals | AL2: % satisfaction | AM2: Total # filled the form | AN2: Actuals | AO2: % satisfaction
A3: 1 | B3: The Process of fixing appointment with the doctor
B4: a) Excellent - 100% | C4: =COUNTIF('C+8 Data'!$I:$I,"<>" & "")-1 -> 1 | D4: =G4+J4+M4+P4+S4+V4+Y4+AB4+AE4+AH4+AK4+AN4 -> 1 | E4: =IF(C4 <> 0,D4/C4,"") -> 1 | F4: =COUNTIFS('C+8 Data'!$AB:$AB,F$1,'C+8 Data'!$I:$I,"<>" & "") -> 0 | G4: =COUNTIFS('C+8 Data'!$AB:$AB,F$1,'C+8 Data'!$I:$I,"Very satisfactory (100%)") -> 0 | H4: =IF(F4 <> 0,G4/F4,"") | I4: =COUNTIFS('C+8 Data'!$AB:$AB,I$1,'C+8 Data'!$I:$I,"<>" & "") -> 1 | J4: =COUNTIFS('C+8 Data'!$AB:$AB,I$1,'C+8 Data'!$I:$I,"Very satisfactory (100%)") -> 1 | K4: =IF(I4 <> 0,J4/I4,"") -> 1 | L4: =COUNTIFS('C+8 Data'!$AB:$AB,L$1,'C+8 Data'!$I:$I,"<>" & "") -> 0 | M4: =COUNTIFS('C+8 Data'!$AB:$AB,L$1,'C+8 Data'!$I:$I,"Very satisfactory (100%)") -> 0 | N4: =IF(L4 <> 0,M4/L4,"") | O4: =COUNTIFS('C+8 Data'!$AB:$AB,O$1,'C+8 Data'!$I:$I,"<>" & "") -> 0 | P4: =COUNTIFS('C+8 Data'!$AB:$AB,O$1,'C+8 Data'!$I:$I,"Very satisfactory (100%)") -> 0 | Q4: =IF(O4 <> 0,P4/O4,"") | R4: =COUNTIFS('C+8 Data'!$AB:$AB,R$1,'C+8 Data'!$I:$I,"<>" & "") -> 0 | S4: =COUNTIFS('C+8 Data'!$AB:$AB,R$1,'C+8 Data'!$I:$I,"Very satisfactory (100%)") -> 0 | T4: =IF(R4 <> 0,S4/R4,"") | U4: =COUNTIFS('C+8 Data'!$AB:$AB,U$1,'C+8 Data'!$I:$I,"<>" & "") -> 0 | V4: =COUNTIFS('C+8 Data'!$AB:$AB,U$1,'C+8 Data'!$I:$I,"Very satisfactory (100%)") -> 0 | W4: =IF(U4 <> 0,V4/U4,"") | X4: =COUNTIFS('C+8 Data'!$AB:$AB,X$1,'C+8 Data'!$I:$I,"<>" & "") -> 0 | Y4: =COUNTIFS('C+8 Data'!$AB:$AB,X$1,'C+8 Data'!$I:$I,"Very satisfactory (100%)") -> 0 | Z4: =IF(X4 <> 0,Y4/X4,"") | AA4: =COUNTIFS('C+8 Data'!$AB:$AB,AA$1,'C+8 Data'!$I:$I,"<>" & "") -> 0 | AB4: =COUNTIFS('C+8 Data'!$AB:$AB,AA$1,'C+8 Data'!$I:$I,"Very satisfactory (100%)") -> 0 | AC4: =IF(AA4 <> 0,AB4/AA4,"") | AD4: =COUNTIFS('C+8 Data'!$AB:$AB,AD$1,'C+8 Data'!$I:$I,"<>" & "") -> 0 | AE4: =COUNTIFS('C+8 Data'!$AB:$AB,AD$1,'C+8 Data'!$I:$I,"Very satisfactory (100%)") -> 0 | AF4: =IF(AD4 <> 0,AE4/AD4,"") | AG4: =COUNTIFS('C+8 Data'!$AB:$AB,AG$1,'C+8 Data'!$I:$I,"<>" & "") -> 0 | AH4: =COUNTIFS('C+8 Data'!$AB:$AB,AG$1,'C+8 Data'!$I:$I,"Very satisfactory (100%)") -> 0 | AI4: =IF(AG4 <> 0,AH4/AG4,"") | AJ4: =COUNTIFS('C+8 Data'!$AB:$AB,AJ$1,'C+8 Data'!$I:$I,"<>" & "") -> 0 | AK4: =COUNTIFS('C+8 Data'!$AB:$AB,AJ$1,'C+8 Data'!$I:$I,"Very satisfactory (100%)") -> 0 | AL4: =IF(AJ4 <> 0,AK4/AJ4,"") | AM4: =COUNTIFS('C+8 Data'!$AB:$AB,AM$1,'C+8 Data'!$I:$I,"<>" & "") -> 0 | AN4: =COUNTIFS('C+8 Data'!$AB:$AB,AM$1,'C+8 Data'!$I:$I,"Very satisfactory (100%)") -> 0 | AO4: =IF(AM4 <> 0,AN4/AM4,"")
B5: b) V.Good - 80% | C5: =C4 -> 1 | D5: =G5+J5+M5+P5+S5+V5+Y5+AB5+AE5+AH5+AK5+AN5 -> 0 | E5: =IF(C5 <> 0,D5/C5,"") -> 0 | F5: =F4 -> 0 | G5: =COUNTIFS('C+8 Data'!$AB:$AB,F$1,'C+8 Data'!$I:$I,"Satisfactory (80%)") -> 0 | H5: =IF(F5 <> 0,G5/F5,"") | I5: =I4 -> 1 | J5: =COUNTIFS('C+8 Data'!$AB:$AB,I$1,'C+8 Data'!$I:$I,"Satisfactory (80%)") -> 0 | K5: =IF(I5 <> 0,J5/I5,"") -> 0 | L5: =L4 -> 0 | M5: =COUNTIFS('C+8 Data'!$AB:$AB,L$1,'C+8 Data'!$I:$I,"Satisfactory (80%)") -> 0 | N5: =IF(L5 <> 0,M5/L5,"") | O5: =O4 -> 0 | P5: =COUNTIFS('C+8 Data'!$AB:$AB,O$1,'C+8 Data'!$I:$I,"Satisfactory (80%)") -> 0 | Q5: =IF(O5 <> 0,P5/O5,"") | R5: =R4 -> 0 | S5: =COUNTIFS('C+8 Data'!$AB:$AB,R$1,'C+8 Data'!$I:$I,"Satisfactory (80%)") -> 0 | T5: =IF(R5 <> 0,S5/R5,"") | U5: =U4 -> 0 | V5: =COUNTIFS('C+8 Data'!$AB:$AB,U$1,'C+8 Data'!$I:$I,"Satisfactory (80%)") -> 0 | W5: =IF(U5 <> 0,V5/U5,"") | X5: =X4 -> 0 | Y5: =COUNTIFS('C+8 Data'!$AB:$AB,X$1,'C+8 Data'!$I:$I,"Satisfactory (80%)") -> 0 | Z5: =IF(X5 <> 0,Y5/X5,"") | AA5: =AA4 -> 0 | AB5: =COUNTIFS('C+8 Data'!$AB:$AB,AA$1,'C+8 Data'!$I:$I,"Satisfactory (80%)") -> 0 | AC5: =IF(AA5 <> 0,AB5/AA5,"") | AD5: =AD4 -> 0 | AE5: =COUNTIFS('C+8 Data'!$AB:$AB,AD$1,'C+8 Data'!$I:$I,"Satisfactory (80%)") -> 0 | AF5: =IF(AD5 <> 0,AE5/AD5,"") | AG5: =AG4 -> 0 | AH5: =COUNTIFS('C+8 Data'!$AB:$AB,AG$1,'C+8 Data'!$I:$I,"Satisfactory (80%)") -> 0 | AI5: =IF(AG5 <> 0,AH5/AG5,"") | AJ5: =AJ4 -> 0 | AK5: =COUNTIFS('C+8 Data'!$AB:$AB,AJ$1,'C+8 Data'!$I:$I,"Satisfactory (80%)") -> 0 | AL5: =IF(AJ5 <> 0,AK5/AJ5,"") | AM5: =AM4 -> 0 | AN5: =COUNTIFS('C+8 Data'!$AB:$AB,AM$1,'C+8 Data'!$I:$I,"Satisfactory (80%)") -> 0 | AO5: =IF(AM5 <> 0,AN5/AM5,"")
B6: C) Good - 60% | C6: =C5 -> 1 | D6: =G6+J6+M6+P6+S6+V6+Y6+AB6+AE6+AH6+AK6+AN6 -> 0 | E6: =IF(C6 <> 0,D6/C6,"") -> 0 | F6: =F5 -> 0 | G6: =COUNTIFS('C+8 Data'!$AB:$AB,F$1,'C+8 Data'!$I:$I,"Average (60%)") -> 0 | H6: =IF(F6 <> 0,G6/F6,"") | I6: =I5 -> 1 | J6: =COUNTIFS('C+8 Data'!$AB:$AB,I$1,'C+8 Data'!$I:$I,"Average (60%)") -> 0 | K6: =IF(I6 <> 0,J6/I6,"") -> 0 | L6: =L5 -> 0 | M6: =COUNTIFS('C+8 Data'!$AB:$AB,L$1,'C+8 Data'!$I:$I,"Average (60%)") -> 0 | N6: =IF(L6 <> 0,M6/L6,"") | O6: =O5 -> 0 | P6: =COUNTIFS('C+8 Data'!$AB:$AB,O$1,'C+8 Data'!$I:$I,"Average (60%)") -> 0 | Q6: =IF(O6 <> 0,P6/O6,"") | R6: =R5 -> 0 | S6: =COUNTIFS('C+8 Data'!$AB:$AB,R$1,'C+8 Data'!$I:$I,"Average (60%)") -> 0 | T6: =IF(R6 <> 0,S6/R6,"") | U6: =U5 -> 0 | V6: =COUNTIFS('C+8 Data'!$AB:$AB,U$1,'C+8 Data'!$I:$I,"Average (60%)") -> 0 | W6: =IF(U6 <> 0,V6/U6,"") | X6: =X5 -> 0 | Y6: =COUNTIFS('C+8 Data'!$AB:$AB,X$1,'C+8 Data'!$I:$I,"Average (60%)") -> 0 | Z6: =IF(X6 <> 0,Y6/X6,"") | AA6: =AA5 -> 0 | AB6: =COUNTIFS('C+8 Data'!$AB:$AB,AA$1,'C+8 Data'!$I:$I,"Average (60%)") -> 0 | AC6: =IF(AA6 <> 0,AB6/AA6,"") | AD6: =AD5 -> 0 | AE6: =COUNTIFS('C+8 Data'!$AB:$AB,AD$1,'C+8 Data'!$I:$I,"Average (60%)") -> 0 | AF6: =IF(AD6 <> 0,AE6/AD6,"") | AG6: =AG5 -> 0 | AH6: =COUNTIFS('C+8 Data'!$AB:$AB,AG$1,'C+8 Data'!$I:$I,"Average (60%)") -> 0 | AI6: =IF(AG6 <> 0,AH6/AG6,"") | AJ6: =AJ5 -> 0 | AK6: =COUNTIFS('C+8 Data'!$AB:$AB,AJ$1,'C+8 Data'!$I:$I,"Average (60%)") -> 0 | AL6: =IF(AJ6 <> 0,AK6/AJ6,"") | AM6: =AM5 -> 0 | AN6: =COUNTIFS('C+8 Data'!$AB:$AB,AM$1,'C+8 Data'!$I:$I,"Average (60%)") -> 0 | AO6: =IF(AM6 <> 0,AN6/AM6,"")
B7: d) Fair - 40% | C7: =C6 -> 1 | D7: =G7+J7+M7+P7+S7+V7+Y7+AB7+AE7+AH7+AK7+AN7 -> 0 | E7: =IF(C7 <> 0,D7/C7,"") -> 0 | F7: =F6 -> 0 | G7: =COUNTIFS('C+8 Data'!$AB:$AB,F$1,'C+8 Data'!$I:$I,"Unsatisfactory (40%)") -> 0 | H7: =IF(F7 <> 0,G7/F7,"") | I7: =I6 -> 1 | J7: =COUNTIFS('C+8 Data'!$AB:$AB,I$1,'C+8 Data'!$I:$I,"Unsatisfactory (40%)") -> 0 | K7: =IF(I7 <> 0,J7/I7,"") -> 0 | L7: =L6 -> 0 | M7: =COUNTIFS('C+8 Data'!$AB:$AB,L$1,'C+8 Data'!$I:$I,"Unsatisfactory (40%)") -> 0 | N7: =IF(L7 <> 0,M7/L7,"") | O7: =O6 -> 0 | P7: =COUNTIFS('C+8 Data'!$AB:$AB,O$1,'C+8 Data'!$I:$I,"Unsatisfactory (40%)") -> 0 | Q7: =IF(O7 <> 0,P7/O7,"") | R7: =R6 -> 0 | S7: =COUNTIFS('C+8 Data'!$AB:$AB,R$1,'C+8 Data'!$I:$I,"Unsatisfactory (40%)") -> 0 | T7: =IF(R7 <> 0,S7/R7,"") | U7: =U6 -> 0 | V7: =COUNTIFS('C+8 Data'!$AB:$AB,U$1,'C+8 Data'!$I:$I,"Unsatisfactory (40%)") -> 0 | W7: =IF(U7 <> 0,V7/U7,"") | X7: =X6 -> 0 | Y7: =COUNTIFS('C+8 Data'!$AB:$AB,X$1,'C+8 Data'!$I:$I,"Unsatisfactory (40%)") -> 0 | Z7: =IF(X7 <> 0,Y7/X7,"") | AA7: =AA6 -> 0 | AB7: =COUNTIFS('C+8 Data'!$AB:$AB,AA$1,'C+8 Data'!$I:$I,"Unsatisfactory (40%)") -> 0 | AC7: =IF(AA7 <> 0,AB7/AA7,"") | AD7: =AD6 -> 0 | AE7: =COUNTIFS('C+8 Data'!$AB:$AB,AD$1,'C+8 Data'!$I:$I,"Unsatisfactory (40%)") -> 0 | AF7: =IF(AD7 <> 0,AE7/AD7,"") | AG7: =AG6 -> 0 | AH7: =COUNTIFS('C+8 Data'!$AB:$AB,AG$1,'C+8 Data'!$I:$I,"Unsatisfactory (40%)") -> 0 | AI7: =IF(AG7 <> 0,AH7/AG7,"") | AJ7: =AJ6 -> 0 | AK7: =COUNTIFS('C+8 Data'!$AB:$AB,AJ$1,'C+8 Data'!$I:$I,"Unsatisfactory (40%)") -> 0 | AL7: =IF(AJ7 <> 0,AK7/AJ7,"") | AM7: =AM6 -> 0 | AN7: =COUNTIFS('C+8 Data'!$AB:$AB,AM$1,'C+8 Data'!$I:$I,"Unsatisfactory (40%)") -> 0 | AO7: =IF(AM7 <> 0,AN7/AM7,"")
B8: e) Poor - 20% | C8: =C7 -> 1 | D8: =G8+J8+M8+P8+S8+V8+Y8+AB8+AE8+AH8+AK8+AN8 -> 0 | E8: =IF(C8 <> 0,D8/C8,"") -> 0 | F8: =F7 -> 0 | G8: =COUNTIFS('C+8 Data'!$AB:$AB,F$1,'C+8 Data'!$I:$I,"Very Unsatisfactory (20%)") -> 0 | H8: =IF(F8 <> 0,G8/F8,"") | I8: =I7 -> 1 | J8: =COUNTIFS('C+8 Data'!$AB:$AB,I$1,'C+8 Data'!$I:$I,"Very Unsatisfactory (20%)") -> 0 | K8: =IF(I8 <> 0,J8/I8,"") -> 0 | L8: =L7 -> 0 | M8: =COUNTIFS('C+8 Data'!$AB:$AB,L$1,'C+8 Data'!$I:$I,"Very Unsatisfactory (20%)") -> 0 | N8: =IF(L8 <> 0,M8/L8,"") | O8: =O7 -> 0 | P8: =COUNTIFS('C+8 Data'!$AB:$AB,O$1,'C+8 Data'!$I:$I,"Very Unsatisfactory (20%)") -> 0 | Q8: =IF(O8 <> 0,P8/O8,"") | R8: =R7 -> 0 | S8: =COUNTIFS('C+8 Data'!$AB:$AB,R$1,'C+8 Data'!$I:$I,"Very Unsatisfactory (20%)") -> 0 | T8: =IF(R8 <> 0,S8/R8,"") | U8: =U7 -> 0 | V8: =COUNTIFS('C+8 Data'!$AB:$AB,U$1,'C+8 Data'!$I:$I,"Very Unsatisfactory (20%)") -> 0 | W8: =IF(U8 <> 0,V8/U8,"") | X8: =X7 -> 0 | Y8: =COUNTIFS('C+8 Data'!$AB:$AB,X$1,'C+8 Data'!$I:$I,"Very Unsatisfactory (20%)") -> 0 | Z8: =IF(X8 <> 0,Y8/X8,"") | AA8: =AA7 -> 0 | AB8: =COUNTIFS('C+8 Data'!$AB:$AB,AA$1,'C+8 Data'!$I:$I,"Very Unsatisfactory (20%)") -> 0 | AC8: =IF(AA8 <> 0,AB8/AA8,"") | AD8: =AD7 -> 0 | AE8: =COUNTIFS('C+8 Data'!$AB:$AB,AD$1,'C+8 Data'!$I:$I,"Very Unsatisfactory (20%)") -> 0 | AF8: =IF(AD8 <> 0,AE8/AD8,"") | AG8: =AG7 -> 0 | AH8: =COUNTIFS('C+8 Data'!$AB:$AB,AG$1,'C+8 Data'!$I:$I,"Very Unsatisfactory (20%)") -> 0 | AI8: =IF(AG8 <> 0,AH8/AG8,"") | AJ8: =AJ7 -> 0 | AK8: =COUNTIFS('C+8 Data'!$AB:$AB,AJ$1,'C+8 Data'!$I:$I,"Very Unsatisfactory (20%)") -> 0 | AL8: =IF(AJ8 <> 0,AK8/AJ8,"") | AM8: =AM7 -> 0 | AN8: =COUNTIFS('C+8 Data'!$AB:$AB,AM$1,'C+8 Data'!$I:$I,"Very Unsatisfactory (20%)") -> 0 | AO8: =IF(AM8 <> 0,AN8/AM8,"")
A9: 2 | B9: Overall services provided by the AyurVAID Reception team
B10: a) Excellent - 100% | C10: =COUNTIF('C+8 Data'!$I:$I,"<>" & "")-1 -> 1 | D10: =G10+J10+M10+P10+S10+V10+Y10+AB10+AE10+AH10+AK10+AN10 -> 1 | E10: =IF(C10 <> 0,D10/C10,"") -> 1 | F10: =COUNTIFS('C+8 Data'!$AB:$AB,F$1,'C+8 Data'!$J:$J,"<>" & "") -> 0 | G10: =COUNTIFS('C+8 Data'!$AB:$AB,F$1,'C+8 Data'!$J:$J,"Very satisfactory (100%)") -> 0 | H10: =IF(F10 <> 0,G10/F10,"") | I10: =COUNTIFS('C+8 Data'!$AB:$AB,I$1,'C+8 Data'!$J:$J,"<>" & "") -> 1 | J10: =COUNTIFS('C+8 Data'!$AB:$AB,I$1,'C+8 Data'!$J:$J,"Very satisfactory (100%)") -> 1 | K10: =IF(I10 <> 0,J10/I10,"") -> 1 | L10: =COUNTIFS('C+8 Data'!$AB:$AB,L$1,'C+8 Data'!$J:$J,"<>" & "") -> 0 | M10: =COUNTIFS('C+8 Data'!$AB:$AB,L$1,'C+8 Data'!$J:$J,"Very satisfactory (100%)") -> 0 | N10: =IF(L10 <> 0,M10/L10,"") | O10: =COUNTIFS('C+8 Data'!$AB:$AB,O$1,'C+8 Data'!$J:$J,"<>" & "") -> 0 | P10: =COUNTIFS('C+8 Data'!$AB:$AB,O$1,'C+8 Data'!$J:$J,"Very satisfactory (100%)") -> 0 | Q10: =IF(O10 <> 0,P10/O10,"") | R10: =COUNTIFS('C+8 Data'!$AB:$AB,R$1,'C+8 Data'!$J:$J,"<>" & "") -> 0 | S10: =COUNTIFS('C+8 Data'!$AB:$AB,R$1,'C+8 Data'!$J:$J,"Very satisfactory (100%)") -> 0 | T10: =IF(R10 <> 0,S10/R10,"") | U10: =COUNTIFS('C+8 Data'!$AB:$AB,U$1,'C+8 Data'!$J:$J,"<>" & "") -> 0 | V10: =COUNTIFS('C+8 Data'!$AB:$AB,U$1,'C+8 Data'!$J:$J,"Very satisfactory (100%)") -> 0 | W10: =IF(U10 <> 0,V10/U10,"") | X10: =COUNTIFS('C+8 Data'!$AB:$AB,X$1,'C+8 Data'!$J:$J,"<>" & "") -> 0 | Y10: =COUNTIFS('C+8 Data'!$AB:$AB,X$1,'C+8 Data'!$J:$J,"Very satisfactory (100%)") -> 0 | Z10: =IF(X10 <> 0,Y10/X10,"") | AA10: =COUNTIFS('C+8 Data'!$AB:$AB,AA$1,'C+8 Data'!$J:$J,"<>" & "") -> 0 | AB10: =COUNTIFS('C+8 Data'!$AB:$AB,AA$1,'C+8 Data'!$J:$J,"Very satisfactory (100%)") -> 0 | AC10: =IF(AA10 <> 0,AB10/AA10,"") | AD10: =COUNTIFS('C+8 Data'!$AB:$AB,AD$1,'C+8 Data'!$J:$J,"<>" & "") -> 0 | AE10: =COUNTIFS('C+8 Data'!$AB:$AB,AD$1,'C+8 Data'!$J:$J,"Very satisfactory (100%)") -> 0 | AF10: =IF(AD10 <> 0,AE10/AD10,"") | AG10: =COUNTIFS('C+8 Data'!$AB:$AB,AG$1,'C+8 Data'!$J:$J,"<>" & "") -> 0 | AH10: =COUNTIFS('C+8 Data'!$AB:$AB,AG$1,'C+8 Data'!$J:$J,"Very satisfactory (100%)") -> 0 | AI10: =IF(AG10 <> 0,AH10/AG10,"") | AJ10: =COUNTIFS('C+8 Data'!$AB:$AB,AJ$1,'C+8 Data'!$J:$J,"<>" & "") -> 0 | AK10: =COUNTIFS('C+8 Data'!$AB:$AB,AJ$1,'C+8 Data'!$J:$J,"Very satisfactory (100%)") -> 0 | AL10: =IF(AJ10 <> 0,AK10/AJ10,"") | AM10: =COUNTIFS('C+8 Data'!$AB:$AB,AM$1,'C+8 Data'!$J:$J,"<>" & "") -> 0 | AN10: =COUNTIFS('C+8 Data'!$AB:$AB,AM$1,'C+8 Data'!$J:$J,"Very satisfactory (100%)") -> 0 | AO10: =IF(AM10 <> 0,AN10/AM10,"")
B11: b) V.Good - 80% | C11: =C10 -> 1 | D11: =G11+J11+M11+P11+S11+V11+Y11+AB11+AE11+AH11+AK11+AN11 -> 0 | E11: =IF(C11 <> 0,D11/C11,"") -> 0 | F11: =F10 -> 0 | G11: =COUNTIFS('C+8 Data'!$AB:$AB,F$1,'C+8 Data'!$J:$J,"Satisfactory (80%)") -> 0 | H11: =IF(F11 <> 0,G11/F11,"") | I11: =I10 -> 1 | J11: =COUNTIFS('C+8 Data'!$AB:$AB,I$1,'C+8 Data'!$J:$J,"Satisfactory (80%)") -> 0 | K11: =IF(I11 <> 0,J11/I11,"") -> 0 | L11: =L10 -> 0 | M11: =COUNTIFS('C+8 Data'!$AB:$AB,L$1,'C+8 Data'!$J:$J,"Satisfactory (80%)") -> 0 | N11: =IF(L11 <> 0,M11/L11,"") | O11: =O10 -> 0 | P11: =COUNTIFS('C+8 Data'!$AB:$AB,O$1,'C+8 Data'!$J:$J,"Satisfactory (80%)") -> 0 | Q11: =IF(O11 <> 0,P11/O11,"") | R11: =R10 -> 0 | S11: =COUNTIFS('C+8 Data'!$AB:$AB,R$1,'C+8 Data'!$J:$J,"Satisfactory (80%)") -> 0 | T11: =IF(R11 <> 0,S11/R11,"") | U11: =U10 -> 0 | V11: =COUNTIFS('C+8 Data'!$AB:$AB,U$1,'C+8 Data'!$J:$J,"Satisfactory (80%)") -> 0 | W11: =IF(U11 <> 0,V11/U11,"") | X11: =X10 -> 0 | Y11: =COUNTIFS('C+8 Data'!$AB:$AB,X$1,'C+8 Data'!$J:$J,"Satisfactory (80%)") -> 0 | Z11: =IF(X11 <> 0,Y11/X11,"") | AA11: =AA10 -> 0 | AB11: =COUNTIFS('C+8 Data'!$AB:$AB,AA$1,'C+8 Data'!$J:$J,"Satisfactory (80%)") -> 0 | AC11: =IF(AA11 <> 0,AB11/AA11,"") | AD11: =AD10 -> 0 | AE11: =COUNTIFS('C+8 Data'!$AB:$AB,AD$1,'C+8 Data'!$J:$J,"Satisfactory (80%)") -> 0 | AF11: =IF(AD11 <> 0,AE11/AD11,"") | AG11: =AG10 -> 0 | AH11: =COUNTIFS('C+8 Data'!$AB:$AB,AG$1,'C+8 Data'!$J:$J,"Satisfactory (80%)") -> 0 | AI11: =IF(AG11 <> 0,AH11/AG11,"") | AJ11: =AJ10 -> 0 | AK11: =COUNTIFS('C+8 Data'!$AB:$AB,AJ$1,'C+8 Data'!$J:$J,"Satisfactory (80%)") -> 0 | AL11: =IF(AJ11 <> 0,AK11/AJ11,"") | AM11: =AM10 -> 0 | AN11: =COUNTIFS('C+8 Data'!$AB:$AB,AM$1,'C+8 Data'!$J:$J,"Satisfactory (80%)") -> 0 | AO11: =IF(AM11 <> 0,AN11/AM11,"")
B12: C) Good - 60% | C12: =C11 -> 1 | D12: =G12+J12+M12+P12+S12+V12+Y12+AB12+AE12+AH12+AK12+AN12 -> 0 | E12: =IF(C12 <> 0,D12/C12,"") -> 0 | F12: =F11 -> 0 | G12: =COUNTIFS('C+8 Data'!$AB:$AB,F$1,'C+8 Data'!$J:$J,"Average (60%)") -> 0 | H12: =IF(F12 <> 0,G12/F12,"") | I12: =I11 -> 1 | J12: =COUNTIFS('C+8 Data'!$AB:$AB,I$1,'C+8 Data'!$J:$J,"Average (60%)") -> 0 | K12: =IF(I12 <> 0,J12/I12,"") -> 0 | L12: =L11 -> 0 | M12: =COUNTIFS('C+8 Data'!$AB:$AB,L$1,'C+8 Data'!$J:$J,"Average (60%)") -> 0 | N12: =IF(L12 <> 0,M12/L12,"") | O12: =O11 -> 0 | P12: =COUNTIFS('C+8 Data'!$AB:$AB,O$1,'C+8 Data'!$J:$J,"Average (60%)") -> 0 | Q12: =IF(O12 <> 0,P12/O12,"") | R12: =R11 -> 0 | S12: =COUNTIFS('C+8 Data'!$AB:$AB,R$1,'C+8 Data'!$J:$J,"Average (60%)") -> 0 | T12: =IF(R12 <> 0,S12/R12,"") | U12: =U11 -> 0 | V12: =COUNTIFS('C+8 Data'!$AB:$AB,U$1,'C+8 Data'!$J:$J,"Average (60%)") -> 0 | W12: =IF(U12 <> 0,V12/U12,"") | X12: =X11 -> 0 | Y12: =COUNTIFS('C+8 Data'!$AB:$AB,X$1,'C+8 Data'!$J:$J,"Average (60%)") -> 0 | Z12: =IF(X12 <> 0,Y12/X12,"") | AA12: =AA11 -> 0 | AB12: =COUNTIFS('C+8 Data'!$AB:$AB,AA$1,'C+8 Data'!$J:$J,"Average (60%)") -> 0 | AC12: =IF(AA12 <> 0,AB12/AA12,"") | AD12: =AD11 -> 0 | AE12: =COUNTIFS('C+8 Data'!$AB:$AB,AD$1,'C+8 Data'!$J:$J,"Average (60%)") -> 0 | AF12: =IF(AD12 <> 0,AE12/AD12,"") | AG12: =AG11 -> 0 | AH12: =COUNTIFS('C+8 Data'!$AB:$AB,AG$1,'C+8 Data'!$J:$J,"Average (60%)") -> 0 | AI12: =IF(AG12 <> 0,AH12/AG12,"") | AJ12: =AJ11 -> 0 | AK12: =COUNTIFS('C+8 Data'!$AB:$AB,AJ$1,'C+8 Data'!$J:$J,"Average (60%)") -> 0 | AL12: =IF(AJ12 <> 0,AK12/AJ12,"") | AM12: =AM11 -> 0 | AN12: =COUNTIFS('C+8 Data'!$AB:$AB,AM$1,'C+8 Data'!$J:$J,"Average (60%)") -> 0 | AO12: =IF(AM12 <> 0,AN12/AM12,"")
B13: d) Fair - 40% | C13: =C12 -> 1 | D13: =G13+J13+M13+P13+S13+V13+Y13+AB13+AE13+AH13+AK13+AN13 -> 0 | E13: =IF(C13 <> 0,D13/C13,"") -> 0 | F13: =F12 -> 0 | G13: =COUNTIFS('C+8 Data'!$AB:$AB,F$1,'C+8 Data'!$J:$J,"Unsatisfactory (40%)") -> 0 | H13: =IF(F13 <> 0,G13/F13,"") | I13: =I12 -> 1 | J13: =COUNTIFS('C+8 Data'!$AB:$AB,I$1,'C+8 Data'!$J:$J,"Unsatisfactory (40%)") -> 0 | K13: =IF(I13 <> 0,J13/I13,"") -> 0 | L13: =L12 -> 0 | M13: =COUNTIFS('C+8 Data'!$AB:$AB,L$1,'C+8 Data'!$J:$J,"Unsatisfactory (40%)") -> 0 | N13: =IF(L13 <> 0,M13/L13,"") | O13: =O12 -> 0 | P13: =COUNTIFS('C+8 Data'!$AB:$AB,O$1,'C+8 Data'!$J:$J,"Unsatisfactory (40%)") -> 0 | Q13: =IF(O13 <> 0,P13/O13,"") | R13: =R12 -> 0 | S13: =COUNTIFS('C+8 Data'!$AB:$AB,R$1,'C+8 Data'!$J:$J,"Unsatisfactory (40%)") -> 0 | T13: =IF(R13 <> 0,S13/R13,"") | U13: =U12 -> 0 | V13: =COUNTIFS('C+8 Data'!$AB:$AB,U$1,'C+8 Data'!$J:$J,"Unsatisfactory (40%)") -> 0 | W13: =IF(U13 <> 0,V13/U13,"") | X13: =X12 -> 0 | Y13: =COUNTIFS('C+8 Data'!$AB:$AB,X$1,'C+8 Data'!$J:$J,"Unsatisfactory (40%)") -> 0 | Z13: =IF(X13 <> 0,Y13/X13,"") | AA13: =AA12 -> 0 | AB13: =COUNTIFS('C+8 Data'!$AB:$AB,AA$1,'C+8 Data'!$J:$J,"Unsatisfactory (40%)") -> 0 | AC13: =IF(AA13 <> 0,AB13/AA13,"") | AD13: =AD12 -> 0 | AE13: =COUNTIFS('C+8 Data'!$AB:$AB,AD$1,'C+8 Data'!$J:$J,"Unsatisfactory (40%)") -> 0 | AF13: =IF(AD13 <> 0,AE13/AD13,"") | AG13: =AG12 -> 0 | AH13: =COUNTIFS('C+8 Data'!$AB:$AB,AG$1,'C+8 Data'!$J:$J,"Unsatisfactory (40%)") -> 0 | AI13: =IF(AG13 <> 0,AH13/AG13,"") | AJ13: =AJ12 -> 0 | AK13: =COUNTIFS('C+8 Data'!$AB:$AB,AJ$1,'C+8 Data'!$J:$J,"Unsatisfactory (40%)") -> 0 | AL13: =IF(AJ13 <> 0,AK13/AJ13,"") | AM13: =AM12 -> 0 | AN13: =COUNTIFS('C+8 Data'!$AB:$AB,AM$1,'C+8 Data'!$J:$J,"Unsatisfactory (40%)") -> 0 | AO13: =IF(AM13 <> 0,AN13/AM13,"")
B14: e) Poor - 20% | C14: =C13 -> 1 | D14: =G14+J14+M14+P14+S14+V14+Y14+AB14+AE14+AH14+AK14+AN14 -> 0 | E14: =IF(C14 <> 0,D14/C14,"") -> 0 | F14: =F13 -> 0 | G14: =COUNTIFS('C+8 Data'!$AB:$AB,F$1,'C+8 Data'!$J:$J,"Very Unsatisfactory (20%)") -> 0 | H14: =IF(F14 <> 0,G14/F14,"") | I14: =I13 -> 1 | J14: =COUNTIFS('C+8 Data'!$AB:$AB,I$1,'C+8 Data'!$J:$J,"Very Unsatisfactory (20%)") -> 0 | K14: =IF(I14 <> 0,J14/I14,"") -> 0 | L14: =L13 -> 0 | M14: =COUNTIFS('C+8 Data'!$AB:$AB,L$1,'C+8 Data'!$J:$J,"Very Unsatisfactory (20%)") -> 0 | N14: =IF(L14 <> 0,M14/L14,"") | O14: =O13 -> 0 | P14: =COUNTIFS('C+8 Data'!$AB:$AB,O$1,'C+8 Data'!$J:$J,"Very Unsatisfactory (20%)") -> 0 | Q14: =IF(O14 <> 0,P14/O14,"") | R14: =R13 -> 0 | S14: =COUNTIFS('C+8 Data'!$AB:$AB,R$1,'C+8 Data'!$J:$J,"Very Unsatisfactory (20%)") -> 0 | T14: =IF(R14 <> 0,S14/R14,"") | U14: =U13 -> 0 | V14: =COUNTIFS('C+8 Data'!$AB:$AB,U$1,'C+8 Data'!$J:$J,"Very Unsatisfactory (20%)") -> 0 | W14: =IF(U14 <> 0,V14/U14,"") | X14: =X13 -> 0 | Y14: =COUNTIFS('C+8 Data'!$AB:$AB,X$1,'C+8 Data'!$J:$J,"Very Unsatisfactory (20%)") -> 0 | Z14: =IF(X14 <> 0,Y14/X14,"") | AA14: =AA13 -> 0 | AB14: =COUNTIFS('C+8 Data'!$AB:$AB,AA$1,'C+8 Data'!$J:$J,"Very Unsatisfactory (20%)") -> 0 | AC14: =IF(AA14 <> 0,AB14/AA14,"") | AD14: =AD13 -> 0 | AE14: =COUNTIFS('C+8 Data'!$AB:$AB,AD$1,'C+8 Data'!$J:$J,"Very Unsatisfactory (20%)") -> 0 | AF14: =IF(AD14 <> 0,AE14/AD14,"") | AG14: =AG13 -> 0 | AH14: =COUNTIFS('C+8 Data'!$AB:$AB,AG$1,'C+8 Data'!$J:$J,"Very Unsatisfactory (20%)") -> 0 | AI14: =IF(AG14 <> 0,AH14/AG14,"") | AJ14: =AJ13 -> 0 | AK14: =COUNTIFS('C+8 Data'!$AB:$AB,AJ$1,'C+8 Data'!$J:$J,"Very Unsatisfactory (20%)") -> 0 | AL14: =IF(AJ14 <> 0,AK14/AJ14,"") | AM14: =AM13 -> 0 | AN14: =COUNTIFS('C+8 Data'!$AB:$AB,AM$1,'C+8 Data'!$J:$J,"Very Unsatisfactory (20%)") -> 0 | AO14: =IF(AM14 <> 0,AN14/AM14,"")
A15: 3 | B15: Overall services provided by the Pharmacy and Billing team
B16: a) Excellent - 100% | C16: =COUNTIF('C+8 Data'!$K:$K,"<>" & "")-1 -> 1 | D16: =G16+J16+M16+P16+S16+V16+Y16+AB16+AE16+AH16+AK16+AN16 -> 1 | E16: =IF(C16 <> 0,D16/C16,"") -> 1 | F16: =COUNTIFS('C+8 Data'!$AB:$AB,F$1,'C+8 Data'!$K:$K,"<>" & "") -> 0 | G16: =COUNTIFS('C+8 Data'!$AB:$AB,F$1,'C+8 Data'!$K:$K,"Very satisfactory (100%)") -> 0 | H16: =IF(F16 <> 0,G16/F16,"") | I16: =COUNTIFS('C+8 Data'!$AB:$AB,I$1,'C+8 Data'!$K:$K,"<>" & "") -> 1 | J16: =COUNTIFS('C+8 Data'!$AB:$AB,I$1,'C+8 Data'!$K:$K,"Very satisfactory (100%)") -> 1 | K16: =IF(I16 <> 0,J16/I16,"") -> 1 | L16: =COUNTIFS('C+8 Data'!$AB:$AB,L$1,'C+8 Data'!$K:$K,"<>" & "") -> 0 | M16: =COUNTIFS('C+8 Data'!$AB:$AB,L$1,'C+8 Data'!$K:$K,"Very satisfactory (100%)") -> 0 | N16: =IF(L16 <> 0,M16/L16,"") | O16: =COUNTIFS('C+8 Data'!$AB:$AB,O$1,'C+8 Data'!$K:$K,"<>" & "") -> 0 | P16: =COUNTIFS('C+8 Data'!$AB:$AB,O$1,'C+8 Data'!$K:$K,"Very satisfactory (100%)") -> 0 | Q16: =IF(O16 <> 0,P16/O16,"") | R16: =COUNTIFS('C+8 Data'!$AB:$AB,R$1,'C+8 Data'!$K:$K,"<>" & "") -> 0 | S16: =COUNTIFS('C+8 Data'!$AB:$AB,R$1,'C+8 Data'!$K:$K,"Very satisfactory (100%)") -> 0 | T16: =IF(R16 <> 0,S16/R16,"") | U16: =COUNTIFS('C+8 Data'!$AB:$AB,U$1,'C+8 Data'!$K:$K,"<>" & "") -> 0 | V16: =COUNTIFS('C+8 Data'!$AB:$AB,U$1,'C+8 Data'!$K:$K,"Very satisfactory (100%)") -> 0 | W16: =IF(U16 <> 0,V16/U16,"") | X16: =COUNTIFS('C+8 Data'!$AB:$AB,X$1,'C+8 Data'!$K:$K,"<>" & "") -> 0 | Y16: =COUNTIFS('C+8 Data'!$AB:$AB,X$1,'C+8 Data'!$K:$K,"Very satisfactory (100%)") -> 0 | Z16: =IF(X16 <> 0,Y16/X16,"") | AA16: =COUNTIFS('C+8 Data'!$AB:$AB,AA$1,'C+8 Data'!$K:$K,"<>" & "") -> 0 | AB16: =COUNTIFS('C+8 Data'!$AB:$AB,AA$1,'C+8 Data'!$K:$K,"Very satisfactory (100%)") -> 0 | AC16: =IF(AA16 <> 0,AB16/AA16,"") | AD16: =COUNTIFS('C+8 Data'!$AB:$AB,AD$1,'C+8 Data'!$K:$K,"<>" & "") -> 0 | AE16: =COUNTIFS('C+8 Data'!$AB:$AB,AD$1,'C+8 Data'!$K:$K,"Very satisfactory (100%)") -> 0 | AF16: =IF(AD16 <> 0,AE16/AD16,"") | AG16: =COUNTIFS('C+8 Data'!$AB:$AB,AG$1,'C+8 Data'!$K:$K,"<>" & "") -> 0 | AH16: =COUNTIFS('C+8 Data'!$AB:$AB,AG$1,'C+8 Data'!$K:$K,"Very satisfactory (100%)") -> 0 | AI16: =IF(AG16 <> 0,AH16/AG16,"") | AJ16: =COUNTIFS('C+8 Data'!$AB:$AB,AJ$1,'C+8 Data'!$K:$K,"<>" & "") -> 0 | AK16: =COUNTIFS('C+8 Data'!$AB:$AB,AJ$1,'C+8 Data'!$K:$K,"Very satisfactory (100%)") -> 0 | AL16: =IF(AJ16 <> 0,AK16/AJ16,"") | AM16: =COUNTIFS('C+8 Data'!$AB:$AB,AM$1,'C+8 Data'!$K:$K,"<>" & "") -> 0 | AN16: =COUNTIFS('C+8 Data'!$AB:$AB,AM$1,'C+8 Data'!$K:$K,"Very satisfactory (100%)") -> 0 | AO16: =IF(AM16 <> 0,AN16/AM16,"")
B17: b) V.Good - 80% | C17: =C16 -> 1 | D17: =G17+J17+M17+P17+S17+V17+Y17+AB17+AE17+AH17+AK17+AN17 -> 0 | E17: =IF(C17 <> 0,D17/C17,"") -> 0 | F17: =F16 -> 0 | G17: =COUNTIFS('C+8 Data'!$AB:$AB,F$1,'C+8 Data'!$K:$K,"Satisfactory (80%)") -> 0 | H17: =IF(F17 <> 0,G17/F17,"") | I17: =I16 -> 1 | J17: =COUNTIFS('C+8 Data'!$AB:$AB,I$1,'C+8 Data'!$K:$K,"Satisfactory (80%)") -> 0 | K17: =IF(I17 <> 0,J17/I17,"") -> 0 | L17: =L16 -> 0 | M17: =COUNTIFS('C+8 Data'!$AB:$AB,L$1,'C+8 Data'!$K:$K,"Satisfactory (80%)") -> 0 | N17: =IF(L17 <> 0,M17/L17,"") | O17: =O16 -> 0 | P17: =COUNTIFS('C+8 Data'!$AB:$AB,O$1,'C+8 Data'!$K:$K,"Satisfactory (80%)") -> 0 | Q17: =IF(O17 <> 0,P17/O17,"") | R17: =R16 -> 0 | S17: =COUNTIFS('C+8 Data'!$AB:$AB,R$1,'C+8 Data'!$K:$K,"Satisfactory (80%)") -> 0 | T17: =IF(R17 <> 0,S17/R17,"") | U17: =U16 -> 0 | V17: =COUNTIFS('C+8 Data'!$AB:$AB,U$1,'C+8 Data'!$K:$K,"Satisfactory (80%)") -> 0 | W17: =IF(U17 <> 0,V17/U17,"") | X17: =X16 -> 0 | Y17: =COUNTIFS('C+8 Data'!$AB:$AB,X$1,'C+8 Data'!$K:$K,"Satisfactory (80%)") -> 0 | Z17: =IF(X17 <> 0,Y17/X17,"") | AA17: =AA16 -> 0 | AB17: =COUNTIFS('C+8 Data'!$AB:$AB,AA$1,'C+8 Data'!$K:$K,"Satisfactory (80%)") -> 0 | AC17: =IF(AA17 <> 0,AB17/AA17,"") | AD17: =AD16 -> 0 | AE17: =COUNTIFS('C+8 Data'!$AB:$AB,AD$1,'C+8 Data'!$K:$K,"Satisfactory (80%)") -> 0 | AF17: =IF(AD17 <> 0,AE17/AD17,"") | AG17: =AG16 -> 0 | AH17: =COUNTIFS('C+8 Data'!$AB:$AB,AG$1,'C+8 Data'!$K:$K,"Satisfactory (80%)") -> 0 | AI17: =IF(AG17 <> 0,AH17/AG17,"") | AJ17: =AJ16 -> 0 | AK17: =COUNTIFS('C+8 Data'!$AB:$AB,AJ$1,'C+8 Data'!$K:$K,"Satisfactory (80%)") -> 0 | AL17: =IF(AJ17 <> 0,AK17/AJ17,"") | AM17: =AM16 -> 0 | AN17: =COUNTIFS('C+8 Data'!$AB:$AB,AM$1,'C+8 Data'!$K:$K,"Satisfactory (80%)") -> 0 | AO17: =IF(AM17 <> 0,AN17/AM17,"")
B18: C) Good - 60% | C18: =C17 -> 1 | D18: =G18+J18+M18+P18+S18+V18+Y18+AB18+AE18+AH18+AK18+AN18 -> 0 | E18: =IF(C18 <> 0,D18/C18,"") -> 0 | F18: =F17 -> 0 | G18: =COUNTIFS('C+8 Data'!$AB:$AB,F$1,'C+8 Data'!$K:$K,"Average (60%)") -> 0 | H18: =IF(F18 <> 0,G18/F18,"") | I18: =I17 -> 1 | J18: =COUNTIFS('C+8 Data'!$AB:$AB,I$1,'C+8 Data'!$K:$K,"Average (60%)") -> 0 | K18: =IF(I18 <> 0,J18/I18,"") -> 0 | L18: =L17 -> 0 | M18: =COUNTIFS('C+8 Data'!$AB:$AB,L$1,'C+8 Data'!$K:$K,"Average (60%)") -> 0 | N18: =IF(L18 <> 0,M18/L18,"") | O18: =O17 -> 0 | P18: =COUNTIFS('C+8 Data'!$AB:$AB,O$1,'C+8 Data'!$K:$K,"Average (60%)") -> 0 | Q18: =IF(O18 <> 0,P18/O18,"") | R18: =R17 -> 0 | S18: =COUNTIFS('C+8 Data'!$AB:$AB,R$1,'C+8 Data'!$K:$K,"Average (60%)") -> 0 | T18: =IF(R18 <> 0,S18/R18,"") | U18: =U17 -> 0 | V18: =COUNTIFS('C+8 Data'!$AB:$AB,U$1,'C+8 Data'!$K:$K,"Average (60%)") -> 0 | W18: =IF(U18 <> 0,V18/U18,"") | X18: =X17 -> 0 | Y18: =COUNTIFS('C+8 Data'!$AB:$AB,X$1,'C+8 Data'!$K:$K,"Average (60%)") -> 0 | Z18: =IF(X18 <> 0,Y18/X18,"") | AA18: =AA17 -> 0 | AB18: =COUNTIFS('C+8 Data'!$AB:$AB,AA$1,'C+8 Data'!$K:$K,"Average (60%)") -> 0 | AC18: =IF(AA18 <> 0,AB18/AA18,"") | AD18: =AD17 -> 0 | AE18: =COUNTIFS('C+8 Data'!$AB:$AB,AD$1,'C+8 Data'!$K:$K,"Average (60%)") -> 0 | AF18: =IF(AD18 <> 0,AE18/AD18,"") | AG18: =AG17 -> 0 | AH18: =COUNTIFS('C+8 Data'!$AB:$AB,AG$1,'C+8 Data'!$K:$K,"Average (60%)") -> 0 | AI18: =IF(AG18 <> 0,AH18/AG18,"") | AJ18: =AJ17 -> 0 | AK18: =COUNTIFS('C+8 Data'!$AB:$AB,AJ$1,'C+8 Data'!$K:$K,"Average (60%)") -> 0 | AL18: =IF(AJ18 <> 0,AK18/AJ18,"") | AM18: =AM17 -> 0 | AN18: =COUNTIFS('C+8 Data'!$AB:$AB,AM$1,'C+8 Data'!$K:$K,"Average (60%)") -> 0 | AO18: =IF(AM18 <> 0,AN18/AM18,"")
B19: d) Fair - 40% | C19: =C18 -> 1 | D19: =G19+J19+M19+P19+S19+V19+Y19+AB19+AE19+AH19+AK19+AN19 -> 0 | E19: =IF(C19 <> 0,D19/C19,"") -> 0 | F19: =F18 -> 0 | G19: =COUNTIFS('C+8 Data'!$AB:$AB,F$1,'C+8 Data'!$K:$K,"Unsatisfactory (40%)") -> 0 | H19: =IF(F19 <> 0,G19/F19,"") | I19: =I18 -> 1 | J19: =COUNTIFS('C+8 Data'!$AB:$AB,I$1,'C+8 Data'!$K:$K,"Unsatisfactory (40%)") -> 0 | K19: =IF(I19 <> 0,J19/I19,"") -> 0 | L19: =L18 -> 0 | M19: =COUNTIFS('C+8 Data'!$AB:$AB,L$1,'C+8 Data'!$K:$K,"Unsatisfactory (40%)") -> 0 | N19: =IF(L19 <> 0,M19/L19,"") | O19: =O18 -> 0 | P19: =COUNTIFS('C+8 Data'!$AB:$AB,O$1,'C+8 Data'!$K:$K,"Unsatisfactory (40%)") -> 0 | Q19: =IF(O19 <> 0,P19/O19,"") | R19: =R18 -> 0 | S19: =COUNTIFS('C+8 Data'!$AB:$AB,R$1,'C+8 Data'!$K:$K,"Unsatisfactory (40%)") -> 0 | T19: =IF(R19 <> 0,S19/R19,"") | U19: =U18 -> 0 | V19: =COUNTIFS('C+8 Data'!$AB:$AB,U$1,'C+8 Data'!$K:$K,"Unsatisfactory (40%)") -> 0 | W19: =IF(U19 <> 0,V19/U19,"") | X19: =X18 -> 0 | Y19: =COUNTIFS('C+8 Data'!$AB:$AB,X$1,'C+8 Data'!$K:$K,"Unsatisfactory (40%)") -> 0 | Z19: =IF(X19 <> 0,Y19/X19,"") | AA19: =AA18 -> 0 | AB19: =COUNTIFS('C+8 Data'!$AB:$AB,AA$1,'C+8 Data'!$K:$K,"Unsatisfactory (40%)") -> 0 | AC19: =IF(AA19 <> 0,AB19/AA19,"") | AD19: =AD18 -> 0 | AE19: =COUNTIFS('C+8 Data'!$AB:$AB,AD$1,'C+8 Data'!$K:$K,"Unsatisfactory (40%)") -> 0 | AF19: =IF(AD19 <> 0,AE19/AD19,"") | AG19: =AG18 -> 0 | AH19: =COUNTIFS('C+8 Data'!$AB:$AB,AG$1,'C+8 Data'!$K:$K,"Unsatisfactory (40%)") -> 0 | AI19: =IF(AG19 <> 0,AH19/AG19,"") | AJ19: =AJ18 -> 0 | AK19: =COUNTIFS('C+8 Data'!$AB:$AB,AJ$1,'C+8 Data'!$K:$K,"Unsatisfactory (40%)") -> 0 | AL19: =IF(AJ19 <> 0,AK19/AJ19,"") | AM19: =AM18 -> 0 | AN19: =COUNTIFS('C+8 Data'!$AB:$AB,AM$1,'C+8 Data'!$K:$K,"Unsatisfactory (40%)") -> 0 | AO19: =IF(AM19 <> 0,AN19/AM19,"")
B20: e) Poor - 20% | C20: =C19 -> 1 | D20: =G20+J20+M20+P20+S20+V20+Y20+AB20+AE20+AH20+AK20+AN20 -> 0 | E20: =IF(C20 <> 0,D20/C20,"") -> 0 | F20: =F19 -> 0 | G20: =COUNTIFS('C+8 Data'!$AB:$AB,F$1,'C+8 Data'!$K:$K,"Very Unsatisfactory (20%)") -> 0 | H20: =IF(F20 <> 0,G20/F20,"") | I20: =I19 -> 1 | J20: =COUNTIFS('C+8 Data'!$AB:$AB,I$1,'C+8 Data'!$K:$K,"Very Unsatisfactory (20%)") -> 0 | K20: =IF(I20 <> 0,J20/I20,"") -> 0 | L20: =L19 -> 0 | M20: =COUNTIFS('C+8 Data'!$AB:$AB,L$1,'C+8 Data'!$K:$K,"Very Unsatisfactory (20%)") -> 0 | N20: =IF(L20 <> 0,M20/L20,"") | O20: =O19 -> 0 | P20: =COUNTIFS('C+8 Data'!$AB:$AB,O$1,'C+8 Data'!$K:$K,"Very Unsatisfactory (20%)") -> 0 | Q20: =IF(O20 <> 0,P20/O20,"") | R20: =R19 -> 0 | S20: =COUNTIFS('C+8 Data'!$AB:$AB,R$1,'C+8 Data'!$K:$K,"Very Unsatisfactory (20%)") -> 0 | T20: =IF(R20 <> 0,S20/R20,"") | U20: =U19 -> 0 | V20: =COUNTIFS('C+8 Data'!$AB:$AB,U$1,'C+8 Data'!$K:$K,"Very Unsatisfactory (20%)") -> 0 | W20: =IF(U20 <> 0,V20/U20,"") | X20: =X19 -> 0 | Y20: =COUNTIFS('C+8 Data'!$AB:$AB,X$1,'C+8 Data'!$K:$K,"Very Unsatisfactory (20%)") -> 0 | Z20: =IF(X20 <> 0,Y20/X20,"") | AA20: =AA19 -> 0 | AB20: =COUNTIFS('C+8 Data'!$AB:$AB,AA$1,'C+8 Data'!$K:$K,"Very Unsatisfactory (20%)") -> 0 | AC20: =IF(AA20 <> 0,AB20/AA20,"") | AD20: =AD19 -> 0 | AE20: =COUNTIFS('C+8 Data'!$AB:$AB,AD$1,'C+8 Data'!$K:$K,"Very Unsatisfactory (20%)") -> 0 | AF20: =IF(AD20 <> 0,AE20/AD20,"") | AG20: =AG19 -> 0 | AH20: =COUNTIFS('C+8 Data'!$AB:$AB,AG$1,'C+8 Data'!$K:$K,"Very Unsatisfactory (20%)") -> 0 | AI20: =IF(AG20 <> 0,AH20/AG20,"") | AJ20: =AJ19 -> 0 | AK20: =COUNTIFS('C+8 Data'!$AB:$AB,AJ$1,'C+8 Data'!$K:$K,"Very Unsatisfactory (20%)") -> 0 | AL20: =IF(AJ20 <> 0,AK20/AJ20,"") | AM20: =AM19 -> 0 | AN20: =COUNTIFS('C+8 Data'!$AB:$AB,AM$1,'C+8 Data'!$K:$K,"Very Unsatisfactory (20%)") -> 0 | AO20: =IF(AM20 <> 0,AN20/AM20,"")
A21: 4 | B21: The interval of time before the doctor could be met
B22: a) Excellent - 100% | C22: =COUNTIF('C+8 Data'!$L:$L,"<>" & "")-1 -> 1 | D22: =G22+J22+M22+P22+S22+V22+Y22+AB22+AE22+AH22+AK22+AN22 -> 1 | E22: =IF(C22 <> 0,D22/C22,"") -> 1 | F22: =COUNTIFS('C+8 Data'!$AB:$AB,F$1,'C+8 Data'!$L:$L,"<>" & "") -> 0 | G22: =COUNTIFS('C+8 Data'!$AB:$AB,F$1,'C+8 Data'!$L:$L,"Very satisfactory (100%)") -> 0 | H22: =IF(F22 <> 0,G22/F22,"") | I22: =COUNTIFS('C+8 Data'!$AB:$AB,I$1,'C+8 Data'!$L:$L,"<>" & "") -> 1 | J22: =COUNTIFS('C+8 Data'!$AB:$AB,I$1,'C+8 Data'!$L:$L,"Very satisfactory (100%)") -> 1 | K22: =IF(I22 <> 0,J22/I22,"") -> 1 | L22: =COUNTIFS('C+8 Data'!$AB:$AB,L$1,'C+8 Data'!$L:$L,"<>" & "") -> 0 | M22: =COUNTIFS('C+8 Data'!$AB:$AB,L$1,'C+8 Data'!$L:$L,"Very satisfactory (100%)") -> 0 | N22: =IF(L22 <> 0,M22/L22,"") | O22: =COUNTIFS('C+8 Data'!$AB:$AB,O$1,'C+8 Data'!$L:$L,"<>" & "") -> 0 | P22: =COUNTIFS('C+8 Data'!$AB:$AB,O$1,'C+8 Data'!$L:$L,"Very satisfactory (100%)") -> 0 | Q22: =IF(O22 <> 0,P22/O22,"") | R22: =COUNTIFS('C+8 Data'!$AB:$AB,R$1,'C+8 Data'!$L:$L,"<>" & "") -> 0 | S22: =COUNTIFS('C+8 Data'!$AB:$AB,R$1,'C+8 Data'!$L:$L,"Very satisfactory (100%)") -> 0 | T22: =IF(R22 <> 0,S22/R22,"") | U22: =COUNTIFS('C+8 Data'!$AB:$AB,U$1,'C+8 Data'!$L:$L,"<>" & "") -> 0 | V22: =COUNTIFS('C+8 Data'!$AB:$AB,U$1,'C+8 Data'!$L:$L,"Very satisfactory (100%)") -> 0 | W22: =IF(U22 <> 0,V22/U22,"") | X22: =COUNTIFS('C+8 Data'!$AB:$AB,X$1,'C+8 Data'!$L:$L,"<>" & "") -> 0 | Y22: =COUNTIFS('C+8 Data'!$AB:$AB,X$1,'C+8 Data'!$L:$L,"Very satisfactory (100%)") -> 0 | Z22: =IF(X22 <> 0,Y22/X22,"") | AA22: =COUNTIFS('C+8 Data'!$AB:$AB,AA$1,'C+8 Data'!$L:$L,"<>" & "") -> 0 | AB22: =COUNTIFS('C+8 Data'!$AB:$AB,AA$1,'C+8 Data'!$L:$L,"Very satisfactory (100%)") -> 0 | AC22: =IF(AA22 <> 0,AB22/AA22,"") | AD22: =COUNTIFS('C+8 Data'!$AB:$AB,AD$1,'C+8 Data'!$L:$L,"<>" & "") -> 0 | AE22: =COUNTIFS('C+8 Data'!$AB:$AB,AD$1,'C+8 Data'!$L:$L,"Very satisfactory (100%)") -> 0 | AF22: =IF(AD22 <> 0,AE22/AD22,"") | AG22: =COUNTIFS('C+8 Data'!$AB:$AB,AG$1,'C+8 Data'!$L:$L,"<>" & "") -> 0 | AH22: =COUNTIFS('C+8 Data'!$AB:$AB,AG$1,'C+8 Data'!$L:$L,"Very satisfactory (100%)") -> 0 | AI22: =IF(AG22 <> 0,AH22/AG22,"") | AJ22: =COUNTIFS('C+8 Data'!$AB:$AB,AJ$1,'C+8 Data'!$L:$L,"<>" & "") -> 0 | AK22: =COUNTIFS('C+8 Data'!$AB:$AB,AJ$1,'C+8 Data'!$L:$L,"Very satisfactory (100%)") -> 0 | AL22: =IF(AJ22 <> 0,AK22/AJ22,"") | AM22: =COUNTIFS('C+8 Data'!$AB:$AB,AM$1,'C+8 Data'!$L:$L,"<>" & "") -> 0 | AN22: =COUNTIFS('C+8 Data'!$AB:$AB,AM$1,'C+8 Data'!$L:$L,"Very satisfactory (100%)") -> 0 | AO22: =IF(AM22 <> 0,AN22/AM22,"")
B23: b) V.Good - 80% | C23: =C22 -> 1 | D23: =G23+J23+M23+P23+S23+V23+Y23+AB23+AE23+AH23+AK23+AN23 -> 0 | E23: =IF(C23 <> 0,D23/C23,"") -> 0 | F23: =F22 -> 0 | G23: =COUNTIFS('C+8 Data'!$AB:$AB,F$1,'C+8 Data'!$L:$L,"Satisfactory (80%)") -> 0 | H23: =IF(F23 <> 0,G23/F23,"") | I23: =I22 -> 1 | J23: =COUNTIFS('C+8 Data'!$AB:$AB,I$1,'C+8 Data'!$L:$L,"Satisfactory (80%)") -> 0 | K23: =IF(I23 <> 0,J23/I23,"") -> 0 | L23: =L22 -> 0 | M23: =COUNTIFS('C+8 Data'!$AB:$AB,L$1,'C+8 Data'!$L:$L,"Satisfactory (80%)") -> 0 | N23: =IF(L23 <> 0,M23/L23,"") | O23: =O22 -> 0 | P23: =COUNTIFS('C+8 Data'!$AB:$AB,O$1,'C+8 Data'!$L:$L,"Satisfactory (80%)") -> 0 | Q23: =IF(O23 <> 0,P23/O23,"") | R23: =R22 -> 0 | S23: =COUNTIFS('C+8 Data'!$AB:$AB,R$1,'C+8 Data'!$L:$L,"Satisfactory (80%)") -> 0 | T23: =IF(R23 <> 0,S23/R23,"") | U23: =U22 -> 0 | V23: =COUNTIFS('C+8 Data'!$AB:$AB,U$1,'C+8 Data'!$L:$L,"Satisfactory (80%)") -> 0 | W23: =IF(U23 <> 0,V23/U23,"") | X23: =X22 -> 0 | Y23: =COUNTIFS('C+8 Data'!$AB:$AB,X$1,'C+8 Data'!$L:$L,"Satisfactory (80%)") -> 0 | Z23: =IF(X23 <> 0,Y23/X23,"") | AA23: =AA22 -> 0 | AB23: =COUNTIFS('C+8 Data'!$AB:$AB,AA$1,'C+8 Data'!$L:$L,"Satisfactory (80%)") -> 0 | AC23: =IF(AA23 <> 0,AB23/AA23,"") | AD23: =AD22 -> 0 | AE23: =COUNTIFS('C+8 Data'!$AB:$AB,AD$1,'C+8 Data'!$L:$L,"Satisfactory (80%)") -> 0 | AF23: =IF(AD23 <> 0,AE23/AD23,"") | AG23: =AG22 -> 0 | AH23: =COUNTIFS('C+8 Data'!$AB:$AB,AG$1,'C+8 Data'!$L:$L,"Satisfactory (80%)") -> 0 | AI23: =IF(AG23 <> 0,AH23/AG23,"") | AJ23: =AJ22 -> 0 | AK23: =COUNTIFS('C+8 Data'!$AB:$AB,AJ$1,'C+8 Data'!$L:$L,"Satisfactory (80%)") -> 0 | AL23: =IF(AJ23 <> 0,AK23/AJ23,"") | AM23: =AM22 -> 0 | AN23: =COUNTIFS('C+8 Data'!$AB:$AB,AM$1,'C+8 Data'!$L:$L,"Satisfactory (80%)") -> 0 | AO23: =IF(AM23 <> 0,AN23/AM23,"")
B24: C) Good - 60% | C24: =C23 -> 1 | D24: =G24+J24+M24+P24+S24+V24+Y24+AB24+AE24+AH24+AK24+AN24 -> 0 | E24: =IF(C24 <> 0,D24/C24,"") -> 0 | F24: =F23 -> 0 | G24: =COUNTIFS('C+8 Data'!$AB:$AB,F$1,'C+8 Data'!$L:$L,"Average (60%)") -> 0 | H24: =IF(F24 <> 0,G24/F24,"") | I24: =I23 -> 1 | J24: =COUNTIFS('C+8 Data'!$AB:$AB,I$1,'C+8 Data'!$L:$L,"Average (60%)") -> 0 | K24: =IF(I24 <> 0,J24/I24,"") -> 0 | L24: =L23 -> 0 | M24: =COUNTIFS('C+8 Data'!$AB:$AB,L$1,'C+8 Data'!$L:$L,"Average (60%)") -> 0 | N24: =IF(L24 <> 0,M24/L24,"") | O24: =O23 -> 0 | P24: =COUNTIFS('C+8 Data'!$AB:$AB,O$1,'C+8 Data'!$L:$L,"Average (60%)") -> 0 | Q24: =IF(O24 <> 0,P24/O24,"") | R24: =R23 -> 0 | S24: =COUNTIFS('C+8 Data'!$AB:$AB,R$1,'C+8 Data'!$L:$L,"Average (60%)") -> 0 | T24: =IF(R24 <> 0,S24/R24,"") | U24: =U23 -> 0 | V24: =COUNTIFS('C+8 Data'!$AB:$AB,U$1,'C+8 Data'!$L:$L,"Average (60%)") -> 0 | W24: =IF(U24 <> 0,V24/U24,"") | X24: =X23 -> 0 | Y24: =COUNTIFS('C+8 Data'!$AB:$AB,X$1,'C+8 Data'!$L:$L,"Average (60%)") -> 0 | Z24: =IF(X24 <> 0,Y24/X24,"") | AA24: =AA23 -> 0 | AB24: =COUNTIFS('C+8 Data'!$AB:$AB,AA$1,'C+8 Data'!$L:$L,"Average (60%)") -> 0 | AC24: =IF(AA24 <> 0,AB24/AA24,"") | AD24: =AD23 -> 0 | AE24: =COUNTIFS('C+8 Data'!$AB:$AB,AD$1,'C+8 Data'!$L:$L,"Average (60%)") -> 0 | AF24: =IF(AD24 <> 0,AE24/AD24,"") | AG24: =AG23 -> 0 | AH24: =COUNTIFS('C+8 Data'!$AB:$AB,AG$1,'C+8 Data'!$L:$L,"Average (60%)") -> 0 | AI24: =IF(AG24 <> 0,AH24/AG24,"") | AJ24: =AJ23 -> 0 | AK24: =COUNTIFS('C+8 Data'!$AB:$AB,AJ$1,'C+8 Data'!$L:$L,"Average (60%)") -> 0 | AL24: =IF(AJ24 <> 0,AK24/AJ24,"") | AM24: =AM23 -> 0 | AN24: =COUNTIFS('C+8 Data'!$AB:$AB,AM$1,'C+8 Data'!$L:$L,"Average (60%)") -> 0 | AO24: =IF(AM24 <> 0,AN24/AM24,"")
B25: d) Fair - 40% | C25: =C24 -> 1 | D25: =G25+J25+M25+P25+S25+V25+Y25+AB25+AE25+AH25+AK25+AN25 -> 0 | E25: =IF(C25 <> 0,D25/C25,"") -> 0 | F25: =F24 -> 0 | G25: =COUNTIFS('C+8 Data'!$AB:$AB,F$1,'C+8 Data'!$L:$L,"Unsatisfactory (40%)") -> 0 | H25: =IF(F25 <> 0,G25/F25,"") | I25: =I24 -> 1 | J25: =COUNTIFS('C+8 Data'!$AB:$AB,I$1,'C+8 Data'!$L:$L,"Unsatisfactory (40%)") -> 0 | K25: =IF(I25 <> 0,J25/I25,"") -> 0 | L25: =L24 -> 0 | M25: =COUNTIFS('C+8 Data'!$AB:$AB,L$1,'C+8 Data'!$L:$L,"Unsatisfactory (40%)") -> 0 | N25: =IF(L25 <> 0,M25/L25,"") | O25: =O24 -> 0 | P25: =COUNTIFS('C+8 Data'!$AB:$AB,O$1,'C+8 Data'!$L:$L,"Unsatisfactory (40%)") -> 0 | Q25: =IF(O25 <> 0,P25/O25,"") | R25: =R24 -> 0 | S25: =COUNTIFS('C+8 Data'!$AB:$AB,R$1,'C+8 Data'!$L:$L,"Unsatisfactory (40%)") -> 0 | T25: =IF(R25 <> 0,S25/R25,"") | U25: =U24 -> 0 | V25: =COUNTIFS('C+8 Data'!$AB:$AB,U$1,'C+8 Data'!$L:$L,"Unsatisfactory (40%)") -> 0 | W25: =IF(U25 <> 0,V25/U25,"") | X25: =X24 -> 0 | Y25: =COUNTIFS('C+8 Data'!$AB:$AB,X$1,'C+8 Data'!$L:$L,"Unsatisfactory (40%)") -> 0 | Z25: =IF(X25 <> 0,Y25/X25,"") | AA25: =AA24 -> 0 | AB25: =COUNTIFS('C+8 Data'!$AB:$AB,AA$1,'C+8 Data'!$L:$L,"Unsatisfactory (40%)") -> 0 | AC25: =IF(AA25 <> 0,AB25/AA25,"") | AD25: =AD24 -> 0 | AE25: =COUNTIFS('C+8 Data'!$AB:$AB,AD$1,'C+8 Data'!$L:$L,"Unsatisfactory (40%)") -> 0 | AF25: =IF(AD25 <> 0,AE25/AD25,"") | AG25: =AG24 -> 0 | AH25: =COUNTIFS('C+8 Data'!$AB:$AB,AG$1,'C+8 Data'!$L:$L,"Unsatisfactory (40%)") -> 0 | AI25: =IF(AG25 <> 0,AH25/AG25,"") | AJ25: =AJ24 -> 0 | AK25: =COUNTIFS('C+8 Data'!$AB:$AB,AJ$1,'C+8 Data'!$L:$L,"Unsatisfactory (40%)") -> 0 | AL25: =IF(AJ25 <> 0,AK25/AJ25,"") | AM25: =AM24 -> 0 | AN25: =COUNTIFS('C+8 Data'!$AB:$AB,AM$1,'C+8 Data'!$L:$L,"Unsatisfactory (40%)") -> 0 | AO25: =IF(AM25 <> 0,AN25/AM25,"")
B26: e) Poor - 20% | C26: =C25 -> 1 | D26: =G26+J26+M26+P26+S26+V26+Y26+AB26+AE26+AH26+AK26+AN26 -> 0 | E26: =IF(C26 <> 0,D26/C26,"") -> 0 | F26: =F25 -> 0 | G26: =COUNTIFS('C+8 Data'!$AB:$AB,F$1,'C+8 Data'!$L:$L,"Very Unsatisfactory (20%)") -> 0 | H26: =IF(F26 <> 0,G26/F26,"") | I26: =I25 -> 1 | J26: =COUNTIFS('C+8 Data'!$AB:$AB,I$1,'C+8 Data'!$L:$L,"Very Unsatisfactory (20%)") -> 0 | K26: =IF(I26 <> 0,J26/I26,"") -> 0 | L26: =L25 -> 0 | M26: =COUNTIFS('C+8 Data'!$AB:$AB,L$1,'C+8 Data'!$L:$L,"Very Unsatisfactory (20%)") -> 0 | N26: =IF(L26 <> 0,M26/L26,"") | O26: =O25 -> 0 | P26: =COUNTIFS('C+8 Data'!$AB:$AB,O$1,'C+8 Data'!$L:$L,"Very Unsatisfactory (20%)") -> 0 | Q26: =IF(O26 <> 0,P26/O26,"") | R26: =R25 -> 0 | S26: =COUNTIFS('C+8 Data'!$AB:$AB,R$1,'C+8 Data'!$L:$L,"Very Unsatisfactory (20%)") -> 0 | T26: =IF(R26 <> 0,S26/R26,"") | U26: =U25 -> 0 | V26: =COUNTIFS('C+8 Data'!$AB:$AB,U$1,'C+8 Data'!$L:$L,"Very Unsatisfactory (20%)") -> 0 | W26: =IF(U26 <> 0,V26/U26,"") | X26: =X25 -> 0 | Y26: =COUNTIFS('C+8 Data'!$AB:$AB,X$1,'C+8 Data'!$L:$L,"Very Unsatisfactory (20%)") -> 0 | Z26: =IF(X26 <> 0,Y26/X26,"") | AA26: =AA25 -> 0 | AB26: =COUNTIFS('C+8 Data'!$AB:$AB,AA$1,'C+8 Data'!$L:$L,"Very Unsatisfactory (20%)") -> 0 | AC26: =IF(AA26 <> 0,AB26/AA26,"") | AD26: =AD25 -> 0 | AE26: =COUNTIFS('C+8 Data'!$AB:$AB,AD$1,'C+8 Data'!$L:$L,"Very Unsatisfactory (20%)") -> 0 | AF26: =IF(AD26 <> 0,AE26/AD26,"") | AG26: =AG25 -> 0 | AH26: =COUNTIFS('C+8 Data'!$AB:$AB,AG$1,'C+8 Data'!$L:$L,"Very Unsatisfactory (20%)") -> 0 | AI26: =IF(AG26 <> 0,AH26/AG26,"") | AJ26: =AJ25 -> 0 | AK26: =COUNTIFS('C+8 Data'!$AB:$AB,AJ$1,'C+8 Data'!$L:$L,"Very Unsatisfactory (20%)") -> 0 | AL26: =IF(AJ26 <> 0,AK26/AJ26,"") | AM26: =AM25 -> 0 | AN26: =COUNTIFS('C+8 Data'!$AB:$AB,AM$1,'C+8 Data'!$L:$L,"Very Unsatisfactory (20%)") -> 0 | AO26: =IF(AM26 <> 0,AN26/AM26,"")
A27: 5 | B27: Time spent by the doctor with you for screening and main consultation
B28: a) Excellent - 100% | C28: =COUNTIF('C+8 Data'!$M:$M,"<>" & "")-1 -> 1 | D28: =G28+J28+M28+P28+S28+V28+Y28+AB28+AE28+AH28+AK28+AN28 -> 1 | E28: =IF(C28 <> 0,D28/C28,"") -> 1 | F28: =COUNTIFS('C+8 Data'!$AB:$AB,F$1,'C+8 Data'!$M:$M,"<>" & "") -> 0 | G28: =COUNTIFS('C+8 Data'!$AB:$AB,F$1,'C+8 Data'!$M:$M,"Very satisfactory (100%)") -> 0 | H28: =IF(F28 <> 0,G28/F28,"") | I28: =COUNTIFS('C+8 Data'!$AB:$AB,I$1,'C+8 Data'!$M:$M,"<>" & "") -> 1 | J28: =COUNTIFS('C+8 Data'!$AB:$AB,I$1,'C+8 Data'!$M:$M,"Very satisfactory (100%)") -> 1 | K28: =IF(I28 <> 0,J28/I28,"") -> 1 | L28: =COUNTIFS('C+8 Data'!$AB:$AB,L$1,'C+8 Data'!$M:$M,"<>" & "") -> 0 | M28: =COUNTIFS('C+8 Data'!$AB:$AB,L$1,'C+8 Data'!$M:$M,"Very satisfactory (100%)") -> 0 | N28: =IF(L28 <> 0,M28/L28,"") | O28: =COUNTIFS('C+8 Data'!$AB:$AB,O$1,'C+8 Data'!$M:$M,"<>" & "") -> 0 | P28: =COUNTIFS('C+8 Data'!$AB:$AB,O$1,'C+8 Data'!$M:$M,"Very satisfactory (100%)") -> 0 | Q28: =IF(O28 <> 0,P28/O28,"") | R28: =COUNTIFS('C+8 Data'!$AB:$AB,R$1,'C+8 Data'!$M:$M,"<>" & "") -> 0 | S28: =COUNTIFS('C+8 Data'!$AB:$AB,R$1,'C+8 Data'!$M:$M,"Very satisfactory (100%)") -> 0 | T28: =IF(R28 <> 0,S28/R28,"") | U28: =COUNTIFS('C+8 Data'!$AB:$AB,U$1,'C+8 Data'!$M:$M,"<>" & "") -> 0 | V28: =COUNTIFS('C+8 Data'!$AB:$AB,U$1,'C+8 Data'!$M:$M,"Very satisfactory (100%)") -> 0 | W28: =IF(U28 <> 0,V28/U28,"") | X28: =COUNTIFS('C+8 Data'!$AB:$AB,X$1,'C+8 Data'!$M:$M,"<>" & "") -> 0 | Y28: =COUNTIFS('C+8 Data'!$AB:$AB,X$1,'C+8 Data'!$M:$M,"Very satisfactory (100%)") -> 0 | Z28: =IF(X28 <> 0,Y28/X28,"") | AA28: =COUNTIFS('C+8 Data'!$AB:$AB,AA$1,'C+8 Data'!$M:$M,"<>" & "") -> 0 | AB28: =COUNTIFS('C+8 Data'!$AB:$AB,AA$1,'C+8 Data'!$M:$M,"Very satisfactory (100%)") -> 0 | AC28: =IF(AA28 <> 0,AB28/AA28,"") | AD28: =COUNTIFS('C+8 Data'!$AB:$AB,AD$1,'C+8 Data'!$M:$M,"<>" & "") -> 0 | AE28: =COUNTIFS('C+8 Data'!$AB:$AB,AD$1,'C+8 Data'!$M:$M,"Very satisfactory (100%)") -> 0 | AF28: =IF(AD28 <> 0,AE28/AD28,"") | AG28: =COUNTIFS('C+8 Data'!$AB:$AB,AG$1,'C+8 Data'!$M:$M,"<>" & "") -> 0 | AH28: =COUNTIFS('C+8 Data'!$AB:$AB,AG$1,'C+8 Data'!$M:$M,"Very satisfactory (100%)") -> 0 | AI28: =IF(AG28 <> 0,AH28/AG28,"") | AJ28: =COUNTIFS('C+8 Data'!$AB:$AB,AJ$1,'C+8 Data'!$M:$M,"<>" & "") -> 0 | AK28: =COUNTIFS('C+8 Data'!$AB:$AB,AJ$1,'C+8 Data'!$M:$M,"Very satisfactory (100%)") -> 0 | AL28: =IF(AJ28 <> 0,AK28/AJ28,"") | AM28: =COUNTIFS('C+8 Data'!$AB:$AB,AM$1,'C+8 Data'!$M:$M,"<>" & "") -> 0 | AN28: =COUNTIFS('C+8 Data'!$AB:$AB,AM$1,'C+8 Data'!$M:$M,"Very satisfactory (100%)") -> 0 | AO28: =IF(AM28 <> 0,AN28/AM28,"")
B29: b) V.Good - 80% | C29: =C28 -> 1 | D29: =G29+J29+M29+P29+S29+V29+Y29+AB29+AE29+AH29+AK29+AN29 -> 0 | E29: =IF(C29 <> 0,D29/C29,"") -> 0 | F29: =F28 -> 0 | G29: =COUNTIFS('C+8 Data'!$AB:$AB,F$1,'C+8 Data'!$M:$M,"Satisfactory (80%)") -> 0 | H29: =IF(F29 <> 0,G29/F29,"") | I29: =I28 -> 1 | J29: =COUNTIFS('C+8 Data'!$AB:$AB,I$1,'C+8 Data'!$M:$M,"Satisfactory (80%)") -> 0 | K29: =IF(I29 <> 0,J29/I29,"") -> 0 | L29: =L28 -> 0 | M29: =COUNTIFS('C+8 Data'!$AB:$AB,L$1,'C+8 Data'!$M:$M,"Satisfactory (80%)") -> 0 | N29: =IF(L29 <> 0,M29/L29,"") | O29: =O28 -> 0 | P29: =COUNTIFS('C+8 Data'!$AB:$AB,O$1,'C+8 Data'!$M:$M,"Satisfactory (80%)") -> 0 | Q29: =IF(O29 <> 0,P29/O29,"") | R29: =R28 -> 0 | S29: =COUNTIFS('C+8 Data'!$AB:$AB,R$1,'C+8 Data'!$M:$M,"Satisfactory (80%)") -> 0 | T29: =IF(R29 <> 0,S29/R29,"") | U29: =U28 -> 0 | V29: =COUNTIFS('C+8 Data'!$AB:$AB,U$1,'C+8 Data'!$M:$M,"Satisfactory (80%)") -> 0 | W29: =IF(U29 <> 0,V29/U29,"") | X29: =X28 -> 0 | Y29: =COUNTIFS('C+8 Data'!$AB:$AB,X$1,'C+8 Data'!$M:$M,"Satisfactory (80%)") -> 0 | Z29: =IF(X29 <> 0,Y29/X29,"") | AA29: =AA28 -> 0 | AB29: =COUNTIFS('C+8 Data'!$AB:$AB,AA$1,'C+8 Data'!$M:$M,"Satisfactory (80%)") -> 0 | AC29: =IF(AA29 <> 0,AB29/AA29,"") | AD29: =AD28 -> 0 | AE29: =COUNTIFS('C+8 Data'!$AB:$AB,AD$1,'C+8 Data'!$M:$M,"Satisfactory (80%)") -> 0 | AF29: =IF(AD29 <> 0,AE29/AD29,"") | AG29: =AG28 -> 0 | AH29: =COUNTIFS('C+8 Data'!$AB:$AB,AG$1,'C+8 Data'!$M:$M,"Satisfactory (80%)") -> 0 | AI29: =IF(AG29 <> 0,AH29/AG29,"") | AJ29: =AJ28 -> 0 | AK29: =COUNTIFS('C+8 Data'!$AB:$AB,AJ$1,'C+8 Data'!$M:$M,"Satisfactory (80%)") -> 0 | AL29: =IF(AJ29 <> 0,AK29/AJ29,"") | AM29: =AM28 -> 0 | AN29: =COUNTIFS('C+8 Data'!$AB:$AB,AM$1,'C+8 Data'!$M:$M,"Satisfactory (80%)") -> 0 | AO29: =IF(AM29 <> 0,AN29/AM29,"")
B30: C) Good - 60% | C30: =C29 -> 1 | D30: =G30+J30+M30+P30+S30+V30+Y30+AB30+AE30+AH30+AK30+AN30 -> 0 | E30: =IF(C30 <> 0,D30/C30,"") -> 0 | F30: =F29 -> 0 | G30: =COUNTIFS('C+8 Data'!$AB:$AB,F$1,'C+8 Data'!$M:$M,"Average (60%)") -> 0 | H30: =IF(F30 <> 0,G30/F30,"") | I30: =I29 -> 1 | J30: =COUNTIFS('C+8 Data'!$AB:$AB,I$1,'C+8 Data'!$M:$M,"Average (60%)") -> 0 | K30: =IF(I30 <> 0,J30/I30,"") -> 0 | L30: =L29 -> 0 | M30: =COUNTIFS('C+8 Data'!$AB:$AB,L$1,'C+8 Data'!$M:$M,"Average (60%)") -> 0 | N30: =IF(L30 <> 0,M30/L30,"") | O30: =O29 -> 0 | P30: =COUNTIFS('C+8 Data'!$AB:$AB,O$1,'C+8 Data'!$M:$M,"Average (60%)") -> 0 | Q30: =IF(O30 <> 0,P30/O30,"") | R30: =R29 -> 0 | S30: =COUNTIFS('C+8 Data'!$AB:$AB,R$1,'C+8 Data'!$M:$M,"Average (60%)") -> 0 | T30: =IF(R30 <> 0,S30/R30,"") | U30: =U29 -> 0 | V30: =COUNTIFS('C+8 Data'!$AB:$AB,U$1,'C+8 Data'!$M:$M,"Average (60%)") -> 0 | W30: =IF(U30 <> 0,V30/U30,"") | X30: =X29 -> 0 | Y30: =COUNTIFS('C+8 Data'!$AB:$AB,X$1,'C+8 Data'!$M:$M,"Average (60%)") -> 0 | Z30: =IF(X30 <> 0,Y30/X30,"") | AA30: =AA29 -> 0 | AB30: =COUNTIFS('C+8 Data'!$AB:$AB,AA$1,'C+8 Data'!$M:$M,"Average (60%)") -> 0 | AC30: =IF(AA30 <> 0,AB30/AA30,"") | AD30: =AD29 -> 0 | AE30: =COUNTIFS('C+8 Data'!$AB:$AB,AD$1,'C+8 Data'!$M:$M,"Average (60%)") -> 0 | AF30: =IF(AD30 <> 0,AE30/AD30,"") | AG30: =AG29 -> 0 | AH30: =COUNTIFS('C+8 Data'!$AB:$AB,AG$1,'C+8 Data'!$M:$M,"Average (60%)") -> 0 | AI30: =IF(AG30 <> 0,AH30/AG30,"") | AJ30: =AJ29 -> 0 | AK30: =COUNTIFS('C+8 Data'!$AB:$AB,AJ$1,'C+8 Data'!$M:$M,"Average (60%)") -> 0 | AL30: =IF(AJ30 <> 0,AK30/AJ30,"") | AM30: =AM29 -> 0 | AN30: =COUNTIFS('C+8 Data'!$AB:$AB,AM$1,'C+8 Data'!$M:$M,"Average (60%)") -> 0 | AO30: =IF(AM30 <> 0,AN30/AM30,"")
B31: d) Fair - 40% | C31: =C30 -> 1 | D31: =G31+J31+M31+P31+S31+V31+Y31+AB31+AE31+AH31+AK31+AN31 -> 0 | E31: =IF(C31 <> 0,D31/C31,"") -> 0 | F31: =F30 -> 0 | G31: =COUNTIFS('C+8 Data'!$AB:$AB,F$1,'C+8 Data'!$M:$M,"Unsatisfactory (40%)") -> 0 | H31: =IF(F31 <> 0,G31/F31,"") | I31: =I30 -> 1 | J31: =COUNTIFS('C+8 Data'!$AB:$AB,I$1,'C+8 Data'!$M:$M,"Unsatisfactory (40%)") -> 0 | K31: =IF(I31 <> 0,J31/I31,"") -> 0 | L31: =L30 -> 0 | M31: =COUNTIFS('C+8 Data'!$AB:$AB,L$1,'C+8 Data'!$M:$M,"Unsatisfactory (40%)") -> 0 | N31: =IF(L31 <> 0,M31/L31,"") | O31: =O30 -> 0 | P31: =COUNTIFS('C+8 Data'!$AB:$AB,O$1,'C+8 Data'!$M:$M,"Unsatisfactory (40%)") -> 0 | Q31: =IF(O31 <> 0,P31/O31,"") | R31: =R30 -> 0 | S31: =COUNTIFS('C+8 Data'!$AB:$AB,R$1,'C+8 Data'!$M:$M,"Unsatisfactory (40%)") -> 0 | T31: =IF(R31 <> 0,S31/R31,"") | U31: =U30 -> 0 | V31: =COUNTIFS('C+8 Data'!$AB:$AB,U$1,'C+8 Data'!$M:$M,"Unsatisfactory (40%)") -> 0 | W31: =IF(U31 <> 0,V31/U31,"") | X31: =X30 -> 0 | Y31: =COUNTIFS('C+8 Data'!$AB:$AB,X$1,'C+8 Data'!$M:$M,"Unsatisfactory (40%)") -> 0 | Z31: =IF(X31 <> 0,Y31/X31,"") | AA31: =AA30 -> 0 | AB31: =COUNTIFS('C+8 Data'!$AB:$AB,AA$1,'C+8 Data'!$M:$M,"Unsatisfactory (40%)") -> 0 | AC31: =IF(AA31 <> 0,AB31/AA31,"") | AD31: =AD30 -> 0 | AE31: =COUNTIFS('C+8 Data'!$AB:$AB,AD$1,'C+8 Data'!$M:$M,"Unsatisfactory (40%)") -> 0 | AF31: =IF(AD31 <> 0,AE31/AD31,"") | AG31: =AG30 -> 0 | AH31: =COUNTIFS('C+8 Data'!$AB:$AB,AG$1,'C+8 Data'!$M:$M,"Unsatisfactory (40%)") -> 0 | AI31: =IF(AG31 <> 0,AH31/AG31,"") | AJ31: =AJ30 -> 0 | AK31: =COUNTIFS('C+8 Data'!$AB:$AB,AJ$1,'C+8 Data'!$M:$M,"Unsatisfactory (40%)") -> 0 | AL31: =IF(AJ31 <> 0,AK31/AJ31,"") | AM31: =AM30 -> 0 | AN31: =COUNTIFS('C+8 Data'!$AB:$AB,AM$1,'C+8 Data'!$M:$M,"Unsatisfactory (40%)") -> 0 | AO31: =IF(AM31 <> 0,AN31/AM31,"")
B32: e) Poor - 20% | C32: =C31 -> 1 | D32: =G32+J32+M32+P32+S32+V32+Y32+AB32+AE32+AH32+AK32+AN32 -> 0 | E32: =IF(C32 <> 0,D32/C32,"") -> 0 | F32: =F31 -> 0 | G32: =COUNTIFS('C+8 Data'!$AB:$AB,F$1,'C+8 Data'!$M:$M,"Very Unsatisfactory (20%)") -> 0 | H32: =IF(F32 <> 0,G32/F32,"") | I32: =I31 -> 1 | J32: =COUNTIFS('C+8 Data'!$AB:$AB,I$1,'C+8 Data'!$M:$M,"Very Unsatisfactory (20%)") -> 0 | K32: =IF(I32 <> 0,J32/I32,"") -> 0 | L32: =L31 -> 0 | M32: =COUNTIFS('C+8 Data'!$AB:$AB,L$1,'C+8 Data'!$M:$M,"Very Unsatisfactory (20%)") -> 0 | N32: =IF(L32 <> 0,M32/L32,"") | O32: =O31 -> 0 | P32: =COUNTIFS('C+8 Data'!$AB:$AB,O$1,'C+8 Data'!$M:$M,"Very Unsatisfactory (20%)") -> 0 | Q32: =IF(O32 <> 0,P32/O32,"") | R32: =R31 -> 0 | S32: =COUNTIFS('C+8 Data'!$AB:$AB,R$1,'C+8 Data'!$M:$M,"Very Unsatisfactory (20%)") -> 0 | T32: =IF(R32 <> 0,S32/R32,"") | U32: =U31 -> 0 | V32: =COUNTIFS('C+8 Data'!$AB:$AB,U$1,'C+8 Data'!$M:$M,"Very Unsatisfactory (20%)") -> 0 | W32: =IF(U32 <> 0,V32/U32,"") | X32: =X31 -> 0 | Y32: =COUNTIFS('C+8 Data'!$AB:$AB,X$1,'C+8 Data'!$M:$M,"Very Unsatisfactory (20%)") -> 0 | Z32: =IF(X32 <> 0,Y32/X32,"") | AA32: =AA31 -> 0 | AB32: =COUNTIFS('C+8 Data'!$AB:$AB,AA$1,'C+8 Data'!$M:$M,"Very Unsatisfactory (20%)") -> 0 | AC32: =IF(AA32 <> 0,AB32/AA32,"") | AD32: =AD31 -> 0 | AE32: =COUNTIFS('C+8 Data'!$AB:$AB,AD$1,'C+8 Data'!$M:$M,"Very Unsatisfactory (20%)") -> 0 | AF32: =IF(AD32 <> 0,AE32/AD32,"") | AG32: =AG31 -> 0 | AH32: =COUNTIFS('C+8 Data'!$AB:$AB,AG$1,'C+8 Data'!$M:$M,"Very Unsatisfactory (20%)") -> 0 | AI32: =IF(AG32 <> 0,AH32/AG32,"") | AJ32: =AJ31 -> 0 | AK32: =COUNTIFS('C+8 Data'!$AB:$AB,AJ$1,'C+8 Data'!$M:$M,"Very Unsatisfactory (20%)") -> 0 | AL32: =IF(AJ32 <> 0,AK32/AJ32,"") | AM32: =AM31 -> 0 | AN32: =COUNTIFS('C+8 Data'!$AB:$AB,AM$1,'C+8 Data'!$M:$M,"Very Unsatisfactory (20%)") -> 0 | AO32: =IF(AM32 <> 0,AN32/AM32,"")
A33: 6 | B33: Do you think your health needs have been understood clearly by the doctor?
B34: Yes | C34: =COUNTIF('C+8 Data'!$O:$O,"<>" & "")-1 -> 1 | D34: =G34+J34+M34+P34+S34+V34+Y34+AB34+AE34+AH34+AK34+AN34 -> 1 | E34: =IF(C34 <> 0,D34/C34,"") -> 1 | F34: =COUNTIFS('C+8 Data'!$AB:$AB,F$1,'C+8 Data'!$O:$O,"<>" & "") -> 0 | G34: =COUNTIFS('C+8 Data'!$AB:$AB,F$1,'C+8 Data'!$O:$O,$B34) -> 0 | H34: =IF(F34 <> 0,G34/F34,"") | I34: =COUNTIFS('C+8 Data'!$AB:$AB,I$1,'C+8 Data'!$O:$O,"<>" & "") -> 1 | J34: =COUNTIFS('C+8 Data'!$AB:$AB,I$1,'C+8 Data'!$O:$O,$B34) -> 1 | K34: =IF(I34 <> 0,J34/I34,"") -> 1 | L34: =COUNTIFS('C+8 Data'!$AB:$AB,L$1,'C+8 Data'!$O:$O,"<>" & "") -> 0 | M34: =COUNTIFS('C+8 Data'!$AB:$AB,L$1,'C+8 Data'!$O:$O,$B34) -> 0 | N34: =IF(L34 <> 0,M34/L34,"") | O34: =COUNTIFS('C+8 Data'!$AB:$AB,O$1,'C+8 Data'!$O:$O,"<>" & "") -> 0 | P34: =COUNTIFS('C+8 Data'!$AB:$AB,O$1,'C+8 Data'!$O:$O,$B34) -> 0 | Q34: =IF(O34 <> 0,P34/O34,"") | R34: =COUNTIFS('C+8 Data'!$AB:$AB,R$1,'C+8 Data'!$O:$O,"<>" & "") -> 0 | S34: =COUNTIFS('C+8 Data'!$AB:$AB,R$1,'C+8 Data'!$O:$O,$B34) -> 0 | T34: =IF(R34 <> 0,S34/R34,"") | U34: =COUNTIFS('C+8 Data'!$AB:$AB,U$1,'C+8 Data'!$O:$O,"<>" & "") -> 0 | V34: =COUNTIFS('C+8 Data'!$AB:$AB,U$1,'C+8 Data'!$O:$O,$B34) -> 0 | W34: =IF(U34 <> 0,V34/U34,"") | X34: =COUNTIFS('C+8 Data'!$AB:$AB,X$1,'C+8 Data'!$O:$O,"<>" & "") -> 0 | Y34: =COUNTIFS('C+8 Data'!$AB:$AB,X$1,'C+8 Data'!$O:$O,$B34) -> 0 | Z34: =IF(X34 <> 0,Y34/X34,"") | AA34: =COUNTIFS('C+8 Data'!$AB:$AB,AA$1,'C+8 Data'!$O:$O,"<>" & "") -> 0 | AB34: =COUNTIFS('C+8 Data'!$AB:$AB,AA$1,'C+8 Data'!$O:$O,$B34) -> 0 | AC34: =IF(AA34 <> 0,AB34/AA34,"") | AD34: =COUNTIFS('C+8 Data'!$AB:$AB,AD$1,'C+8 Data'!$O:$O,"<>" & "") -> 0 | AE34: =COUNTIFS('C+8 Data'!$AB:$AB,AD$1,'C+8 Data'!$O:$O,$B34) -> 0 | AF34: =IF(AD34 <> 0,AE34/AD34,"") | AG34: =COUNTIFS('C+8 Data'!$AB:$AB,AG$1,'C+8 Data'!$O:$O,"<>" & "") -> 0 | AH34: =COUNTIFS('C+8 Data'!$AB:$AB,AG$1,'C+8 Data'!$O:$O,$B34) -> 0 | AI34: =IF(AG34 <> 0,AH34/AG34,"") | AJ34: =COUNTIFS('C+8 Data'!$AB:$AB,AJ$1,'C+8 Data'!$O:$O,"<>" & "") -> 0 | AK34: =COUNTIFS('C+8 Data'!$AB:$AB,AJ$1,'C+8 Data'!$O:$O,$B34) -> 0 | AL34: =IF(AJ34 <> 0,AK34/AJ34,"") | AM34: =COUNTIFS('C+8 Data'!$AB:$AB,AM$1,'C+8 Data'!$O:$O,"<>" & "") -> 0 | AN34: =COUNTIFS('C+8 Data'!$AB:$AB,AM$1,'C+8 Data'!$O:$O,$B34) -> 0 | AO34: =IF(AM34 <> 0,AN34/AM34,"")
B35: No | C35: =C34 -> 1 | D35: =G35+J35+M35+P35+S35+V35+Y35+AB35+AE35+AH35+AK35+AN35 -> 0 | E35: =IF(C35 <> 0,D35/C35,"") -> 0 | F35: =F34 -> 0 | G35: =COUNTIFS('C+8 Data'!$H:$H,F$1,'C+8 Data'!$O:$O,$B35) -> 0 | H35: =IF(F35 <> 0,G35/F35,"") | I35: =I34 -> 1 | J35: =COUNTIFS('C+8 Data'!$H:$H,I$1,'C+8 Data'!$O:$O,$B35) -> 0 | K35: =IF(I35 <> 0,J35/I35,"") -> 0 | L35: =L34 -> 0 | M35: =COUNTIFS('C+8 Data'!$H:$H,L$1,'C+8 Data'!$O:$O,$B35) -> 0 | N35: =IF(L35 <> 0,M35/L35,"") | O35: =O34 -> 0 | P35: =COUNTIFS('C+8 Data'!$H:$H,O$1,'C+8 Data'!$O:$O,$B35) -> 0 | Q35: =IF(O35 <> 0,P35/O35,"") | R35: =R34 -> 0 | S35: =COUNTIFS('C+8 Data'!$H:$H,R$1,'C+8 Data'!$O:$O,$B35) -> 0 | T35: =IF(R35 <> 0,S35/R35,"") | U35: =U34 -> 0 | V35: =COUNTIFS('C+8 Data'!$H:$H,U$1,'C+8 Data'!$O:$O,$B35) -> 0 | W35: =IF(U35 <> 0,V35/U35,"") | X35: =X34 -> 0 | Y35: =COUNTIFS('C+8 Data'!$H:$H,X$1,'C+8 Data'!$O:$O,$B35) -> 0 | Z35: =IF(X35 <> 0,Y35/X35,"") | AA35: =AA34 -> 0 | AB35: =COUNTIFS('C+8 Data'!$H:$H,AA$1,'C+8 Data'!$O:$O,$B35) -> 0 | AC35: =IF(AA35 <> 0,AB35/AA35,"") | AD35: =AD34 -> 0 | AE35: =COUNTIFS('C+8 Data'!$H:$H,AD$1,'C+8 Data'!$O:$O,$B35) -> 0 | AF35: =IF(AD35 <> 0,AE35/AD35,"") | AG35: =AG34 -> 0 | AH35: =COUNTIFS('C+8 Data'!$H:$H,AG$1,'C+8 Data'!$O:$O,$B35) -> 0 | AI35: =IF(AG35 <> 0,AH35/AG35,"") | AJ35: =AJ34 -> 0 | AK35: =COUNTIFS('C+8 Data'!$H:$H,AJ$1,'C+8 Data'!$O:$O,$B35) -> 0 | AL35: =IF(AJ35 <> 0,AK35/AJ35,"") | AM35: =AM34 -> 0 | AN35: =COUNTIFS('C+8 Data'!$H:$H,AM$1,'C+8 Data'!$O:$O,$B35) -> 0 | AO35: =IF(AM35 <> 0,AN35/AM35,"")
A36: 7 | B36: During your consultation, have you received clear information about
A37: 7.1 | B37: Your diagnosis
B38: Yes | C38: =COUNTIF('C+8 Data'!$P:$P,"<>" & "")-1 -> 1 | D38: =G38+J38+M38+P38+S38+V38+Y38+AB38+AE38+AH38+AK38+AN38 -> 1 | E38: =IF(C38 <> 0,D38/C38,"") -> 1 | F38: =COUNTIFS('C+8 Data'!$AB:$AB,F$1,'C+8 Data'!$P:$P,"<>" & "") -> 0 | G38: =COUNTIFS('C+8 Data'!$AB:$AB,F$1,'C+8 Data'!$P:$P,$B38) -> 0 | H38: =IF(F38 <> 0,G38/F38,"") | I38: =COUNTIFS('C+8 Data'!$AB:$AB,I$1,'C+8 Data'!$P:$P,"<>" & "") -> 1 | J38: =COUNTIFS('C+8 Data'!$AB:$AB,I$1,'C+8 Data'!$P:$P,$B38) -> 1 | K38: =IF(I38 <> 0,J38/I38,"") -> 1 | L38: =COUNTIFS('C+8 Data'!$AB:$AB,L$1,'C+8 Data'!$P:$P,"<>" & "") -> 0 | M38: =COUNTIFS('C+8 Data'!$AB:$AB,L$1,'C+8 Data'!$P:$P,$B38) -> 0 | N38: =IF(L38 <> 0,M38/L38,"") | O38: =COUNTIFS('C+8 Data'!$AB:$AB,O$1,'C+8 Data'!$P:$P,"<>" & "") -> 0 | P38: =COUNTIFS('C+8 Data'!$AB:$AB,O$1,'C+8 Data'!$P:$P,$B38) -> 0 | Q38: =IF(O38 <> 0,P38/O38,"") | R38: =COUNTIFS('C+8 Data'!$AB:$AB,R$1,'C+8 Data'!$P:$P,"<>" & "") -> 0 | S38: =COUNTIFS('C+8 Data'!$AB:$AB,R$1,'C+8 Data'!$P:$P,$B38) -> 0 | T38: =IF(R38 <> 0,S38/R38,"") | U38: =COUNTIFS('C+8 Data'!$AB:$AB,U$1,'C+8 Data'!$P:$P,"<>" & "") -> 0 | V38: =COUNTIFS('C+8 Data'!$AB:$AB,U$1,'C+8 Data'!$P:$P,$B38) -> 0 | W38: =IF(U38 <> 0,V38/U38,"") | X38: =COUNTIFS('C+8 Data'!$AB:$AB,X$1,'C+8 Data'!$P:$P,"<>" & "") -> 0 | Y38: =COUNTIFS('C+8 Data'!$AB:$AB,X$1,'C+8 Data'!$P:$P,$B38) -> 0 | Z38: =IF(X38 <> 0,Y38/X38,"") | AA38: =COUNTIFS('C+8 Data'!$AB:$AB,AA$1,'C+8 Data'!$P:$P,"<>" & "") -> 0 | AB38: =COUNTIFS('C+8 Data'!$AB:$AB,AA$1,'C+8 Data'!$P:$P,$B38) -> 0 | AC38: =IF(AA38 <> 0,AB38/AA38,"") | AD38: =COUNTIFS('C+8 Data'!$AB:$AB,AD$1,'C+8 Data'!$P:$P,"<>" & "") -> 0 | AE38: =COUNTIFS('C+8 Data'!$AB:$AB,AD$1,'C+8 Data'!$P:$P,$B38) -> 0 | AF38: =IF(AD38 <> 0,AE38/AD38,"") | AG38: =COUNTIFS('C+8 Data'!$AB:$AB,AG$1,'C+8 Data'!$P:$P,"<>" & "") -> 0 | AH38: =COUNTIFS('C+8 Data'!$AB:$AB,AG$1,'C+8 Data'!$P:$P,$B38) -> 0 | AI38: =IF(AG38 <> 0,AH38/AG38,"") | AJ38: =COUNTIFS('C+8 Data'!$AB:$AB,AJ$1,'C+8 Data'!$P:$P,"<>" & "") -> 0 | AK38: =COUNTIFS('C+8 Data'!$AB:$AB,AJ$1,'C+8 Data'!$P:$P,$B38) -> 0 | AL38: =IF(AJ38 <> 0,AK38/AJ38,"") | AM38: =COUNTIFS('C+8 Data'!$AB:$AB,AM$1,'C+8 Data'!$P:$P,"<>" & "") -> 0 | AN38: =COUNTIFS('C+8 Data'!$AB:$AB,AM$1,'C+8 Data'!$P:$P,$B38) -> 0 | AO38: =IF(AM38 <> 0,AN38/AM38,"")
