Workbook

Sheet Data-SO
A1: Date | B1: Type | C1: AturaID | D1: Document Number | E1: Patient Name ----------- | F1: Status | G1: Amount | H1: Treatment Type | I1: Sales Type | J1: Memo | K1: Patient Name | L1: Primary Physician | M1: TSD | N1: TED | O1: AyurVAID Centre | P1: Covered by Insurance? | Q1: Payable By Insurance | R1: Cashless / Reimbursement | S1: Corporate / Retail | T1: Insurance Company | U1: Insurance Policy # | V1: TPA | W1: TPA Card # | X1: TPA / CGHS Claim ID | Y1: Created By | Z1: Days | AA1: Date of Birth | AB1: PP1-Primary Physician | AC1: Created From | AD1: OPT/IPT # | AE1: Primary Diagnosis (Allopathy) | AF1: Primary Diagnosis (Ayurveda) | AG1: TSD | AH1: TED | AI1: TSD Month | AJ1: TED Month | AK1: Missed TSD | AL1: Missed TED
A2: 45748 | B2: Sales Order | D2: KFHS/AVEIHCL/000227/SaleOrd | F2: Pending Fulfillment | G2: 11210 | H2: OPT | I2: Treatment | L2: Dr. Bindu M (IHCL) | M2: 45748 | N2: 45748 | O2: AVHE-IHCL | P2: No | Y2: AVH IT | Z2: 1 | AB2: Dr. Bindu M (IHCL) | AG2: =M2 -> 45748 | AH2: =N2 -> 45748 | AI2: =VLOOKUP(MONTH(AG2),Month!$A:$B,2,FALSE) & "-" & MID(YEAR(AG2),3,2) -> Apr-25 | AJ2: =VLOOKUP(MONTH(AH2),Month!$A:$B,2,FALSE) & "-" & MID(YEAR(AH2),3,2) -> Apr-25 | AK2: =IFERROR(VLOOKUP(D2, 'Data-TSD+1'!Z:Z, 1, FALSE), "NOT COVERED") -> NOT COVERED | AL2: =IFERROR(VLOOKUP(D2, 'Data-TED-1'!AF:AF, 1, FALSE), "NOT COVERED") -> NOT COVERED

Sheet Data-TSD+1
A1: AyurVAID Centre | B1: Treatment Start Date | C1: Patient ID | D1: Name of Physician | E1: Satisfactory Clarity of Treatment Objves | F1: Timely & Satisfactory information | G1: Daily routine | H1: Do's and Don'ts | I1: Quality of Medical Care | J1: OVERALL QUALITY OF SERVICES (Reception) | K1: OVERALL QUALITY OF SERVICES (PBE) | L1: Timely & Satisfactory Information (TED) | M1: Attention by your PP | N1: Attention by the RMO | O1: Attention by the CM | P1: Quality of housekeeping | Q1: Timeliness of service | R1: Overall services at AyurVAID hospitals | S1: OPT /IPT # | T1: Date and Time of Feedback (TED) | U1: TSD + 1 Date | V1: Commit to be Conscious(Discharge) | W1: Comment | X1: Probability that you will RECOMMEND ? | Y1: Date Created | Z1: Document Number | AA1: Feedback Status | AB1: Treatment Type | AC1: Month
A2: HRBR | B2: 45766 | C2: 802074397 | D2: Dr. Nagendra Kumar (HRBR) | E2: Very satisfactory (100%) | F2: Very satisfactory (100%) | G2: Very satisfactory (100%) | H2: Very satisfactory (100%) | M2: Very satisfactory (100%) | N2: Very satisfactory (100%) | O2: Very satisfactory (100%) | P2: Very satisfactory (100%) | Q2: Very satisfactory (100%) | R2: Very satisfactory (100%) | S2: OPT#53/2025 | T2: 45766.725 | U2: 45766 | V2: No | W2: Happy with the treatment and the services | X2: 1 | Y2: 45766.724 | Z2: KFHS/AVHRBR/001759/SaleOrd | AA2: Done | AB2: =_xlfn.IFNA(VLOOKUP(Z2, 'Data-SO'!D:H, 5, FALSE),"") | AC2: =VLOOKUP(MONTH(B2),Month!$A:$B,2,FALSE) & "-" & MID(YEAR(B2),3,2) -> Apr-25

Sheet Data-TED-1
A1: AyurVAID Centre | B1: Patient ID | C1: TED - 1 | D1: OPT IPT # | E1: Name of the Physician | F1: Timely and Satisfactory Information | G1: Quality of Medical Care by your PP | H1: Quality of MC by CG | I1: Quality of Medical Care by our RMO | J1: Quality of Care by CM | K1: Overall Quality(Reception) | L1: Overall Quality(Pharmacy and Billing) | M1: Ease of lodging complaints | N1: Resolution of complaints lodged | O1: AyurVAID's Medical Care | P1: Vomiting | Q1: Acidity | R1: Cought/Cold | S1: Rash | T1: Loose Motion | U1: Pain | V1: Fall | W1: Other | X1: Overall Satisfaction with AVH | Y1: Probability that you will Recommend | Z1: Details of Other | AA1: Your Suggestion for Improvement | AB1: Date Created | AC1: Feedback Date | AD1: Feedback Status | AE1: TSD | AF1: Document Number | AG1: Treatment Type | AH1: Month
A2: HRBR | B2: 801058408 | C2: 46019 | D2: IPT#183/2025 | E2: Dr. Sushma M (HRBR) | G2: Satisfactory (80%) | H2: Satisfactory (80%) | I2: Satisfactory (80%) | J2: Average (60%) | K2: Satisfactory (80%) | L2: Satisfactory (80%) | M2: Unsatisfactory (40%) | N2: Unsatisfactory (40%) | O2: Satisfactory (80%) | P2: No | Q2: No | R2: No | S2: No | T2: No | U2: No | V2: No | W2: No | X2: Average (60%) | Y2: 0.6 | AA2: Happy with the clinical part but shared the following : The patient was highly disappointed as no action was taken on the above feedback. He faced several difficulties during his stay, including the absence of any communication facility for assistance. On one occasion late at night, he had to step out of his room to get a towel due to the lack of an intercom. He also requested that he not be contacted again for feedback. | AB2: 46011.496 | AC2: 46011 | AD2: Done | AE2: 46011 | AF2: KFHS/AVHRBR/003299/SaleOrd | AG2: =_xlfn.IFNA(VLOOKUP(AF2, 'Data-SO'!D:H, 5, FALSE),"") | AH2: =VLOOKUP(MONTH(C2),Month!$A:$B,2,FALSE) & "-" & MID(YEAR(C2),3,2) -> Dec-25

Sheet CSAT-AVH
A1: CSAT- OPT & IP | F1: 45748 | I1: =EDATE(F1,1) -> 45778 | L1: =EDATE(I1,1) -> 45809 | O1: =EDATE(L1,1) -> 45839 | R1: =EDATE(O1,1) -> 45870 | U1: =EDATE(R1,1) -> 45901 | X1: =EDATE(U1,1) -> 45931 | AA1: =EDATE(X1,1) -> 45962 | AD1: =EDATE(AA1,1) -> 45992 | AG1: =EDATE(AD1,1) -> 46023 | AJ1: =EDATE(AG1,1) -> 46054 | AM1: =EDATE(AJ1,1) -> 46082
A2: 1 | B2: TSD+1: Satisfaction with clarity of treatment objectives | C2: Total | D2: Actuals | E2: % Sat
B3: a) Excellent - 100% | C3: =COUNTIF('Data-TSD+1'!$E:$E,"<>" & "")-1 -> 1 | D3: =G3+J3+M3+P3+S3+V3+Y3+AB3+AE3+AH3+AK3+AN3 -> 1 | E3: =IF(C3 <> 0,D3/C3,"") -> 1 | F3: =COUNTIFS('Data-TSD+1'!$AC:$AC,F$1,'Data-TSD+1'!$E:$E,"<>" & "") -> 1 | G3: =COUNTIFS('Data-TSD+1'!$AC:$AC,F$1,'Data-TSD+1'!$E:$E,"Very satisfactory (100%)") -> 1 | H3: =IF(F3 <> 0,G3/F3,"") -> 1 | I3: =COUNTIFS('Data-TSD+1'!$AC:$AC,I$1,'Data-TSD+1'!$E:$E,"<>" & "") -> 0 | J3: =COUNTIFS('Data-TSD+1'!$AC:$AC,I$1,'Data-TSD+1'!$E:$E,"Very satisfactory (100%)") -> 0 | K3: =IF(I3 <> 0,J3/I3,"") | L3: =COUNTIFS('Data-TSD+1'!$AC:$AC,L$1,'Data-TSD+1'!$E:$E,"<>" & "") -> 0 | M3: =COUNTIFS('Data-TSD+1'!$AC:$AC,L$1,'Data-TSD+1'!$E:$E,"Very satisfactory (100%)") -> 0 | N3: =IF(L3 <> 0,M3/L3,"") | O3: =COUNTIFS('Data-TSD+1'!$AC:$AC,O$1,'Data-TSD+1'!$E:$E,"<>" & "") -> 0 | P3: =COUNTIFS('Data-TSD+1'!$AC:$AC,O$1,'Data-TSD+1'!$E:$E,"Very satisfactory (100%)") -> 0 | Q3: =IF(O3 <> 0,P3/O3,"") | R3: =COUNTIFS('Data-TSD+1'!$AC:$AC,R$1,'Data-TSD+1'!$E:$E,"<>" & "") -> 0 | S3: =COUNTIFS('Data-TSD+1'!$AC:$AC,R$1,'Data-TSD+1'!$E:$E,"Very satisfactory (100%)") -> 0 | T3: =IF(R3 <> 0,S3/R3,"") | U3: =COUNTIFS('Data-TSD+1'!$AC:$AC,U$1,'Data-TSD+1'!$E:$E,"<>" & "") -> 0 | V3: =COUNTIFS('Data-TSD+1'!$AC:$AC,U$1,'Data-TSD+1'!$E:$E,"Very satisfactory (100%)") -> 0 | W3: =IF(U3 <> 0,V3/U3,"") | X3: =COUNTIFS('Data-TSD+1'!$AC:$AC,X$1,'Data-TSD+1'!$E:$E,"<>" & "") -> 0 | Y3: =COUNTIFS('Data-TSD+1'!$AC:$AC,X$1,'Data-TSD+1'!$E:$E,"Very satisfactory (100%)") -> 0 | Z3: =IF(X3 <> 0,Y3/X3,"") | AA3: =COUNTIFS('Data-TSD+1'!$AC:$AC,AA$1,'Data-TSD+1'!$E:$E,"<>" & "") -> 0 | AB3: =COUNTIFS('Data-TSD+1'!$AC:$AC,AA$1,'Data-TSD+1'!$E:$E,"Very satisfactory (100%)") -> 0 | AC3: =IF(AA3 <> 0,AB3/AA3,"") | AD3: =COUNTIFS('Data-TSD+1'!$AC:$AC,AD$1,'Data-TSD+1'!$E:$E,"<>" & "") -> 0 | AE3: =COUNTIFS('Data-TSD+1'!$AC:$AC,AD$1,'Data-TSD+1'!$E:$E,"Very satisfactory (100%)") -> 0 | AF3: =IF(AD3 <> 0,AE3/AD3,"") | AG3: =COUNTIFS('Data-TSD+1'!$AC:$AC,AG$1,'Data-TSD+1'!$E:$E,"<>" & "") -> 0 | AH3: =COUNTIFS('Data-TSD+1'!$AC:$AC,AG$1,'Data-TSD+1'!$E:$E,"Very satisfactory (100%)") -> 0 | AI3: =IF(AG3 <> 0,AH3/AG3,"") | AJ3: =COUNTIFS('Data-TSD+1'!$AC:$AC,AJ$1,'Data-TSD+1'!$E:$E,"<>" & "") -> 0 | AK3: =COUNTIFS('Data-TSD+1'!$AC:$AC,AJ$1,'Data-TSD+1'!$E:$E,"Very satisfactory (100%)") -> 0 | AL3: =IF(AJ3 <> 0,AK3/AJ3,"") | AM3: =COUNTIFS('Data-TSD+1'!$AC:$AC,AM$1,'Data-TSD+1'!$E:$E,"<>" & "") -> 0 | AN3: =COUNTIFS('Data-TSD+1'!$AC:$AC,AM$1,'Data-TSD+1'!$E:$E,"Very satisfactory (100%)") -> 0 | AO3: =IF(AM3 <> 0,AN3/AM3,"")
B4: b) V.Good - 80% | C4: =C3 -> 1 | D4: =G4+J4+M4+P4+S4+V4+Y4+AB4+AE4+AH4+AK4+AN4 -> 0 | E4: =IF(C4 <> 0,D4/C4,"") -> 0 | F4: =F3 -> 1 | G4: =COUNTIFS('Data-TSD+1'!$AC:$AC,F$1,'Data-TSD+1'!$E:$E,"Satisfactory (80%)") -> 0 | H4: =IF(F4 <> 0,G4/F4,"") -> 0 | I4: =I3 -> 0 | J4: =COUNTIFS('Data-TSD+1'!$AC:$AC,I$1,'Data-TSD+1'!$E:$E,"Satisfactory (80%)") -> 0 | K4: =IF(I4 <> 0,J4/I4,"") | L4: =L3 -> 0 | M4: =COUNTIFS('Data-TSD+1'!$AC:$AC,L$1,'Data-TSD+1'!$E:$E,"Satisfactory (80%)") -> 0 | N4: =IF(L4 <> 0,M4/L4,"") | O4: =O3 -> 0 | P4: =COUNTIFS('Data-TSD+1'!$AC:$AC,O$1,'Data-TSD+1'!$E:$E,"Satisfactory (80%)") -> 0 | Q4: =IF(O4 <> 0,P4/O4,"") | R4: =R3 -> 0 | S4: =COUNTIFS('Data-TSD+1'!$AC:$AC,R$1,'Data-TSD+1'!$E:$E,"Satisfactory (80%)") -> 0 | T4: =IF(R4 <> 0,S4/R4,"") | U4: =U3 -> 0 | V4: =COUNTIFS('Data-TSD+1'!$AC:$AC,U$1,'Data-TSD+1'!$E:$E,"Satisfactory (80%)") -> 0 | W4: =IF(U4 <> 0,V4/U4,"") | X4: =X3 -> 0 | Y4: =COUNTIFS('Data-TSD+1'!$AC:$AC,X$1,'Data-TSD+1'!$E:$E,"Satisfactory (80%)") -> 0 | Z4: =IF(X4 <> 0,Y4/X4,"") | AA4: =AA3 -> 0 | AB4: =COUNTIFS('Data-TSD+1'!$AC:$AC,AA$1,'Data-TSD+1'!$E:$E,"Satisfactory (80%)") -> 0 | AC4: =IF(AA4 <> 0,AB4/AA4,"") | AD4: =AD3 -> 0 | AE4: =COUNTIFS('Data-TSD+1'!$AC:$AC,AD$1,'Data-TSD+1'!$E:$E,"Satisfactory (80%)") -> 0 | AF4: =IF(AD4 <> 0,AE4/AD4,"") | AG4: =AG3 -> 0 | AH4: =COUNTIFS('Data-TSD+1'!$AC:$AC,AG$1,'Data-TSD+1'!$E:$E,"Satisfactory (80%)") -> 0 | AI4: =IF(AG4 <> 0,AH4/AG4,"") | AJ4: =AJ3 -> 0 | AK4: =COUNTIFS('Data-TSD+1'!$AC:$AC,AJ$1,'Data-TSD+1'!$E:$E,"Satisfactory (80%)") -> 0 | AL4: =IF(AJ4 <> 0,AK4/AJ4,"") | AM4: =AM3 -> 0 | AN4: =COUNTIFS('Data-TSD+1'!$AC:$AC,AM$1,'Data-TSD+1'!$E:$E,"Satisfactory (80%)") -> 0 | AO4: =IF(AM4 <> 0,AN4/AM4,"")
B5: C) Good - 60% | C5: =C4 -> 1 | D5: =G5+J5+M5+P5+S5+V5+Y5+AB5+AE5+AH5+AK5+AN5 -> 0 | E5: =IF(C5 <> 0,D5/C5,"") -> 0 | F5: =F4 -> 1 | G5: =COUNTIFS('Data-TSD+1'!$AC:$AC,F$1,'Data-TSD+1'!$E:$E,"Average (60%)") -> 0 | H5: =IF(F5 <> 0,G5/F5,"") -> 0 | I5: =I4 -> 0 | J5: =COUNTIFS('Data-TSD+1'!$AC:$AC,I$1,'Data-TSD+1'!$E:$E,"Average (60%)") -> 0 | K5: =IF(I5 <> 0,J5/I5,"") | L5: =L4 -> 0 | M5: =COUNTIFS('Data-TSD+1'!$AC:$AC,L$1,'Data-TSD+1'!$E:$E,"Average (60%)") -> 0 | N5: =IF(L5 <> 0,M5/L5,"") | O5: =O4 -> 0 | P5: =COUNTIFS('Data-TSD+1'!$AC:$AC,O$1,'Data-TSD+1'!$E:$E,"Average (60%)") -> 0 | Q5: =IF(O5 <> 0,P5/O5,"") | R5: =R4 -> 0 | S5: =COUNTIFS('Data-TSD+1'!$AC:$AC,R$1,'Data-TSD+1'!$E:$E,"Average (60%)") -> 0 | T5: =IF(R5 <> 0,S5/R5,"") | U5: =U4 -> 0 | V5: =COUNTIFS('Data-TSD+1'!$AC:$AC,U$1,'Data-TSD+1'!$E:$E,"Average (60%)") -> 0 | W5: =IF(U5 <> 0,V5/U5,"") | X5: =X4 -> 0 | Y5: =COUNTIFS('Data-TSD+1'!$AC:$AC,X$1,'Data-TSD+1'!$E:$E,"Average (60%)") -> 0 | Z5: =IF(X5 <> 0,Y5/X5,"") | AA5: =AA4 -> 0 | AB5: =COUNTIFS('Data-TSD+1'!$AC:$AC,AA$1,'Data-TSD+1'!$E:$E,"Average (60%)") -> 0 | AC5: =IF(AA5 <> 0,AB5/AA5,"") | AD5: =AD4 -> 0 | AE5: =COUNTIFS('Data-TSD+1'!$AC:$AC,AD$1,'Data-TSD+1'!$E:$E,"Average (60%)") -> 0 | AF5: =IF(AD5 <> 0,AE5/AD5,"") | AG5: =AG4 -> 0 | AH5: =COUNTIFS('Data-TSD+1'!$AC:$AC,AG$1,'Data-TSD+1'!$E:$E,"Average (60%)") -> 0 | AI5: =IF(AG5 <> 0,AH5/AG5,"") | AJ5: =AJ4 -> 0 | AK5: =COUNTIFS('Data-TSD+1'!$AC:$AC,AJ$1,'Data-TSD+1'!$E:$E,"Average (60%)") -> 0 | AL5: =IF(AJ5 <> 0,AK5/AJ5,"") | AM5: =AM4 -> 0 | AN5: =COUNTIFS('Data-TSD+1'!$AC:$AC,AM$1,'Data-TSD+1'!$E:$E,"Average (60%)") -> 0 | AO5: =IF(AM5 <> 0,AN5/AM5,"")
B6: d) Fair - 40% | C6: =C5 -> 1 | D6: =G6+J6+M6+P6+S6+V6+Y6+AB6+AE6+AH6+AK6+AN6 -> 0 | E6: =IF(C6 <> 0,D6/C6,"") -> 0 | F6: =F5 -> 1 | G6: =COUNTIFS('Data-TSD+1'!$AC:$AC,F$1,'Data-TSD+1'!$E:$E,"Unsatisfactory (40%)") -> 0 | H6: =IF(F6 <> 0,G6/F6,"") -> 0 | I6: =I5 -> 0 | J6: =COUNTIFS('Data-TSD+1'!$AC:$AC,I$1,'Data-TSD+1'!$E:$E,"Unsatisfactory (40%)") -> 0 | K6: =IF(I6 <> 0,J6/I6,"") | L6: =L5 -> 0 | M6: =COUNTIFS('Data-TSD+1'!$AC:$AC,L$1,'Data-TSD+1'!$E:$E,"Unsatisfactory (40%)") -> 0 | N6: =IF(L6 <> 0,M6/L6,"") | O6: =O5 -> 0 | P6: =COUNTIFS('Data-TSD+1'!$AC:$AC,O$1,'Data-TSD+1'!$E:$E,"Unsatisfactory (40%)") -> 0 | Q6: =IF(O6 <> 0,P6/O6,"") | R6: =R5 -> 0 | S6: =COUNTIFS('Data-TSD+1'!$AC:$AC,R$1,'Data-TSD+1'!$E:$E,"Unsatisfactory (40%)") -> 0 | T6: =IF(R6 <> 0,S6/R6,"") | U6: =U5 -> 0 | V6: =COUNTIFS('Data-TSD+1'!$AC:$AC,U$1,'Data-TSD+1'!$E:$E,"Unsatisfactory (40%)") -> 0 | W6: =IF(U6 <> 0,V6/U6,"") | X6: =X5 -> 0 | Y6: =COUNTIFS('Data-TSD+1'!$AC:$AC,X$1,'Data-TSD+1'!$E:$E,"Unsatisfactory (40%)") -> 0 | Z6: =IF(X6 <> 0,Y6/X6,"") | AA6: =AA5 -> 0 | AB6: =COUNTIFS('Data-TSD+1'!$AC:$AC,AA$1,'Data-TSD+1'!$E:$E,"Unsatisfactory (40%)") -> 0 | AC6: =IF(AA6 <> 0,AB6/AA6,"") | AD6: =AD5 -> 0 | AE6: =COUNTIFS('Data-TSD+1'!$AC:$AC,AD$1,'Data-TSD+1'!$E:$E,"Unsatisfactory (40%)") -> 0 | AF6: =IF(AD6 <> 0,AE6/AD6,"") | AG6: =AG5 -> 0 | AH6: =COUNTIFS('Data-TSD+1'!$AC:$AC,AG$1,'Data-TSD+1'!$E:$E,"Unsatisfactory (40%)") -> 0 | AI6: =IF(AG6 <> 0,AH6/AG6,"") | AJ6: =AJ5 -> 0 | AK6: =COUNTIFS('Data-TSD+1'!$AC:$AC,AJ$1,'Data-TSD+1'!$E:$E,"Unsatisfactory (40%)") -> 0 | AL6: =IF(AJ6 <> 0,AK6/AJ6,"") | AM6: =AM5 -> 0 | AN6: =COUNTIFS('Data-TSD+1'!$AC:$AC,AM$1,'Data-TSD+1'!$E:$E,"Unsatisfactory (40%)") -> 0 | AO6: =IF(AM6 <> 0,AN6/AM6,"")
B7: e) Poor - 20% | C7: =C6 -> 1 | D7: =G7+J7+M7+P7+S7+V7+Y7+AB7+AE7+AH7+AK7+AN7 -> 0 | E7: =IF(C7 <> 0,D7/C7,"") -> 0 | F7: =F6 -> 1 | G7: =COUNTIFS('Data-TSD+1'!$AC:$AC,F$1,'Data-TSD+1'!$E:$E,"Very unsatisfactory (20%)") -> 0 | H7: =IF(F7 <> 0,G7/F7,"") -> 0 | I7: =I6 -> 0 | J7: =COUNTIFS('Data-TSD+1'!$AC:$AC,I$1,'Data-TSD+1'!$E:$E,"Very unsatisfactory (20%)") -> 0 | K7: =IF(I7 <> 0,J7/I7,"") | L7: =L6 -> 0 | M7: =COUNTIFS('Data-TSD+1'!$AC:$AC,L$1,'Data-TSD+1'!$E:$E,"Very unsatisfactory (20%)") -> 0 | N7: =IF(L7 <> 0,M7/L7,"") | O7: =O6 -> 0 | P7: =COUNTIFS('Data-TSD+1'!$AC:$AC,O$1,'Data-TSD+1'!$E:$E,"Very unsatisfactory (20%)") -> 0 | Q7: =IF(O7 <> 0,P7/O7,"") | R7: =R6 -> 0 | S7: =COUNTIFS('Data-TSD+1'!$AC:$AC,R$1,'Data-TSD+1'!$E:$E,"Very unsatisfactory (20%)") -> 0 | T7: =IF(R7 <> 0,S7/R7,"") | U7: =U6 -> 0 | V7: =COUNTIFS('Data-TSD+1'!$AC:$AC,U$1,'Data-TSD+1'!$E:$E,"Very unsatisfactory (20%)") -> 0 | W7: =IF(U7 <> 0,V7/U7,"") | X7: =X6 -> 0 | Y7: =COUNTIFS('Data-TSD+1'!$AC:$AC,X$1,'Data-TSD+1'!$E:$E,"Very unsatisfactory (20%)") -> 0 | Z7: =IF(X7 <> 0,Y7/X7,"") | AA7: =AA6 -> 0 | AB7: =COUNTIFS('Data-TSD+1'!$AC:$AC,AA$1,'Data-TSD+1'!$E:$E,"Very unsatisfactory (20%)") -> 0 | AC7: =IF(AA7 <> 0,AB7/AA7,"") | AD7: =AD6 -> 0 | AE7: =COUNTIFS('Data-TSD+1'!$AC:$AC,AD$1,'Data-TSD+1'!$E:$E,"Very unsatisfactory (20%)") -> 0 | AF7: =IF(AD7 <> 0,AE7/AD7,"") | AG7: =AG6 -> 0 | AH7: =COUNTIFS('Data-TSD+1'!$AC:$AC,AG$1,'Data-TSD+1'!$E:$E,"Very unsatisfactory (20%)") -> 0 | AI7: =IF(AG7 <> 0,AH7/AG7,"") | AJ7: =AJ6 -> 0 | AK7: =COUNTIFS('Data-TSD+1'!$AC:$AC,AJ$1,'Data-TSD+1'!$E:$E,"Very unsatisfactory (20%)") -> 0 | AL7: =IF(AJ7 <> 0,AK7/AJ7,"") | AM7: =AM6 -> 0 | AN7: =COUNTIFS('Data-TSD+1'!$AC:$AC,AM$1,'Data-TSD+1'!$E:$E,"Very unsatisfactory (20%)") -> 0 | AO7: =IF(AM7 <> 0,AN7/AM7,"")
A8: 2 | B8: TSD+1: Satisfaction with information about your Treatment schedule (Day & Time)
B9: a) Excellent - 100% | C9: =COUNTIF('Data-TSD+1'!$F:$F,"<>" & "")-1 -> 1 | D9: =G9+J9+M9+P9+S9+V9+Y9+AB9+AE9+AH9+AK9+AN9 -> 1 | E9: =IF(C9 <> 0,D9/C9,"") -> 1 | F9: =COUNTIFS('Data-TSD+1'!$AC:$AC,F$1,'Data-TSD+1'!$F:$F,"<>" & "") -> 1 | G9: =COUNTIFS('Data-TSD+1'!$AC:$AC,F$1,'Data-TSD+1'!$F:$F,"Very satisfactory (100%)") -> 1 | H9: =IF(F9 <> 0,G9/F9,"") -> 1 | I9: =COUNTIFS('Data-TSD+1'!$AC:$AC,I$1,'Data-TSD+1'!$F:$F,"<>" & "") -> 0 | J9: =COUNTIFS('Data-TSD+1'!$AC:$AC,I$1,'Data-TSD+1'!$F:$F,"Very satisfactory (100%)") -> 0 | K9: =IF(I9 <> 0,J9/I9,"") | L9: =COUNTIFS('Data-TSD+1'!$AC:$AC,L$1,'Data-TSD+1'!$F:$F,"<>" & "") -> 0 | M9: =COUNTIFS('Data-TSD+1'!$AC:$AC,L$1,'Data-TSD+1'!$F:$F,"Very satisfactory (100%)") -> 0 | N9: =IF(L9 <> 0,M9/L9,"") | O9: =COUNTIFS('Data-TSD+1'!$AC:$AC,O$1,'Data-TSD+1'!$F:$F,"<>" & "") -> 0 | P9: =COUNTIFS('Data-TSD+1'!$AC:$AC,O$1,'Data-TSD+1'!$F:$F,"Very satisfactory (100%)") -> 0 | Q9: =IF(O9 <> 0,P9/O9,"") | R9: =COUNTIFS('Data-TSD+1'!$AC:$AC,R$1,'Data-TSD+1'!$F:$F,"<>" & "") -> 0 | S9: =COUNTIFS('Data-TSD+1'!$AC:$AC,R$1,'Data-TSD+1'!$F:$F,"Very satisfactory (100%)") -> 0 | T9: =IF(R9 <> 0,S9/R9,"") | U9: =COUNTIFS('Data-TSD+1'!$AC:$AC,U$1,'Data-TSD+1'!$F:$F,"<>" & "") -> 0 | V9: =COUNTIFS('Data-TSD+1'!$AC:$AC,U$1,'Data-TSD+1'!$F:$F,"Very satisfactory (100%)") -> 0 | W9: =IF(U9 <> 0,V9/U9,"") | X9: =COUNTIFS('Data-TSD+1'!$AC:$AC,X$1,'Data-TSD+1'!$F:$F,"<>" & "") -> 0 | Y9: =COUNTIFS('Data-TSD+1'!$AC:$AC,X$1,'Data-TSD+1'!$F:$F,"Very satisfactory (100%)") -> 0 | Z9: =IF(X9 <> 0,Y9/X9,"") | AA9: =COUNTIFS('Data-TSD+1'!$AC:$AC,AA$1,'Data-TSD+1'!$F:$F,"<>" & "") -> 0 | AB9: =COUNTIFS('Data-TSD+1'!$AC:$AC,AA$1,'Data-TSD+1'!$F:$F,"Very satisfactory (100%)") -> 0 | AC9: =IF(AA9 <> 0,AB9/AA9,"") | AD9: =COUNTIFS('Data-TSD+1'!$AC:$AC,AD$1,'Data-TSD+1'!$F:$F,"<>" & "") -> 0 | AE9: =COUNTIFS('Data-TSD+1'!$AC:$AC,AD$1,'Data-TSD+1'!$F:$F,"Very satisfactory (100%)") -> 0 | AF9: =IF(AD9 <> 0,AE9/AD9,"") | AG9: =COUNTIFS('Data-TSD+1'!$AC:$AC,AG$1,'Data-TSD+1'!$F:$F,"<>" & "") -> 0 | AH9: =COUNTIFS('Data-TSD+1'!$AC:$AC,AG$1,'Data-TSD+1'!$F:$F,"Very satisfactory (100%)") -> 0 | AI9: =IF(AG9 <> 0,AH9/AG9,"") | AJ9: =COUNTIFS('Data-TSD+1'!$AC:$AC,AJ$1,'Data-TSD+1'!$F:$F,"<>" & "") -> 0 | AK9: =COUNTIFS('Data-TSD+1'!$AC:$AC,AJ$1,'Data-TSD+1'!$F:$F,"Very satisfactory (100%)") -> 0 | AL9: =IF(AJ9 <> 0,AK9/AJ9,"") | AM9: =COUNTIFS('Data-TSD+1'!$AC:$AC,AM$1,'Data-TSD+1'!$F:$F,"<>" & "") -> 0 | AN9: =COUNTIFS('Data-TSD+1'!$AC:$AC,AM$1,'Data-TSD+1'!$F:$F,"Very satisfactory (100%)") -> 0 | AO9: =IF(AM9 <> 0,AN9/AM9,"")
B10: b) V.Good - 80% | C10: =C9 -> 1 | D10: =G10+J10+M10+P10+S10+V10+Y10+AB10+AE10+AH10+AK10+AN10 -> 0 | E10: =IF(C10 <> 0,D10/C10,"") -> 0 | F10: =F9 -> 1 | G10: =COUNTIFS('Data-TSD+1'!$AC:$AC,F$1,'Data-TSD+1'!$F:$F,"Satisfactory (80%)") -> 0 | H10: =IF(F10 <> 0,G10/F10,"") -> 0 | I10: =I9 -> 0 | J10: =COUNTIFS('Data-TSD+1'!$AC:$AC,I$1,'Data-TSD+1'!$F:$F,"Satisfactory (80%)") -> 0 | K10: =IF(I10 <> 0,J10/I10,"") | L10: =L9 -> 0 | M10: =COUNTIFS('Data-TSD+1'!$AC:$AC,L$1,'Data-TSD+1'!$F:$F,"Satisfactory (80%)") -> 0 | N10: =IF(L10 <> 0,M10/L10,"") | O10: =O9 -> 0 | P10: =COUNTIFS('Data-TSD+1'!$AC:$AC,O$1,'Data-TSD+1'!$F:$F,"Satisfactory (80%)") -> 0 | Q10: =IF(O10 <> 0,P10/O10,"") | R10: =R9 -> 0 | S10: =COUNTIFS('Data-TSD+1'!$AC:$AC,R$1,'Data-TSD+1'!$F:$F,"Satisfactory (80%)") -> 0 | T10: =IF(R10 <> 0,S10/R10,"") | U10: =U9 -> 0 | V10: =COUNTIFS('Data-TSD+1'!$AC:$AC,U$1,'Data-TSD+1'!$F:$F,"Satisfactory (80%)") -> 0 | W10: =IF(U10 <> 0,V10/U10,"") | X10: =X9 -> 0 | Y10: =COUNTIFS('Data-TSD+1'!$AC:$AC,X$1,'Data-TSD+1'!$F:$F,"Satisfactory (80%)") -> 0 | Z10: =IF(X10 <> 0,Y10/X10,"") | AA10: =AA9 -> 0 | AB10: =COUNTIFS('Data-TSD+1'!$AC:$AC,AA$1,'Data-TSD+1'!$F:$F,"Satisfactory (80%)") -> 0 | AC10: =IF(AA10 <> 0,AB10/AA10,"") | AD10: =AD9 -> 0 | AE10: =COUNTIFS('Data-TSD+1'!$AC:$AC,AD$1,'Data-TSD+1'!$F:$F,"Satisfactory (80%)") -> 0 | AF10: =IF(AD10 <> 0,AE10/AD10,"") | AG10: =AG9 -> 0 | AH10: =COUNTIFS('Data-TSD+1'!$AC:$AC,AG$1,'Data-TSD+1'!$F:$F,"Satisfactory (80%)") -> 0 | AI10: =IF(AG10 <> 0,AH10/AG10,"") | AJ10: =AJ9 -> 0 | AK10: =COUNTIFS('Data-TSD+1'!$AC:$AC,AJ$1,'Data-TSD+1'!$F:$F,"Satisfactory (80%)") -> 0 | AL10: =IF(AJ10 <> 0,AK10/AJ10,"") | AM10: =AM9 -> 0 | AN10: =COUNTIFS('Data-TSD+1'!$AC:$AC,AM$1,'Data-TSD+1'!$F:$F,"Satisfactory (80%)") -> 0 | AO10: =IF(AM10 <> 0,AN10/AM10,"")
B11: C) Good - 60% | C11: =C10 -> 1 | D11: =G11+J11+M11+P11+S11+V11+Y11+AB11+AE11+AH11+AK11+AN11 -> 0 | E11: =IF(C11 <> 0,D11/C11,"") -> 0 | F11: =F10 -> 1 | G11: =COUNTIFS('Data-TSD+1'!$AC:$AC,F$1,'Data-TSD+1'!$F:$F,"Average (60%)") -> 0 | H11: =IF(F11 <> 0,G11/F11,"") -> 0 | I11: =I10 -> 0 | J11: =COUNTIFS('Data-TSD+1'!$AC:$AC,I$1,'Data-TSD+1'!$F:$F,"Average (60%)") -> 0 | K11: =IF(I11 <> 0,J11/I11,"") | L11: =L10 -> 0 | M11: =COUNTIFS('Data-TSD+1'!$AC:$AC,L$1,'Data-TSD+1'!$F:$F,"Average (60%)") -> 0 | N11: =IF(L11 <> 0,M11/L11,"") | O11: =O10 -> 0 | P11: =COUNTIFS('Data-TSD+1'!$AC:$AC,O$1,'Data-TSD+1'!$F:$F,"Average (60%)") -> 0 | Q11: =IF(O11 <> 0,P11/O11,"") | R11: =R10 -> 0 | S11: =COUNTIFS('Data-TSD+1'!$AC:$AC,R$1,'Data-TSD+1'!$F:$F,"Average (60%)") -> 0 | T11: =IF(R11 <> 0,S11/R11,"") | U11: =U10 -> 0 | V11: =COUNTIFS('Data-TSD+1'!$AC:$AC,U$1,'Data-TSD+1'!$F:$F,"Average (60%)") -> 0 | W11: =IF(U11 <> 0,V11/U11,"") | X11: =X10 -> 0 | Y11: =COUNTIFS('Data-TSD+1'!$AC:$AC,X$1,'Data-TSD+1'!$F:$F,"Average (60%)") -> 0 | Z11: =IF(X11 <> 0,Y11/X11,"") | AA11: =AA10 -> 0 | AB11: =COUNTIFS('Data-TSD+1'!$AC:$AC,AA$1,'Data-TSD+1'!$F:$F,"Average (60%)") -> 0 | AC11: =IF(AA11 <> 0,AB11/AA11,"") | AD11: =AD10 -> 0 | AE11: =COUNTIFS('Data-TSD+1'!$AC:$AC,AD$1,'Data-TSD+1'!$F:$F,"Average (60%)") -> 0 | AF11: =IF(AD11 <> 0,AE11/AD11,"") | AG11: =AG10 -> 0 | AH11: =COUNTIFS('Data-TSD+1'!$AC:$AC,AG$1,'Data-TSD+1'!$F:$F,"Average (60%)") -> 0 | AI11: =IF(AG11 <> 0,AH11/AG11,"") | AJ11: =AJ10 -> 0 | AK11: =COUNTIFS('Data-TSD+1'!$AC:$AC,AJ$1,'Data-TSD+1'!$F:$F,"Average (60%)") -> 0 | AL11: =IF(AJ11 <> 0,AK11/AJ11,"") | AM11: =AM10 -> 0 | AN11: =COUNTIFS('Data-TSD+1'!$AC:$AC,AM$1,'Data-TSD+1'!$F:$F,"Average (60%)") -> 0 | AO11: =IF(AM11 <> 0,AN11/AM11,"")
B12: d) Fair - 40% | C12: =C11 -> 1 | D12: =G12+J12+M12+P12+S12+V12+Y12+AB12+AE12+AH12+AK12+AN12 -> 0 | E12: =IF(C12 <> 0,D12/C12,"") -> 0 | F12: =F11 -> 1 | G12: =COUNTIFS('Data-TSD+1'!$AC:$AC,F$1,'Data-TSD+1'!$F:$F,"Unsatisfactory (40%)") -> 0 | H12: =IF(F12 <> 0,G12/F12,"") -> 0 | I12: =I11 -> 0 | J12: =COUNTIFS('Data-TSD+1'!$AC:$AC,I$1,'Data-TSD+1'!$F:$F,"Unsatisfactory (40%)") -> 0 | K12: =IF(I12 <> 0,J12/I12,"") | L12: =L11 -> 0 | M12: =COUNTIFS('Data-TSD+1'!$AC:$AC,L$1,'Data-TSD+1'!$F:$F,"Unsatisfactory (40%)") -> 0 | N12: =IF(L12 <> 0,M12/L12,"") | O12: =O11 -> 0 | P12: =COUNTIFS('Data-TSD+1'!$AC:$AC,O$1,'Data-TSD+1'!$F:$F,"Unsatisfactory (40%)") -> 0 | Q12: =IF(O12 <> 0,P12/O12,"") | R12: =R11 -> 0 | S12: =COUNTIFS('Data-TSD+1'!$AC:$AC,R$1,'Data-TSD+1'!$F:$F,"Unsatisfactory (40%)") -> 0 | T12: =IF(R12 <> 0,S12/R12,"") | U12: =U11 -> 0 | V12: =COUNTIFS('Data-TSD+1'!$AC:$AC,U$1,'Data-TSD+1'!$F:$F,"Unsatisfactory (40%)") -> 0 | W12: =IF(U12 <> 0,V12/U12,"") | X12: =X11 -> 0 | Y12: =COUNTIFS('Data-TSD+1'!$AC:$AC,X$1,'Data-TSD+1'!$F:$F,"Unsatisfactory (40%)") -> 0 | Z12: =IF(X12 <> 0,Y12/X12,"") | AA12: =AA11 -> 0 | AB12: =COUNTIFS('Data-TSD+1'!$AC:$AC,AA$1,'Data-TSD+1'!$F:$F,"Unsatisfactory (40%)") -> 0 | AC12: =IF(AA12 <> 0,AB12/AA12,"") | AD12: =AD11 -> 0 | AE12: =COUNTIFS('Data-TSD+1'!$AC:$AC,AD$1,'Data-TSD+1'!$F:$F,"Unsatisfactory (40%)") -> 0 | AF12: =IF(AD12 <> 0,AE12/AD12,"") | AG12: =AG11 -> 0 | AH12: =COUNTIFS('Data-TSD+1'!$AC:$AC,AG$1,'Data-TSD+1'!$F:$F,"Unsatisfactory (40%)") -> 0 | AI12: =IF(AG12 <> 0,AH12/AG12,"") | AJ12: =AJ11 -> 0 | AK12: =COUNTIFS('Data-TSD+1'!$AC:$AC,AJ$1,'Data-TSD+1'!$F:$F,"Unsatisfactory (40%)") -> 0 | AL12: =IF(AJ12 <> 0,AK12/AJ12,"") | AM12: =AM11 -> 0 | AN12: =COUNTIFS('Data-TSD+1'!$AC:$AC,AM$1,'Data-TSD+1'!$F:$F,"Unsatisfactory (40%)") -> 0 | AO12: =IF(AM12 <> 0,AN12/AM12,"")
B13: e) Poor - 20% | C13: =C12 -> 1 | D13: =G13+J13+M13+P13+S13+V13+Y13+AB13+AE13+AH13+AK13+AN13 -> 0 | E13: =IF(C13 <> 0,D13/C13,"") -> 0 | F13: =F12 -> 1 | G13: =COUNTIFS('Data-TSD+1'!$AC:$AC,F$1,'Data-TSD+1'!$F:$F,"Very unsatisfactory (20%)") -> 0 | H13: =IF(F13 <> 0,G13/F13,"") -> 0 | I13: =I12 -> 0 | J13: =COUNTIFS('Data-TSD+1'!$AC:$AC,I$1,'Data-TSD+1'!$F:$F,"Very unsatisfactory (20%)") -> 0 | K13: =IF(I13 <> 0,J13/I13,"") | L13: =L12 -> 0 | M13: =COUNTIFS('Data-TSD+1'!$AC:$AC,L$1,'Data-TSD+1'!$F:$F,"Very unsatisfactory (20%)") -> 0 | N13: =IF(L13 <> 0,M13/L13,"") | O13: =O12 -> 0 | P13: =COUNTIFS('Data-TSD+1'!$AC:$AC,O$1,'Data-TSD+1'!$F:$F,"Very unsatisfactory (20%)") -> 0 | Q13: =IF(O13 <> 0,P13/O13,"") | R13: =R12 -> 0 | S13: =COUNTIFS('Data-TSD+1'!$AC:$AC,R$1,'Data-TSD+1'!$F:$F,"Very unsatisfactory (20%)") -> 0 | T13: =IF(R13 <> 0,S13/R13,"") | U13: =U12 -> 0 | V13: =COUNTIFS('Data-TSD+1'!$AC:$AC,U$1,'Data-TSD+1'!$F:$F,"Very unsatisfactory (20%)") -> 0 | W13: =IF(U13 <> 0,V13/U13,"") | X13: =X12 -> 0 | Y13: =COUNTIFS('Data-TSD+1'!$AC:$AC,X$1,'Data-TSD+1'!$F:$F,"Very unsatisfactory (20%)") -> 0 | Z13: =IF(X13 <> 0,Y13/X13,"") | AA13: =AA12 -> 0 | AB13: =COUNTIFS('Data-TSD+1'!$AC:$AC,AA$1,'Data-TSD+1'!$F:$F,"Very unsatisfactory (20%)") -> 0 | AC13: =IF(AA13 <> 0,AB13/AA13,"") | AD13: =AD12 -> 0 | AE13: =COUNTIFS('Data-TSD+1'!$AC:$AC,AD$1,'Data-TSD+1'!$F:$F,"Very unsatisfactory (20%)") -> 0 | AF13: =IF(AD13 <> 0,AE13/AD13,"") | AG13: =AG12 -> 0 | AH13: =COUNTIFS('Data-TSD+1'!$AC:$AC,AG$1,'Data-TSD+1'!$F:$F,"Very unsatisfactory (20%)") -> 0 | AI13: =IF(AG13 <> 0,AH13/AG13,"") | AJ13: =AJ12 -> 0 | AK13: =COUNTIFS('Data-TSD+1'!$AC:$AC,AJ$1,'Data-TSD+1'!$F:$F,"Very unsatisfactory (20%)") -> 0 | AL13: =IF(AJ13 <> 0,AK13/AJ13,"") | AM13: =AM12 -> 0 | AN13: =COUNTIFS('Data-TSD+1'!$AC:$AC,AM$1,'Data-TSD+1'!$F:$F,"Very unsatisfactory (20%)") -> 0 | AO13: =IF(AM13 <> 0,AN13/AM13,"")
A14: 3 | B14: TSD+1: Satisfaction with information about your daily routine
B15: a) Excellent - 100% | C15: =COUNTIF('Data-TSD+1'!$G:$G,"<>" & "")-1 -> 1 | D15: =G15+J15+M15+P15+S15+V15+Y15+AB15+AE15+AH15+AK15+AN15 -> 1 | E15: =IF(C15 <> 0,D15/C15,"") -> 1 | F15: =COUNTIFS('Data-TSD+1'!$AC:$AC,F$1,'Data-TSD+1'!$G:$G,"<>" & "") -> 1 | G15: =COUNTIFS('Data-TSD+1'!$AC:$AC,F$1,'Data-TSD+1'!$G:$G,"Very satisfactory (100%)") -> 1 | H15: =IF(F15 <> 0,G15/F15,"") -> 1 | I15: =COUNTIFS('Data-TSD+1'!$AC:$AC,I$1,'Data-TSD+1'!$G:$G,"<>" & "") -> 0 | J15: =COUNTIFS('Data-TSD+1'!$AC:$AC,I$1,'Data-TSD+1'!$G:$G,"Very satisfactory (100%)") -> 0 | K15: =IF(I15 <> 0,J15/I15,"") | L15: =COUNTIFS('Data-TSD+1'!$AC:$AC,L$1,'Data-TSD+1'!$G:$G,"<>" & "") -> 0 | M15: =COUNTIFS('Data-TSD+1'!$AC:$AC,L$1,'Data-TSD+1'!$G:$G,"Very satisfactory (100%)") -> 0 | N15: =IF(L15 <> 0,M15/L15,"") | O15: =COUNTIFS('Data-TSD+1'!$AC:$AC,O$1,'Data-TSD+1'!$G:$G,"<>" & "") -> 0 | P15: =COUNTIFS('Data-TSD+1'!$AC:$AC,O$1,'Data-TSD+1'!$G:$G,"Very satisfactory (100%)") -> 0 | Q15: =IF(O15 <> 0,P15/O15,"") | R15: =COUNTIFS('Data-TSD+1'!$AC:$AC,R$1,'Data-TSD+1'!$G:$G,"<>" & "") -> 0 | S15: =COUNTIFS('Data-TSD+1'!$AC:$AC,R$1,'Data-TSD+1'!$G:$G,"Very satisfactory (100%)") -> 0 | T15: =IF(R15 <> 0,S15/R15,"") | U15: =COUNTIFS('Data-TSD+1'!$AC:$AC,U$1,'Data-TSD+1'!$G:$G,"<>" & "") -> 0 | V15: =COUNTIFS('Data-TSD+1'!$AC:$AC,U$1,'Data-TSD+1'!$G:$G,"Very satisfactory (100%)") -> 0 | W15: =IF(U15 <> 0,V15/U15,"") | X15: =COUNTIFS('Data-TSD+1'!$AC:$AC,X$1,'Data-TSD+1'!$G:$G,"<>" & "") -> 0 | Y15: =COUNTIFS('Data-TSD+1'!$AC:$AC,X$1,'Data-TSD+1'!$G:$G,"Very satisfactory (100%)") -> 0 | Z15: =IF(X15 <> 0,Y15/X15,"") | AA15: =COUNTIFS('Data-TSD+1'!$AC:$AC,AA$1,'Data-TSD+1'!$G:$G,"<>" & "") -> 0 | AB15: =COUNTIFS('Data-TSD+1'!$AC:$AC,AA$1,'Data-TSD+1'!$G:$G,"Very satisfactory (100%)") -> 0 | AC15: =IF(AA15 <> 0,AB15/AA15,"") | AD15: =COUNTIFS('Data-TSD+1'!$AC:$AC,AD$1,'Data-TSD+1'!$G:$G,"<>" & "") -> 0 | AE15: =COUNTIFS('Data-TSD+1'!$AC:$AC,AD$1,'Data-TSD+1'!$G:$G,"Very satisfactory (100%)") -> 0 | AF15: =IF(AD15 <> 0,AE15/AD15,"") | AG15: =COUNTIFS('Data-TSD+1'!$AC:$AC,AG$1,'Data-TSD+1'!$G:$G,"<>" & "") -> 0 | AH15: =COUNTIFS('Data-TSD+1'!$AC:$AC,AG$1,'Data-TSD+1'!$G:$G,"Very satisfactory (100%)") -> 0 | AI15: =IF(AG15 <> 0,AH15/AG15,"") | AJ15: =COUNTIFS('Data-TSD+1'!$AC:$AC,AJ$1,'Data-TSD+1'!$G:$G,"<>" & "") -> 0 | AK15: =COUNTIFS('Data-TSD+1'!$AC:$AC,AJ$1,'Data-TSD+1'!$G:$G,"Very satisfactory (100%)") -> 0 | AL15: =IF(AJ15 <> 0,AK15/AJ15,"") | AM15: =COUNTIFS('Data-TSD+1'!$AC:$AC,AM$1,'Data-TSD+1'!$G:$G,"<>" & "") -> 0 | AN15: =COUNTIFS('Data-TSD+1'!$AC:$AC,AM$1,'Data-TSD+1'!$G:$G,"Very satisfactory (100%)") -> 0 | AO15: =IF(AM15 <> 0,AN15/AM15,"")
B16: b) V.Good - 80% | C16: =C15 -> 1 | D16: =G16+J16+M16+P16+S16+V16+Y16+AB16+AE16+AH16+AK16+AN16 -> 0 | E16: =IF(C16 <> 0,D16/C16,"") -> 0 | F16: =F15 -> 1 | G16: =COUNTIFS('Data-TSD+1'!$AC:$AC,F$1,'Data-TSD+1'!$G:$G,"Satisfactory (80%)") -> 0 | H16: =IF(F16 <> 0,G16/F16,"") -> 0 | I16: =I15 -> 0 | J16: =COUNTIFS('Data-TSD+1'!$AC:$AC,I$1,'Data-TSD+1'!$G:$G,"Satisfactory (80%)") -> 0 | K16: =IF(I16 <> 0,J16/I16,"") | L16: =L15 -> 0 | M16: =COUNTIFS('Data-TSD+1'!$AC:$AC,L$1,'Data-TSD+1'!$G:$G,"Satisfactory (80%)") -> 0 | N16: =IF(L16 <> 0,M16/L16,"") | O16: =O15 -> 0 | P16: =COUNTIFS('Data-TSD+1'!$AC:$AC,O$1,'Data-TSD+1'!$G:$G,"Satisfactory (80%)") -> 0 | Q16: =IF(O16 <> 0,P16/O16,"") | R16: =R15 -> 0 | S16: =COUNTIFS('Data-TSD+1'!$AC:$AC,R$1,'Data-TSD+1'!$G:$G,"Satisfactory (80%)") -> 0 | T16: =IF(R16 <> 0,S16/R16,"") | U16: =U15 -> 0 | V16: =COUNTIFS('Data-TSD+1'!$AC:$AC,U$1,'Data-TSD+1'!$G:$G,"Satisfactory (80%)") -> 0 | W16: =IF(U16 <> 0,V16/U16,"") | X16: =X15 -> 0 | Y16: =COUNTIFS('Data-TSD+1'!$AC:$AC,X$1,'Data-TSD+1'!$G:$G,"Satisfactory (80%)") -> 0 | Z16: =IF(X16 <> 0,Y16/X16,"") | AA16: =AA15 -> 0 | AB16: =COUNTIFS('Data-TSD+1'!$AC:$AC,AA$1,'Data-TSD+1'!$G:$G,"Satisfactory (80%)") -> 0 | AC16: =IF(AA16 <> 0,AB16/AA16,"") | AD16: =AD15 -> 0 | AE16: =COUNTIFS('Data-TSD+1'!$AC:$AC,AD$1,'Data-TSD+1'!$G:$G,"Satisfactory (80%)") -> 0 | AF16: =IF(AD16 <> 0,AE16/AD16,"") | AG16: =AG15 -> 0 | AH16: =COUNTIFS('Data-TSD+1'!$AC:$AC,AG$1,'Data-TSD+1'!$G:$G,"Satisfactory (80%)") -> 0 | AI16: =IF(AG16 <> 0,AH16/AG16,"") | AJ16: =AJ15 -> 0 | AK16: =COUNTIFS('Data-TSD+1'!$AC:$AC,AJ$1,'Data-TSD+1'!$G:$G,"Satisfactory (80%)") -> 0 | AL16: =IF(AJ16 <> 0,AK16/AJ16,"") | AM16: =AM15 -> 0 | AN16: =COUNTIFS('Data-TSD+1'!$AC:$AC,AM$1,'Data-TSD+1'!$G:$G,"Satisfactory (80%)") -> 0 | AO16: =IF(AM16 <> 0,AN16/AM16,"")
B17: C) Good - 60% | C17: =C16 -> 1 | D17: =G17+J17+M17+P17+S17+V17+Y17+AB17+AE17+AH17+AK17+AN17 -> 0 | E17: =IF(C17 <> 0,D17/C17,"") -> 0 | F17: =F16 -> 1 | G17: =COUNTIFS('Data-TSD+1'!$AC:$AC,F$1,'Data-TSD+1'!$G:$G,"Average (60%)") -> 0 | H17: =IF(F17 <> 0,G17/F17,"") -> 0 | I17: =I16 -> 0 | J17: =COUNTIFS('Data-TSD+1'!$AC:$AC,I$1,'Data-TSD+1'!$G:$G,"Average (60%)") -> 0 | K17: =IF(I17 <> 0,J17/I17,"") | L17: =L16 -> 0 | M17: =COUNTIFS('Data-TSD+1'!$AC:$AC,L$1,'Data-TSD+1'!$G:$G,"Average (60%)") -> 0 | N17: =IF(L17 <> 0,M17/L17,"") | O17: =O16 -> 0 | P17: =COUNTIFS('Data-TSD+1'!$AC:$AC,O$1,'Data-TSD+1'!$G:$G,"Average (60%)") -> 0 | Q17: =IF(O17 <> 0,P17/O17,"") | R17: =R16 -> 0 | S17: =COUNTIFS('Data-TSD+1'!$AC:$AC,R$1,'Data-TSD+1'!$G:$G,"Average (60%)") -> 0 | T17: =IF(R17 <> 0,S17/R17,"") | U17: =U16 -> 0 | V17: =COUNTIFS('Data-TSD+1'!$AC:$AC,U$1,'Data-TSD+1'!$G:$G,"Average (60%)") -> 0 | W17: =IF(U17 <> 0,V17/U17,"") | X17: =X16 -> 0 | Y17: =COUNTIFS('Data-TSD+1'!$AC:$AC,X$1,'Data-TSD+1'!$G:$G,"Average (60%)") -> 0 | Z17: =IF(X17 <> 0,Y17/X17,"") | AA17: =AA16 -> 0 | AB17: =COUNTIFS('Data-TSD+1'!$AC:$AC,AA$1,'Data-TSD+1'!$G:$G,"Average (60%)") -> 0 | AC17: =IF(AA17 <> 0,AB17/AA17,"") | AD17: =AD16 -> 0 | AE17: =COUNTIFS('Data-TSD+1'!$AC:$AC,AD$1,'Data-TSD+1'!$G:$G,"Average (60%)") -> 0 | AF17: =IF(AD17 <> 0,AE17/AD17,"") | AG17: =AG16 -> 0 | AH17: =COUNTIFS('Data-TSD+1'!$AC:$AC,AG$1,'Data-TSD+1'!$G:$G,"Average (60%)") -> 0 | AI17: =IF(AG17 <> 0,AH17/AG17,"") | AJ17: =AJ16 -> 0 | AK17: =COUNTIFS('Data-TSD+1'!$AC:$AC,AJ$1,'Data-TSD+1'!$G:$G,"Average (60%)") -> 0 | AL17: =IF(AJ17 <> 0,AK17/AJ17,"") | AM17: =AM16 -> 0 | AN17: =COUNTIFS('Data-TSD+1'!$AC:$AC,AM$1,'Data-TSD+1'!$G:$G,"Average (60%)") -> 0 | AO17: =IF(AM17 <> 0,AN17/AM17,"")
B18: d) Fair - 40% | C18: =C17 -> 1 | D18: =G18+J18+M18+P18+S18+V18+Y18+AB18+AE18+AH18+AK18+AN18 -> 0 | E18: =IF(C18 <> 0,D18/C18,"") -> 0 | F18: =F17 -> 1 | G18: =COUNTIFS('Data-TSD+1'!$AC:$AC,F$1,'Data-TSD+1'!$G:$G,"Unsatisfactory (40%)") -> 0 | H18: =IF(F18 <> 0,G18/F18,"") -> 0 | I18: =I17 -> 0 | J18: =COUNTIFS('Data-TSD+1'!$AC:$AC,I$1,'Data-TSD+1'!$G:$G,"Unsatisfactory (40%)") -> 0 | K18: =IF(I18 <> 0,J18/I18,"") | L18: =L17 -> 0 | M18: =COUNTIFS('Data-TSD+1'!$AC:$AC,L$1,'Data-TSD+1'!$G:$G,"Unsatisfactory (40%)") -> 0 | N18: =IF(L18 <> 0,M18/L18,"") | O18: =O17 -> 0 | P18: =COUNTIFS('Data-TSD+1'!$AC:$AC,O$1,'Data-TSD+1'!$G:$G,"Unsatisfactory (40%)") -> 0 | Q18: =IF(O18 <> 0,P18/O18,"") | R18: =R17 -> 0 | S18: =COUNTIFS('Data-TSD+1'!$AC:$AC,R$1,'Data-TSD+1'!$G:$G,"Unsatisfactory (40%)") -> 0 | T18: =IF(R18 <> 0,S18/R18,"") | U18: =U17 -> 0 | V18: =COUNTIFS('Data-TSD+1'!$AC:$AC,U$1,'Data-TSD+1'!$G:$G,"Unsatisfactory (40%)") -> 0 | W18: =IF(U18 <> 0,V18/U18,"") | X18: =X17 -> 0 | Y18: =COUNTIFS('Data-TSD+1'!$AC:$AC,X$1,'Data-TSD+1'!$G:$G,"Unsatisfactory (40%)") -> 0 | Z18: =IF(X18 <> 0,Y18/X18,"") | AA18: =AA17 -> 0 | AB18: =COUNTIFS('Data-TSD+1'!$AC:$AC,AA$1,'Data-TSD+1'!$G:$G,"Unsatisfactory (40%)") -> 0 | AC18: =IF(AA18 <> 0,AB18/AA18,"") | AD18: =AD17 -> 0 | AE18: =COUNTIFS('Data-TSD+1'!$AC:$AC,AD$1,'Data-TSD+1'!$G:$G,"Unsatisfactory (40%)") -> 0 | AF18: =IF(AD18 <> 0,AE18/AD18,"") | AG18: =AG17 -> 0 | AH18: =COUNTIFS('Data-TSD+1'!$AC:$AC,AG$1,'Data-TSD+1'!$G:$G,"Unsatisfactory (40%)") -> 0 | AI18: =IF(AG18 <> 0,AH18/AG18,"") | AJ18: =AJ17 -> 0 | AK18: =COUNTIFS('Data-TSD+1'!$AC:$AC,AJ$1,'Data-TSD+1'!$G:$G,"Unsatisfactory (40%)") -> 0 | AL18: =IF(AJ18 <> 0,AK18/AJ18,"") | AM18: =AM17 -> 0 | AN18: =COUNTIFS('Data-TSD+1'!$AC:$AC,AM$1,'Data-TSD+1'!$G:$G,"Unsatisfactory (40%)") -> 0 | AO18: =IF(AM18 <> 0,AN18/AM18,"")
B19: e) Poor - 20% | C19: =C18 -> 1 | D19: =G19+J19+M19+P19+S19+V19+Y19+AB19+AE19+AH19+AK19+AN19 -> 0 | E19: =IF(C19 <> 0,D19/C19,"") -> 0 | F19: =F18 -> 1 | G19: =COUNTIFS('Data-TSD+1'!$AC:$AC,F$1,'Data-TSD+1'!$G:$G,"Very unsatisfactory (20%)") -> 0 | H19: =IF(F19 <> 0,G19/F19,"") -> 0 | I19: =I18 -> 0 | J19: =COUNTIFS('Data-TSD+1'!$AC:$AC,I$1,'Data-TSD+1'!$G:$G,"Very unsatisfactory (20%)") -> 0 | K19: =IF(I19 <> 0,J19/I19,"") | L19: =L18 -> 0 | M19: =COUNTIFS('Data-TSD+1'!$AC:$AC,L$1,'Data-TSD+1'!$G:$G,"Very unsatisfactory (20%)") -> 0 | N19: =IF(L19 <> 0,M19/L19,"") | O19: =O18 -> 0 | P19: =COUNTIFS('Data-TSD+1'!$AC:$AC,O$1,'Data-TSD+1'!$G:$G,"Very unsatisfactory (20%)") -> 0 | Q19: =IF(O19 <> 0,P19/O19,"") | R19: =R18 -> 0 | S19: =COUNTIFS('Data-TSD+1'!$AC:$AC,R$1,'Data-TSD+1'!$G:$G,"Very unsatisfactory (20%)") -> 0 | T19: =IF(R19 <> 0,S19/R19,"") | U19: =U18 -> 0 | V19: =COUNTIFS('Data-TSD+1'!$AC:$AC,U$1,'Data-TSD+1'!$G:$G,"Very unsatisfactory (20%)") -> 0 | W19: =IF(U19 <> 0,V19/U19,"") | X19: =X18 -> 0 | Y19: =COUNTIFS('Data-TSD+1'!$AC:$AC,X$1,'Data-TSD+1'!$G:$G,"Very unsatisfactory (20%)") -> 0 | Z19: =IF(X19 <> 0,Y19/X19,"") | AA19: =AA18 -> 0 | AB19: =COUNTIFS('Data-TSD+1'!$AC:$AC,AA$1,'Data-TSD+1'!$G:$G,"Very unsatisfactory (20%)") -> 0 | AC19: =IF(AA19 <> 0,AB19/AA19,"") | AD19: =AD18 -> 0 | AE19: =COUNTIFS('Data-TSD+1'!$AC:$AC,AD$1,'Data-TSD+1'!$G:$G,"Very unsatisfactory (20%)") -> 0 | AF19: =IF(AD19 <> 0,AE19/AD19,"") | AG19: =AG18 -> 0 | AH19: =COUNTIFS('Data-TSD+1'!$AC:$AC,AG$1,'Data-TSD+1'!$G:$G,"Very unsatisfactory (20%)") -> 0 | AI19: =IF(AG19 <> 0,AH19/AG19,"") | AJ19: =AJ18 -> 0 | AK19: =COUNTIFS('Data-TSD+1'!$AC:$AC,AJ$1,'Data-TSD+1'!$G:$G,"Very unsatisfactory (20%)") -> 0 | AL19: =IF(AJ19 <> 0,AK19/AJ19,"") | AM19: =AM18 -> 0 | AN19: =COUNTIFS('Data-TSD+1'!$AC:$AC,AM$1,'Data-TSD+1'!$G:$G,"Very unsatisfactory (20%)") -> 0 | AO19: =IF(AM19 <> 0,AN19/AM19,"")
A20: 4 | B20: TSD+1: Satisfaction with information about Do's and Don’ts
B21: a) Excellent - 100% | C21: =COUNTIF('Data-TSD+1'!$H:$H,"<>" & "")-1 -> 1 | D21: =G21+J21+M21+P21+S21+V21+Y21+AB21+AE21+AH21+AK21+AN21 -> 1 | E21: =IF(C21 <> 0,D21/C21,"") -> 1 | F21: =COUNTIFS('Data-TSD+1'!$AC:$AC,F$1,'Data-TSD+1'!$H:$H,"<>" & "") -> 1 | G21: =COUNTIFS('Data-TSD+1'!$AC:$AC,F$1,'Data-TSD+1'!$H:$H,"Very satisfactory (100%)") -> 1 | H21: =IF(F21 <> 0,G21/F21,"") -> 1 | I21: =COUNTIFS('Data-TSD+1'!$AC:$AC,I$1,'Data-TSD+1'!$H:$H,"<>" & "") -> 0 | J21: =COUNTIFS('Data-TSD+1'!$AC:$AC,I$1,'Data-TSD+1'!$H:$H,"Very satisfactory (100%)") -> 0 | K21: =IF(I21 <> 0,J21/I21,"") | L21: =COUNTIFS('Data-TSD+1'!$AC:$AC,L$1,'Data-TSD+1'!$H:$H,"<>" & "") -> 0 | M21: =COUNTIFS('Data-TSD+1'!$AC:$AC,L$1,'Data-TSD+1'!$H:$H,"Very satisfactory (100%)") -> 0 | N21: =IF(L21 <> 0,M21/L21,"") | O21: =COUNTIFS('Data-TSD+1'!$AC:$AC,O$1,'Data-TSD+1'!$H:$H,"<>" & "") -> 0 | P21: =COUNTIFS('Data-TSD+1'!$AC:$AC,O$1,'Data-TSD+1'!$H:$H,"Very satisfactory (100%)") -> 0 | Q21: =IF(O21 <> 0,P21/O21,"") | R21: =COUNTIFS('Data-TSD+1'!$AC:$AC,R$1,'Data-TSD+1'!$H:$H,"<>" & "") -> 0 | S21: =COUNTIFS('Data-TSD+1'!$AC:$AC,R$1,'Data-TSD+1'!$H:$H,"Very satisfactory (100%)") -> 0 | T21: =IF(R21 <> 0,S21/R21,"") | U21: =COUNTIFS('Data-TSD+1'!$AC:$AC,U$1,'Data-TSD+1'!$H:$H,"<>" & "") -> 0 | V21: =COUNTIFS('Data-TSD+1'!$AC:$AC,U$1,'Data-TSD+1'!$H:$H,"Very satisfactory (100%)") -> 0 | W21: =IF(U21 <> 0,V21/U21,"") | X21: =COUNTIFS('Data-TSD+1'!$AC:$AC,X$1,'Data-TSD+1'!$H:$H,"<>" & "") -> 0 | Y21: =COUNTIFS('Data-TSD+1'!$AC:$AC,X$1,'Data-TSD+1'!$H:$H,"Very satisfactory (100%)") -> 0 | Z21: =IF(X21 <> 0,Y21/X21,"") | AA21: =COUNTIFS('Data-TSD+1'!$AC:$AC,AA$1,'Data-TSD+1'!$H:$H,"<>" & "") -> 0 | AB21: =COUNTIFS('Data-TSD+1'!$AC:$AC,AA$1,'Data-TSD+1'!$H:$H,"Very satisfactory (100%)") -> 0 | AC21: =IF(AA21 <> 0,AB21/AA21,"") | AD21: =COUNTIFS('Data-TSD+1'!$AC:$AC,AD$1,'Data-TSD+1'!$H:$H,"<>" & "") -> 0 | AE21: =COUNTIFS('Data-TSD+1'!$AC:$AC,AD$1,'Data-TSD+1'!$H:$H,"Very satisfactory (100%)") -> 0 | AF21: =IF(AD21 <> 0,AE21/AD21,"") | AG21: =COUNTIFS('Data-TSD+1'!$AC:$AC,AG$1,'Data-TSD+1'!$H:$H,"<>" & "") -> 0 | AH21: =COUNTIFS('Data-TSD+1'!$AC:$AC,AG$1,'Data-TSD+1'!$H:$H,"Very satisfactory (100%)") -> 0 | AI21: =IF(AG21 <> 0,AH21/AG21,"") | AJ21: =COUNTIFS('Data-TSD+1'!$AC:$AC,AJ$1,'Data-TSD+1'!$H:$H,"<>" & "") -> 0 | AK21: =COUNTIFS('Data-TSD+1'!$AC:$AC,AJ$1,'Data-TSD+1'!$H:$H,"Very satisfactory (100%)") -> 0 | AL21: =IF(AJ21 <> 0,AK21/AJ21,"") | AM21: =COUNTIFS('Data-TSD+1'!$AC:$AC,AM$1,'Data-TSD+1'!$H:$H,"<>" & "") -> 0 | AN21: =COUNTIFS('Data-TSD+1'!$AC:$AC,AM$1,'Data-TSD+1'!$H:$H,"Very satisfactory (100%)") -> 0 | AO21: =IF(AM21 <> 0,AN21/AM21,"")
B22: b) V.Good - 80% | C22: =C21 -> 1 | D22: =G22+J22+M22+P22+S22+V22+Y22+AB22+AE22+AH22+AK22+AN22 -> 0 | E22: =IF(C22 <> 0,D22/C22,"") -> 0 | F22: =F21 -> 1 | G22: =COUNTIFS('Data-TSD+1'!$AC:$AC,F$1,'Data-TSD+1'!$H:$H,"Satisfactory (80%)") -> 0 | H22: =IF(F22 <> 0,G22/F22,"") -> 0 | I22: =I21 -> 0 | J22: =COUNTIFS('Data-TSD+1'!$AC:$AC,I$1,'Data-TSD+1'!$H:$H,"Satisfactory (80%)") -> 0 | K22: =IF(I22 <> 0,J22/I22,"") | L22: =L21 -> 0 | M22: =COUNTIFS('Data-TSD+1'!$AC:$AC,L$1,'Data-TSD+1'!$H:$H,"Satisfactory (80%)") -> 0 | N22: =IF(L22 <> 0,M22/L22,"") | O22: =O21 -> 0 | P22: =COUNTIFS('Data-TSD+1'!$AC:$AC,O$1,'Data-TSD+1'!$H:$H,"Satisfactory (80%)") -> 0 | Q22: =IF(O22 <> 0,P22/O22,"") | R22: =R21 -> 0 | S22: =COUNTIFS('Data-TSD+1'!$AC:$AC,R$1,'Data-TSD+1'!$H:$H,"Satisfactory (80%)") -> 0 | T22: =IF(R22 <> 0,S22/R22,"") | U22: =U21 -> 0 | V22: =COUNTIFS('Data-TSD+1'!$AC:$AC,U$1,'Data-TSD+1'!$H:$H,"Satisfactory (80%)") -> 0 | W22: =IF(U22 <> 0,V22/U22,"") | X22: =X21 -> 0 | Y22: =COUNTIFS('Data-TSD+1'!$AC:$AC,X$1,'Data-TSD+1'!$H:$H,"Satisfactory (80%)") -> 0 | Z22: =IF(X22 <> 0,Y22/X22,"") | AA22: =AA21 -> 0 | AB22: =COUNTIFS('Data-TSD+1'!$AC:$AC,AA$1,'Data-TSD+1'!$H:$H,"Satisfactory (80%)") -> 0 | AC22: =IF(AA22 <> 0,AB22/AA22,"") | AD22: =AD21 -> 0 | AE22: =COUNTIFS('Data-TSD+1'!$AC:$AC,AD$1,'Data-TSD+1'!$H:$H,"Satisfactory (80%)") -> 0 | AF22: =IF(AD22 <> 0,AE22/AD22,"") | AG22: =AG21 -> 0 | AH22: =COUNTIFS('Data-TSD+1'!$AC:$AC,AG$1,'Data-TSD+1'!$H:$H,"Satisfactory (80%)") -> 0 | AI22: =IF(AG22 <> 0,AH22/AG22,"") | AJ22: =AJ21 -> 0 | AK22: =COUNTIFS('Data-TSD+1'!$AC:$AC,AJ$1,'Data-TSD+1'!$H:$H,"Satisfactory (80%)") -> 0 | AL22: =IF(AJ22 <> 0,AK22/AJ22,"") | AM22: =AM21 -> 0 | AN22: =COUNTIFS('Data-TSD+1'!$AC:$AC,AM$1,'Data-TSD+1'!$H:$H,"Satisfactory (80%)") -> 0 | AO22: =IF(AM22 <> 0,AN22/AM22,"")
B23: C) Good - 60% | C23: =C22 -> 1 | D23: =G23+J23+M23+P23+S23+V23+Y23+AB23+AE23+AH23+AK23+AN23 -> 0 | E23: =IF(C23 <> 0,D23/C23,"") -> 0 | F23: =F22 -> 1 | G23: =COUNTIFS('Data-TSD+1'!$AC:$AC,F$1,'Data-TSD+1'!$H:$H,"Average (60%)") -> 0 | H23: =IF(F23 <> 0,G23/F23,"") -> 0 | I23: =I22 -> 0 | J23: =COUNTIFS('Data-TSD+1'!$AC:$AC,I$1,'Data-TSD+1'!$H:$H,"Average (60%)") -> 0 | K23: =IF(I23 <> 0,J23/I23,"") | L23: =L22 -> 0 | M23: =COUNTIFS('Data-TSD+1'!$AC:$AC,L$1,'Data-TSD+1'!$H:$H,"Average (60%)") -> 0 | N23: =IF(L23 <> 0,M23/L23,"") | O23: =O22 -> 0 | P23: =COUNTIFS('Data-TSD+1'!$AC:$AC,O$1,'Data-TSD+1'!$H:$H,"Average (60%)") -> 0 | Q23: =IF(O23 <> 0,P23/O23,"") | R23: =R22 -> 0 | S23: =COUNTIFS('Data-TSD+1'!$AC:$AC,R$1,'Data-TSD+1'!$H:$H,"Average (60%)") -> 0 | T23: =IF(R23 <> 0,S23/R23,"") | U23: =U22 -> 0 | V23: =COUNTIFS('Data-TSD+1'!$AC:$AC,U$1,'Data-TSD+1'!$H:$H,"Average (60%)") -> 0 | W23: =IF(U23 <> 0,V23/U23,"") | X23: =X22 -> 0 | Y23: =COUNTIFS('Data-TSD+1'!$AC:$AC,X$1,'Data-TSD+1'!$H:$H,"Average (60%)") -> 0 | Z23: =IF(X23 <> 0,Y23/X23,"") | AA23: =AA22 -> 0 | AB23: =COUNTIFS('Data-TSD+1'!$AC:$AC,AA$1,'Data-TSD+1'!$H:$H,"Average (60%)") -> 0 | AC23: =IF(AA23 <> 0,AB23/AA23,"") | AD23: =AD22 -> 0 | AE23: =COUNTIFS('Data-TSD+1'!$AC:$AC,AD$1,'Data-TSD+1'!$H:$H,"Average (60%)") -> 0 | AF23: =IF(AD23 <> 0,AE23/AD23,"") | AG23: =AG22 -> 0 | AH23: =COUNTIFS('Data-TSD+1'!$AC:$AC,AG$1,'Data-TSD+1'!$H:$H,"Average (60%)") -> 0 | AI23: =IF(AG23 <> 0,AH23/AG23,"") | AJ23: =AJ22 -> 0 | AK23: =COUNTIFS('Data-TSD+1'!$AC:$AC,AJ$1,'Data-TSD+1'!$H:$H,"Average (60%)") -> 0 | AL23: =IF(AJ23 <> 0,AK23/AJ23,"") | AM23: =AM22 -> 0 | AN23: =COUNTIFS('Data-TSD+1'!$AC:$AC,AM$1,'Data-TSD+1'!$H:$H,"Average (60%)") -> 0 | AO23: =IF(AM23 <> 0,AN23/AM23,"")
B24: d) Fair - 40% | C24: =C23 -> 1 | D24: =G24+J24+M24+P24+S24+V24+Y24+AB24+AE24+AH24+AK24+AN24 -> 0 | E24: =IF(C24 <> 0,D24/C24,"") -> 0 | F24: =F23 -> 1 | G24: =COUNTIFS('Data-TSD+1'!$AC:$AC,F$1,'Data-TSD+1'!$H:$H,"Unsatisfactory (40%)") -> 0 | H24: =IF(F24 <> 0,G24/F24,"") -> 0 | I24: =I23 -> 0 | J24: =COUNTIFS('Data-TSD+1'!$AC:$AC,I$1,'Data-TSD+1'!$H:$H,"Unsatisfactory (40%)") -> 0 | K24: =IF(I24 <> 0,J24/I24,"") | L24: =L23 -> 0 | M24: =COUNTIFS('Data-TSD+1'!$AC:$AC,L$1,'Data-TSD+1'!$H:$H,"Unsatisfactory (40%)") -> 0 | N24: =IF(L24 <> 0,M24/L24,"") | O24: =O23 -> 0 | P24: =COUNTIFS('Data-TSD+1'!$AC:$AC,O$1,'Data-TSD+1'!$H:$H,"Unsatisfactory (40%)") -> 0 | Q24: =IF(O24 <> 0,P24/O24,"") | R24: =R23 -> 0 | S24: =COUNTIFS('Data-TSD+1'!$AC:$AC,R$1,'Data-TSD+1'!$H:$H,"Unsatisfactory (40%)") -> 0 | T24: =IF(R24 <> 0,S24/R24,"") | U24: =U23 -> 0 | V24: =COUNTIFS('Data-TSD+1'!$AC:$AC,U$1,'Data-TSD+1'!$H:$H,"Unsatisfactory (40%)") -> 0 | W24: =IF(U24 <> 0,V24/U24,"") | X24: =X23 -> 0 | Y24: =COUNTIFS('Data-TSD+1'!$AC:$AC,X$1,'Data-TSD+1'!$H:$H,"Unsatisfactory (40%)") -> 0 | Z24: =IF(X24 <> 0,Y24/X24,"") | AA24: =AA23 -> 0 | AB24: =COUNTIFS('Data-TSD+1'!$AC:$AC,AA$1,'Data-TSD+1'!$H:$H,"Unsatisfactory (40%)") -> 0 | AC24: =IF(AA24 <> 0,AB24/AA24,"") | AD24: =AD23 -> 0 | AE24: =COUNTIFS('Data-TSD+1'!$AC:$AC,AD$1,'Data-TSD+1'!$H:$H,"Unsatisfactory (40%)") -> 0 | AF24: =IF(AD24 <> 0,AE24/AD24,"") | AG24: =AG23 -> 0 | AH24: =COUNTIFS('Data-TSD+1'!$AC:$AC,AG$1,'Data-TSD+1'!$H:$H,"Unsatisfactory (40%)") -> 0 | AI24: =IF(AG24 <> 0,AH24/AG24,"") | AJ24: =AJ23 -> 0 | AK24: =COUNTIFS('Data-TSD+1'!$AC:$AC,AJ$1,'Data-TSD+1'!$H:$H,"Unsatisfactory (40%)") -> 0 | AL24: =IF(AJ24 <> 0,AK24/AJ24,"") | AM24: =AM23 -> 0 | AN24: =COUNTIFS('Data-TSD+1'!$AC:$AC,AM$1,'Data-TSD+1'!$H:$H,"Unsatisfactory (40%)") -> 0 | AO24: =IF(AM24 <> 0,AN24/AM24,"")
B25: e) Poor - 20% | C25: =C24 -> 1 | D25: =G25+J25+M25+P25+S25+V25+Y25+AB25+AE25+AH25+AK25+AN25 -> 0 | E25: =IF(C25 <> 0,D25/C25,"") -> 0 | F25: =F24 -> 1 | G25: =COUNTIFS('Data-TSD+1'!$AC:$AC,F$1,'Data-TSD+1'!$H:$H,"Very unsatisfactory (20%)") -> 0 | H25: =IF(F25 <> 0,G25/F25,"") -> 0 | I25: =I24 -> 0 | J25: =COUNTIFS('Data-TSD+1'!$AC:$AC,I$1,'Data-TSD+1'!$H:$H,"Very unsatisfactory (20%)") -> 0 | K25: =IF(I25 <> 0,J25/I25,"") | L25: =L24 -> 0 | M25: =COUNTIFS('Data-TSD+1'!$AC:$AC,L$1,'Data-TSD+1'!$H:$H,"Very unsatisfactory (20%)") -> 0 | N25: =IF(L25 <> 0,M25/L25,"") | O25: =O24 -> 0 | P25: =COUNTIFS('Data-TSD+1'!$AC:$AC,O$1,'Data-TSD+1'!$H:$H,"Very unsatisfactory (20%)") -> 0 | Q25: =IF(O25 <> 0,P25/O25,"") | R25: =R24 -> 0 | S25: =COUNTIFS('Data-TSD+1'!$AC:$AC,R$1,'Data-TSD+1'!$H:$H,"Very unsatisfactory (20%)") -> 0 | T25: =IF(R25 <> 0,S25/R25,"") | U25: =U24 -> 0 | V25: =COUNTIFS('Data-TSD+1'!$AC:$AC,U$1,'Data-TSD+1'!$H:$H,"Very unsatisfactory (20%)") -> 0 | W25: =IF(U25 <> 0,V25/U25,"") | X25: =X24 -> 0 | Y25: =COUNTIFS('Data-TSD+1'!$AC:$AC,X$1,'Data-TSD+1'!$H:$H,"Very unsatisfactory (20%)") -> 0 | Z25: =IF(X25 <> 0,Y25/X25,"") | AA25: =AA24 -> 0 | AB25: =COUNTIFS('Data-TSD+1'!$AC:$AC,AA$1,'Data-TSD+1'!$H:$H,"Very unsatisfactory (20%)") -> 0 | AC25: =IF(AA25 <> 0,AB25/AA25,"") | AD25: =AD24 -> 0 | AE25: =COUNTIFS('Data-TSD+1'!$AC:$AC,AD$1,'Data-TSD+1'!$H:$H,"Very unsatisfactory (20%)") -> 0 | AF25: =IF(AD25 <> 0,AE25/AD25,"") | AG25: =AG24 -> 0 | AH25: =COUNTIFS('Data-TSD+1'!$AC:$AC,AG$1,'Data-TSD+1'!$H:$H,"Very unsatisfactory (20%)") -> 0 | AI25: =IF(AG25 <> 0,AH25/AG25,"") | AJ25: =AJ24 -> 0 | AK25: =COUNTIFS('Data-TSD+1'!$AC:$AC,AJ$1,'Data-TSD+1'!$H:$H,"Very unsatisfactory (20%)") -> 0 | AL25: =IF(AJ25 <> 0,AK25/AJ25,"") | AM25: =AM24 -> 0 | AN25: =COUNTIFS('Data-TSD+1'!$AC:$AC,AM$1,'Data-TSD+1'!$H:$H,"Very unsatisfactory (20%)") -> 0 | AO25: =IF(AM25 <> 0,AN25/AM25,"")
A26: 5 | B26: TSD+1: Attention by your PP
B27: a) Excellent - 100% | C27: =COUNTIF('Data-TSD+1'!$M:$M,"<>" & "")-1 -> 1 | D27: =G27+J27+M27+P27+S27+V27+Y27+AB27+AE27+AH27+AK27+AN27 -> 1 | E27: =IF(C27 <> 0,D27/C27,"") -> 1 | F27: =COUNTIFS('Data-TSD+1'!$AC:$AC,F$1,'Data-TSD+1'!$M:$M,"<>" & "") -> 1 | G27: =COUNTIFS('Data-TSD+1'!$AC:$AC,F$1,'Data-TSD+1'!$M:$M,"Very satisfactory (100%)") -> 1 | H27: =IF(F27 <> 0,G27/F27,"") -> 1 | I27: =COUNTIFS('Data-TSD+1'!$AC:$AC,I$1,'Data-TSD+1'!$M:$M,"<>" & "") -> 0 | J27: =COUNTIFS('Data-TSD+1'!$AC:$AC,I$1,'Data-TSD+1'!$M:$M,"Very satisfactory (100%)") -> 0 | K27: =IF(I27 <> 0,J27/I27,"") | L27: =COUNTIFS('Data-TSD+1'!$AC:$AC,L$1,'Data-TSD+1'!$M:$M,"<>" & "") -> 0 | M27: =COUNTIFS('Data-TSD+1'!$AC:$AC,L$1,'Data-TSD+1'!$M:$M,"Very satisfactory (100%)") -> 0 | N27: =IF(L27 <> 0,M27/L27,"") | O27: =COUNTIFS('Data-TSD+1'!$AC:$AC,O$1,'Data-TSD+1'!$M:$M,"<>" & "") -> 0 | P27: =COUNTIFS('Data-TSD+1'!$AC:$AC,O$1,'Data-TSD+1'!$M:$M,"Very satisfactory (100%)") -> 0 | Q27: =IF(O27 <> 0,P27/O27,"") | R27: =COUNTIFS('Data-TSD+1'!$AC:$AC,R$1,'Data-TSD+1'!$M:$M,"<>" & "") -> 0 | S27: =COUNTIFS('Data-TSD+1'!$AC:$AC,R$1,'Data-TSD+1'!$M:$M,"Very satisfactory (100%)") -> 0 | T27: =IF(R27 <> 0,S27/R27,"") | U27: =COUNTIFS('Data-TSD+1'!$AC:$AC,U$1,'Data-TSD+1'!$M:$M,"<>" & "") -> 0 | V27: =COUNTIFS('Data-TSD+1'!$AC:$AC,U$1,'Data-TSD+1'!$M:$M,"Very satisfactory (100%)") -> 0 | W27: =IF(U27 <> 0,V27/U27,"") | X27: =COUNTIFS('Data-TSD+1'!$AC:$AC,X$1,'Data-TSD+1'!$M:$M,"<>" & "") -> 0 | Y27: =COUNTIFS('Data-TSD+1'!$AC:$AC,X$1,'Data-TSD+1'!$M:$M,"Very satisfactory (100%)") -> 0 | Z27: =IF(X27 <> 0,Y27/X27,"") | AA27: =COUNTIFS('Data-TSD+1'!$AC:$AC,AA$1,'Data-TSD+1'!$M:$M,"<>" & "") -> 0 | AB27: =COUNTIFS('Data-TSD+1'!$AC:$AC,AA$1,'Data-TSD+1'!$M:$M,"Very satisfactory (100%)") -> 0 | AC27: =IF(AA27 <> 0,AB27/AA27,"") | AD27: =COUNTIFS('Data-TSD+1'!$AC:$AC,AD$1,'Data-TSD+1'!$M:$M,"<>" & "") -> 0 | AE27: =COUNTIFS('Data-TSD+1'!$AC:$AC,AD$1,'Data-TSD+1'!$M:$M,"Very satisfactory (100%)") -> 0 | AF27: =IF(AD27 <> 0,AE27/AD27,"") | AG27: =COUNTIFS('Data-TSD+1'!$AC:$AC,AG$1,'Data-TSD+1'!$M:$M,"<>" & "") -> 0 | AH27: =COUNTIFS('Data-TSD+1'!$AC:$AC,AG$1,'Data-TSD+1'!$M:$M,"Very satisfactory (100%)") -> 0 | AI27: =IF(AG27 <> 0,AH27/AG27,"") | AJ27: =COUNTIFS('Data-TSD+1'!$AC:$AC,AJ$1,'Data-TSD+1'!$M:$M,"<>" & "") -> 0 | AK27: =COUNTIFS('Data-TSD+1'!$AC:$AC,AJ$1,'Data-TSD+1'!$M:$M,"Very satisfactory (100%)") -> 0 | AL27: =IF(AJ27 <> 0,AK27/AJ27,"") | AM27: =COUNTIFS('Data-TSD+1'!$AC:$AC,AM$1,'Data-TSD+1'!$M:$M,"<>" & "") -> 0 | AN27: =COUNTIFS('Data-TSD+1'!$AC:$AC,AM$1,'Data-TSD+1'!$M:$M,"Very satisfactory (100%)") -> 0 | AO27: =IF(AM27 <> 0,AN27/AM27,"")
B28: b) V.Good - 80% | C28: =C27 -> 1 | D28: =G28+J28+M28+P28+S28+V28+Y28+AB28+AE28+AH28+AK28+AN28 -> 0 | E28: =IF(C28 <> 0,D28/C28,"") -> 0 | F28: =F27 -> 1 | G28: =COUNTIFS('Data-TSD+1'!$AC:$AC,F$1,'Data-TSD+1'!$M:$M,"Satisfactory (80%)") -> 0 | H28: =IF(F28 <> 0,G28/F28,"") -> 0 | I28: =I27 -> 0 | J28: =COUNTIFS('Data-TSD+1'!$AC:$AC,I$1,'Data-TSD+1'!$M:$M,"Satisfactory (80%)") -> 0 | K28: =IF(I28 <> 0,J28/I28,"") | L28: =L27 -> 0 | M28: =COUNTIFS('Data-TSD+1'!$AC:$AC,L$1,'Data-TSD+1'!$M:$M,"Satisfactory (80%)") -> 0 | N28: =IF(L28 <> 0,M28/L28,"") | O28: =O27 -> 0 | P28: =COUNTIFS('Data-TSD+1'!$AC:$AC,O$1,'Data-TSD+1'!$M:$M,"Satisfactory (80%)") -> 0 | Q28: =IF(O28 <> 0,P28/O28,"") | R28: =R27 -> 0 | S28: =COUNTIFS('Data-TSD+1'!$AC:$AC,R$1,'Data-TSD+1'!$M:$M,"Satisfactory (80%)") -> 0 | T28: =IF(R28 <> 0,S28/R28,"") | U28: =U27 -> 0 | V28: =COUNTIFS('Data-TSD+1'!$AC:$AC,U$1,'Data-TSD+1'!$M:$M,"Satisfactory (80%)") -> 0 | W28: =IF(U28 <> 0,V28/U28,"") | X28: =X27 -> 0 | Y28: =COUNTIFS('Data-TSD+1'!$AC:$AC,X$1,'Data-TSD+1'!$M:$M,"Satisfactory (80%)") -> 0 | Z28: =IF(X28 <> 0,Y28/X28,"") | AA28: =AA27 -> 0 | AB28: =COUNTIFS('Data-TSD+1'!$AC:$AC,AA$1,'Data-TSD+1'!$M:$M,"Satisfactory (80%)") -> 0 | AC28: =IF(AA28 <> 0,AB28/AA28,"") | AD28: =AD27 -> 0 | AE28: =COUNTIFS('Data-TSD+1'!$AC:$AC,AD$1,'Data-TSD+1'!$M:$M,"Satisfactory (80%)") -> 0 | AF28: =IF(AD28 <> 0,AE28/AD28,"") | AG28: =AG27 -> 0 | AH28: =COUNTIFS('Data-TSD+1'!$AC:$AC,AG$1,'Data-TSD+1'!$M:$M,"Satisfactory (80%)") -> 0 | AI28: =IF(AG28 <> 0,AH28/AG28,"") | AJ28: =AJ27 -> 0 | AK28: =COUNTIFS('Data-TSD+1'!$AC:$AC,AJ$1,'Data-TSD+1'!$M:$M,"Satisfactory (80%)") -> 0 | AL28: =IF(AJ28 <> 0,AK28/AJ28,"") | AM28: =AM27 -> 0 | AN28: =COUNTIFS('Data-TSD+1'!$AC:$AC,AM$1,'Data-TSD+1'!$M:$M,"Satisfactory (80%)") -> 0 | AO28: =IF(AM28 <> 0,AN28/AM28,"")
B29: C) Good - 60% | C29: =C28 -> 1 | D29: =G29+J29+M29+P29+S29+V29+Y29+AB29+AE29+AH29+AK29+AN29 -> 0 | E29: =IF(C29 <> 0,D29/C29,"") -> 0 | F29: =F28 -> 1 | G29: =COUNTIFS('Data-TSD+1'!$AC:$AC,F$1,'Data-TSD+1'!$M:$M,"Average (60%)") -> 0 | H29: =IF(F29 <> 0,G29/F29,"") -> 0 | I29: =I28 -> 0 | J29: =COUNTIFS('Data-TSD+1'!$AC:$AC,I$1,'Data-TSD+1'!$M:$M,"Average (60%)") -> 0 | K29: =IF(I29 <> 0,J29/I29,"") | L29: =L28 -> 0 | M29: =COUNTIFS('Data-TSD+1'!$AC:$AC,L$1,'Data-TSD+1'!$M:$M,"Average (60%)") -> 0 | N29: =IF(L29 <> 0,M29/L29,"") | O29: =O28 -> 0 | P29: =COUNTIFS('Data-TSD+1'!$AC:$AC,O$1,'Data-TSD+1'!$M:$M,"Average (60%)") -> 0 | Q29: =IF(O29 <> 0,P29/O29,"") | R29: =R28 -> 0 | S29: =COUNTIFS('Data-TSD+1'!$AC:$AC,R$1,'Data-TSD+1'!$M:$M,"Average (60%)") -> 0 | T29: =IF(R29 <> 0,S29/R29,"") | U29: =U28 -> 0 | V29: =COUNTIFS('Data-TSD+1'!$AC:$AC,U$1,'Data-TSD+1'!$M:$M,"Average (60%)") -> 0 | W29: =IF(U29 <> 0,V29/U29,"") | X29: =X28 -> 0 | Y29: =COUNTIFS('Data-TSD+1'!$AC:$AC,X$1,'Data-TSD+1'!$M:$M,"Average (60%)") -> 0 | Z29: =IF(X29 <> 0,Y29/X29,"") | AA29: =AA28 -> 0 | AB29: =COUNTIFS('Data-TSD+1'!$AC:$AC,AA$1,'Data-TSD+1'!$M:$M,"Average (60%)") -> 0 | AC29: =IF(AA29 <> 0,AB29/AA29,"") | AD29: =AD28 -> 0 | AE29: =COUNTIFS('Data-TSD+1'!$AC:$AC,AD$1,'Data-TSD+1'!$M:$M,"Average (60%)") -> 0 | AF29: =IF(AD29 <> 0,AE29/AD29,"") | AG29: =AG28 -> 0 | AH29: =COUNTIFS('Data-TSD+1'!$AC:$AC,AG$1,'Data-TSD+1'!$M:$M,"Average (60%)") -> 0 | AI29: =IF(AG29 <> 0,AH29/AG29,"") | AJ29: =AJ28 -> 0 | AK29: =COUNTIFS('Data-TSD+1'!$AC:$AC,AJ$1,'Data-TSD+1'!$M:$M,"Average (60%)") -> 0 | AL29: =IF(AJ29 <> 0,AK29/AJ29,"") | AM29: =AM28 -> 0 | AN29: =COUNTIFS('Data-TSD+1'!$AC:$AC,AM$1,'Data-TSD+1'!$M:$M,"Average (60%)") -> 0 | AO29: =IF(AM29 <> 0,AN29/AM29,"")
B30: d) Fair - 40% | C30: =C29 -> 1 | D30: =G30+J30+M30+P30+S30+V30+Y30+AB30+AE30+AH30+AK30+AN30 -> 0 | E30: =IF(C30 <> 0,D30/C30,"") -> 0 | F30: =F29 -> 1 | G30: =COUNTIFS('Data-TSD+1'!$AC:$AC,F$1,'Data-TSD+1'!$M:$M,"Unsatisfactory (40%)") -> 0 | H30: =IF(F30 <> 0,G30/F30,"") -> 0 | I30: =I29 -> 0 | J30: =COUNTIFS('Data-TSD+1'!$AC:$AC,I$1,'Data-TSD+1'!$M:$M,"Unsatisfactory (40%)") -> 0 | K30: =IF(I30 <> 0,J30/I30,"") | L30: =L29 -> 0 | M30: =COUNTIFS('Data-TSD+1'!$AC:$AC,L$1,'Data-TSD+1'!$M:$M,"Unsatisfactory (40%)") -> 0 | N30: =IF(L30 <> 0,M30/L30,"") | O30: =O29 -> 0 | P30: =COUNTIFS('Data-TSD+1'!$AC:$AC,O$1,'Data-TSD+1'!$M:$M,"Unsatisfactory (40%)") -> 0 | Q30: =IF(O30 <> 0,P30/O30,"") | R30: =R29 -> 0 | S30: =COUNTIFS('Data-TSD+1'!$AC:$AC,R$1,'Data-TSD+1'!$M:$M,"Unsatisfactory (40%)") -> 0 | T30: =IF(R30 <> 0,S30/R30,"") | U30: =U29 -> 0 | V30: =COUNTIFS('Data-TSD+1'!$AC:$AC,U$1,'Data-TSD+1'!$M:$M,"Unsatisfactory (40%)") -> 0 | W30: =IF(U30 <> 0,V30/U30,"") | X30: =X29 -> 0 | Y30: =COUNTIFS('Data-TSD+1'!$AC:$AC,X$1,'Data-TSD+1'!$M:$M,"Unsatisfactory (40%)") -> 0 | Z30: =IF(X30 <> 0,Y30/X30,"") | AA30: =AA29 -> 0 | AB30: =COUNTIFS('Data-TSD+1'!$AC:$AC,AA$1,'Data-TSD+1'!$M:$M,"Unsatisfactory (40%)") -> 0 | AC30: =IF(AA30 <> 0,AB30/AA30,"") | AD30: =AD29 -> 0 | AE30: =COUNTIFS('Data-TSD+1'!$AC:$AC,AD$1,'Data-TSD+1'!$M:$M,"Unsatisfactory (40%)") -> 0 | AF30: =IF(AD30 <> 0,AE30/AD30,"") | AG30: =AG29 -> 0 | AH30: =COUNTIFS('Data-TSD+1'!$AC:$AC,AG$1,'Data-TSD+1'!$M:$M,"Unsatisfactory (40%)") -> 0 | AI30: =IF(AG30 <> 0,AH30/AG30,"") | AJ30: =AJ29 -> 0 | AK30: =COUNTIFS('Data-TSD+1'!$AC:$AC,AJ$1,'Data-TSD+1'!$M:$M,"Unsatisfactory (40%)") -> 0 | AL30: =IF(AJ30 <> 0,AK30/AJ30,"") | AM30: =AM29 -> 0 | AN30: =COUNTIFS('Data-TSD+1'!$AC:$AC,AM$1,'Data-TSD+1'!$M:$M,"Unsatisfactory (40%)") -> 0 | AO30: =IF(AM30 <> 0,AN30/AM30,"")
B31: e) Poor - 20% | C31: =C30 -> 1 | D31: =G31+J31+M31+P31+S31+V31+Y31+AB31+AE31+AH31+AK31+AN31 -> 0 | E31: =IF(C31 <> 0,D31/C31,"") -> 0 | F31: =F30 -> 1 | G31: =COUNTIFS('Data-TSD+1'!$AC:$AC,F$1,'Data-TSD+1'!$M:$M,"Very unsatisfactory (20%)") -> 0 | H31: =IF(F31 <> 0,G31/F31,"") -> 0 | I31: =I30 -> 0 | J31: =COUNTIFS('Data-TSD+1'!$AC:$AC,I$1,'Data-TSD+1'!$M:$M,"Very unsatisfactory (20%)") -> 0 | K31: =IF(I31 <> 0,J31/I31,"") | L31: =L30 -> 0 | M31: =COUNTIFS('Data-TSD+1'!$AC:$AC,L$1,'Data-TSD+1'!$M:$M,"Very unsatisfactory (20%)") -> 0 | N31: =IF(L31 <> 0,M31/L31,"") | O31: =O30 -> 0 | P31: =COUNTIFS('Data-TSD+1'!$AC:$AC,O$1,'Data-TSD+1'!$M:$M,"Very unsatisfactory (20%)") -> 0 | Q31: =IF(O31 <> 0,P31/O31,"") | R31: =R30 -> 0 | S31: =COUNTIFS('Data-TSD+1'!$AC:$AC,R$1,'Data-TSD+1'!$M:$M,"Very unsatisfactory (20%)") -> 0 | T31: =IF(R31 <> 0,S31/R31,"") | U31: =U30 -> 0 | V31: =COUNTIFS('Data-TSD+1'!$AC:$AC,U$1,'Data-TSD+1'!$M:$M,"Very unsatisfactory (20%)") -> 0 | W31: =IF(U31 <> 0,V31/U31,"") | X31: =X30 -> 0 | Y31: =COUNTIFS('Data-TSD+1'!$AC:$AC,X$1,'Data-TSD+1'!$M:$M,"Very unsatisfactory (20%)") -> 0 | Z31: =IF(X31 <> 0,Y31/X31,"") | AA31: =AA30 -> 0 | AB31: =COUNTIFS('Data-TSD+1'!$AC:$AC,AA$1,'Data-TSD+1'!$M:$M,"Very unsatisfactory (20%)") -> 0 | AC31: =IF(AA31 <> 0,AB31/AA31,"") | AD31: =AD30 -> 0 | AE31: =COUNTIFS('Data-TSD+1'!$AC:$AC,AD$1,'Data-TSD+1'!$M:$M,"Very unsatisfactory (20%)") -> 0 | AF31: =IF(AD31 <> 0,AE31/AD31,"") | AG31: =AG30 -> 0 | AH31: =COUNTIFS('Data-TSD+1'!$AC:$AC,AG$1,'Data-TSD+1'!$M:$M,"Very unsatisfactory (20%)") -> 0 | AI31: =IF(AG31 <> 0,AH31/AG31,"") | AJ31: =AJ30 -> 0 | AK31: =COUNTIFS('Data-TSD+1'!$AC:$AC,AJ$1,'Data-TSD+1'!$M:$M,"Very unsatisfactory (20%)") -> 0 | AL31: =IF(AJ31 <> 0,AK31/AJ31,"") | AM31: =AM30 -> 0 | AN31: =COUNTIFS('Data-TSD+1'!$AC:$AC,AM$1,'Data-TSD+1'!$M:$M,"Very unsatisfactory (20%)") -> 0 | AO31: =IF(AM31 <> 0,AN31/AM31,"")
A32: 6 | B32: TSD+1: Attention by the RMO
B33: a) Excellent - 100% | C33: =COUNTIF('Data-TSD+1'!$N:$N,"<>" & "")-1 -> 1 | D33: =G33+J33+M33+P33+S33+V33+Y33+AB33+AE33+AH33+AK33+AN33 -> 1 | E33: =IF(C33 <> 0,D33/C33,"") -> 1 | F33: =COUNTIFS('Data-TSD+1'!$AC:$AC,F$1,'Data-TSD+1'!$N:$N,"<>" & "") -> 1 | G33: =COUNTIFS('Data-TSD+1'!$AC:$AC,F$1,'Data-TSD+1'!$N:$N,"Very satisfactory (100%)") -> 1 | H33: =IF(F33 <> 0,G33/F33,"") -> 1 | I33: =COUNTIFS('Data-TSD+1'!$AC:$AC,I$1,'Data-TSD+1'!$N:$N,"<>" & "") -> 0 | J33: =COUNTIFS('Data-TSD+1'!$AC:$AC,I$1,'Data-TSD+1'!$N:$N,"Very satisfactory (100%)") -> 0 | K33: =IF(I33 <> 0,J33/I33,"") | L33: =COUNTIFS('Data-TSD+1'!$AC:$AC,L$1,'Data-TSD+1'!$N:$N,"<>" & "") -> 0 | M33: =COUNTIFS('Data-TSD+1'!$AC:$AC,L$1,'Data-TSD+1'!$N:$N,"Very satisfactory (100%)") -> 0 | N33: =IF(L33 <> 0,M33/L33,"") | O33: =COUNTIFS('Data-TSD+1'!$AC:$AC,O$1,'Data-TSD+1'!$N:$N,"<>" & "") -> 0 | P33: =COUNTIFS('Data-TSD+1'!$AC:$AC,O$1,'Data-TSD+1'!$N:$N,"Very satisfactory (100%)") -> 0 | Q33: =IF(O33 <> 0,P33/O33,"") | R33: =COUNTIFS('Data-TSD+1'!$AC:$AC,R$1,'Data-TSD+1'!$N:$N,"<>" & "") -> 0 | S33: =COUNTIFS('Data-TSD+1'!$AC:$AC,R$1,'Data-TSD+1'!$N:$N,"Very satisfactory (100%)") -> 0 | T33: =IF(R33 <> 0,S33/R33,"") | U33: =COUNTIFS('Data-TSD+1'!$AC:$AC,U$1,'Data-TSD+1'!$N:$N,"<>" & "") -> 0 | V33: =COUNTIFS('Data-TSD+1'!$AC:$AC,U$1,'Data-TSD+1'!$N:$N,"Very satisfactory (100%)") -> 0 | W33: =IF(U33 <> 0,V33/U33,"") | X33: =COUNTIFS('Data-TSD+1'!$AC:$AC,X$1,'Data-TSD+1'!$N:$N,"<>" & "") -> 0 | Y33: =COUNTIFS('Data-TSD+1'!$AC:$AC,X$1,'Data-TSD+1'!$N:$N,"Very satisfactory (100%)") -> 0 | Z33: =IF(X33 <> 0,Y33/X33,"") | AA33: =COUNTIFS('Data-TSD+1'!$AC:$AC,AA$1,'Data-TSD+1'!$N:$N,"<>" & "") -> 0 | AB33: =COUNTIFS('Data-TSD+1'!$AC:$AC,AA$1,'Data-TSD+1'!$N:$N,"Very satisfactory (100%)") -> 0 | AC33: =IF(AA33 <> 0,AB33/AA33,"") | AD33: =COUNTIFS('Data-TSD+1'!$AC:$AC,AD$1,'Data-TSD+1'!$N:$N,"<>" & "") -> 0 | AE33: =COUNTIFS('Data-TSD+1'!$AC:$AC,AD$1,'Data-TSD+1'!$N:$N,"Very satisfactory (100%)") -> 0 | AF33: =IF(AD33 <> 0,AE33/AD33,"") | AG33: =COUNTIFS('Data-TSD+1'!$AC:$AC,AG$1,'Data-TSD+1'!$N:$N,"<>" & "") -> 0 | AH33: =COUNTIFS('Data-TSD+1'!$AC:$AC,AG$1,'Data-TSD+1'!$N:$N,"Very satisfactory (100%)") -> 0 | AI33: =IF(AG33 <> 0,AH33/AG33,"") | AJ33: =COUNTIFS('Data-TSD+1'!$AC:$AC,AJ$1,'Data-TSD+1'!$N:$N,"<>" & "") -> 0 | AK33: =COUNTIFS('Data-TSD+1'!$AC:$AC,AJ$1,'Data-TSD+1'!$N:$N,"Very satisfactory (100%)") -> 0 | AL33: =IF(AJ33 <> 0,AK33/AJ33,"") | AM33: =COUNTIFS('Data-TSD+1'!$AC:$AC,AM$1,'Data-TSD+1'!$N:$N,"<>" & "") -> 0 | AN33: =COUNTIFS('Data-TSD+1'!$AC:$AC,AM$1,'Data-TSD+1'!$N:$N,"Very satisfactory (100%)") -> 0 | AO33: =IF(AM33 <> 0,AN33/AM33,"")
B34: b) V.Good - 80% | C34: =C33 -> 1 | D34: =G34+J34+M34+P34+S34+V34+Y34+AB34+AE34+AH34+AK34+AN34 -> 0 | E34: =IF(C34 <> 0,D34/C34,"") -> 0 | F34: =F33 -> 1 | G34: =COUNTIFS('Data-TSD+1'!$AC:$AC,F$1,'Data-TSD+1'!$N:$N,"Satisfactory (80%)") -> 0 | H34: =IF(F34 <> 0,G34/F34,"") -> 0 | I34: =I33 -> 0 | J34: =COUNTIFS('Data-TSD+1'!$AC:$AC,I$1,'Data-TSD+1'!$N:$N,"Satisfactory (80%)") -> 0 | K34: =IF(I34 <> 0,J34/I34,"") | L34: =L33 -> 0 | M34: =COUNTIFS('Data-TSD+1'!$AC:$AC,L$1,'Data-TSD+1'!$N:$N,"Satisfactory (80%)") -> 0 | N34: =IF(L34 <> 0,M34/L34,"") | O34: =O33 -> 0 | P34: =COUNTIFS('Data-TSD+1'!$AC:$AC,O$1,'Data-TSD+1'!$N:$N,"Satisfactory (80%)") -> 0 | Q34: =IF(O34 <> 0,P34/O34,"") | R34: =R33 -> 0 | S34: =COUNTIFS('Data-TSD+1'!$AC:$AC,R$1,'Data-TSD+1'!$N:$N,"Satisfactory (80%)") -> 0 | T34: =IF(R34 <> 0,S34/R34,"") | U34: =U33 -> 0 | V34: =COUNTIFS('Data-TSD+1'!$AC:$AC,U$1,'Data-TSD+1'!$N:$N,"Satisfactory (80%)") -> 0 | W34: =IF(U34 <> 0,V34/U34,"") | X34: =X33 -> 0 | Y34: =COUNTIFS('Data-TSD+1'!$AC:$AC,X$1,'Data-TSD+1'!$N:$N,"Satisfactory (80%)") -> 0 | Z34: =IF(X34 <> 0,Y34/X34,"") | AA34: =AA33 -> 0 | AB34: =COUNTIFS('Data-TSD+1'!$AC:$AC,AA$1,'Data-TSD+1'!$N:$N,"Satisfactory (80%)") -> 0 | AC34: =IF(AA34 <> 0,AB34/AA34,"") | AD34: =AD33 -> 0 | AE34: =COUNTIFS('Data-TSD+1'!$AC:$AC,AD$1,'Data-TSD+1'!$N:$N,"Satisfactory (80%)") -> 0 | AF34: =IF(AD34 <> 0,AE34/AD34,"") | AG34: =AG33 -> 0 | AH34: =COUNTIFS('Data-TSD+1'!$AC:$AC,AG$1,'Data-TSD+1'!$N:$N,"Satisfactory (80%)") -> 0 | AI34: =IF(AG34 <> 0,AH34/AG34,"") | AJ34: =AJ33 -> 0 | AK34: =COUNTIFS('Data-TSD+1'!$AC:$AC,AJ$1,'Data-TSD+1'!$N:$N,"Satisfactory (80%)") -> 0 | AL34: =IF(AJ34 <> 0,AK34/AJ34,"") | AM34: =AM33 -> 0 | AN34: =COUNTIFS('Data-TSD+1'!$AC:$AC,AM$1,'Data-TSD+1'!$N:$N,"Satisfactory (80%)") -> 0 | AO34: =IF(AM34 <> 0,AN34/AM34,"")
